I0707 14:29:13.883370  1796 logging.cpp:172] INFO level logging started!
I0707 14:29:13.883658  1796 main.cpp:181] Build: 2015-07-06 18:27:13 by jsteiner
I0707 14:29:13.883677  1796 main.cpp:183] Version: 0.22.1
I0707 14:29:13.897650  1796 leveldb.cpp:176] Opened db in 13.366827ms
I0707 14:29:13.899898  1796 leveldb.cpp:183] Compacted db in 2.204574ms
I0707 14:29:13.899988  1796 leveldb.cpp:198] Created db iterator in 47535ns
I0707 14:29:13.900013  1796 leveldb.cpp:204] Seeked to beginning of db in 2619ns
I0707 14:29:13.900027  1796 leveldb.cpp:273] Iterated through 0 keys in the db in 327ns
I0707 14:29:13.900929  1796 replica.cpp:744] Replica recovered with log positions 0 -> 0 with 1 holes and 0 unlearned
I0707 14:29:13.910363  1802 recover.cpp:449] Starting replica recovery
I0707 14:29:13.913190  1802 recover.cpp:475] Replica is in EMPTY status
I0707 14:29:13.914352  1796 main.cpp:306] Starting Mesos master
I0707 14:29:13.916218  1802 replica.cpp:641] Replica in EMPTY status received a broadcasted recover request
I0707 14:29:13.916508  1805 recover.cpp:195] Received a recover response from a replica in EMPTY status
I0707 14:29:13.917129  1803 recover.cpp:566] Updating replica status to STARTING
I0707 14:29:13.918696  1804 master.cpp:349] Master 20150707-142913-16777343-5050-1796 (localhost) started on 127.0.0.1:5050
W0707 14:29:13.918745  1804 master.cpp:353] 
**************************************************
Master bound to loopback interface! Cannot communicate with remote schedulers or slaves. You might want to set '--ip' flag to a routable IP address.
**************************************************
I0707 14:29:13.918913  1804 master.cpp:395] Master only allowing authenticated frameworks to register
I0707 14:29:13.918937  1804 master.cpp:400] Master only allowing authenticated slaves to register
I0707 14:29:13.918984  1804 credentials.hpp:37] Loading credentials for authentication from '/home/jsteiner/mesosCredentials.cred'
W0707 14:29:13.921844  1804 credentials.hpp:52] Permissions on credentials file '/home/jsteiner/mesosCredentials.cred' are too open. It is recommended that your credentials file is NOT accessible by others.
I0707 14:29:13.923221  1802 leveldb.cpp:306] Persisting metadata (8 bytes) to leveldb took 5.924186ms
I0707 14:29:13.923274  1802 replica.cpp:323] Persisted replica status to STARTING
I0707 14:29:13.923578  1799 recover.cpp:475] Replica is in STARTING status
I0707 14:29:13.924407  1805 replica.cpp:641] Replica in STARTING status received a broadcasted recover request
I0707 14:29:13.924721  1802 recover.cpp:195] Received a recover response from a replica in STARTING status
I0707 14:29:13.925026  1798 recover.cpp:566] Updating replica status to VOTING
I0707 14:29:13.926718  1800 leveldb.cpp:306] Persisting metadata (8 bytes) to leveldb took 1.552062ms
I0707 14:29:13.926774  1800 replica.cpp:323] Persisted replica status to VOTING
I0707 14:29:13.926861  1803 recover.cpp:580] Successfully joined the Paxos group
I0707 14:29:13.927088  1803 recover.cpp:464] Recover process terminated
I0707 14:29:13.934433  1804 master.cpp:1295] Successfully attached file '/tmp/mesos-master.INFO'
I0707 14:29:13.934633  1805 master.cpp:1356] The newly elected leader is master@127.0.0.1:5050 with id 20150707-142913-16777343-5050-1796
I0707 14:29:13.934679  1805 master.cpp:1369] Elected as the leading master!
I0707 14:29:13.934720  1805 master.cpp:1187] Recovering from registrar
I0707 14:29:13.934937  1800 registrar.cpp:313] Recovering registrar
I0707 14:29:13.935920  1799 log.cpp:660] Attempting to start the writer
I0707 14:29:13.938010  1801 replica.cpp:477] Replica received implicit promise request with proposal 1
I0707 14:29:13.939604  1801 leveldb.cpp:306] Persisting metadata (8 bytes) to leveldb took 1.550172ms
I0707 14:29:13.939642  1801 replica.cpp:345] Persisted promised to 1
I0707 14:29:13.940407  1803 coordinator.cpp:230] Coordinator attemping to fill missing position
I0707 14:29:13.942117  1805 replica.cpp:378] Replica received explicit promise request for position 0 with proposal 2
I0707 14:29:13.943833  1805 leveldb.cpp:343] Persisting action (8 bytes) to leveldb took 1.611705ms
I0707 14:29:13.943882  1805 replica.cpp:679] Persisted action at 0
I0707 14:29:13.944865  1802 replica.cpp:511] Replica received write request for position 0
I0707 14:29:13.944959  1802 leveldb.cpp:438] Reading position from leveldb took 38824ns
I0707 14:29:13.946576  1802 leveldb.cpp:343] Persisting action (14 bytes) to leveldb took 1.557269ms
I0707 14:29:13.946660  1802 replica.cpp:679] Persisted action at 0
I0707 14:29:13.947165  1800 replica.cpp:658] Replica received learned notice for position 0
I0707 14:29:13.948710  1800 leveldb.cpp:343] Persisting action (16 bytes) to leveldb took 1.503531ms
I0707 14:29:13.948747  1800 replica.cpp:679] Persisted action at 0
I0707 14:29:13.948776  1800 replica.cpp:664] Replica learned NOP action at position 0
I0707 14:29:13.949172  1798 log.cpp:676] Writer started with ending position 0
I0707 14:29:13.950856  1800 leveldb.cpp:438] Reading position from leveldb took 24118ns
I0707 14:29:13.953579  1800 registrar.cpp:346] Successfully fetched the registry (0B) in 18.58304ms
I0707 14:29:13.953797  1800 registrar.cpp:445] Applied 1 operations in 57424ns; attempting to update the 'registry'
I0707 14:29:13.957751  1799 log.cpp:684] Attempting to append 118 bytes to the log
I0707 14:29:13.957891  1798 coordinator.cpp:340] Coordinator attempting to write APPEND action at position 1
I0707 14:29:13.958533  1801 replica.cpp:511] Replica received write request for position 1
I0707 14:29:13.960135  1801 leveldb.cpp:343] Persisting action (135 bytes) to leveldb took 1.557047ms
I0707 14:29:13.960178  1801 replica.cpp:679] Persisted action at 1
I0707 14:29:13.960615  1799 replica.cpp:658] Replica received learned notice for position 1
I0707 14:29:13.962167  1799 leveldb.cpp:343] Persisting action (137 bytes) to leveldb took 1.512554ms
I0707 14:29:13.962203  1799 replica.cpp:679] Persisted action at 1
I0707 14:29:13.962232  1799 replica.cpp:664] Replica learned APPEND action at position 1
I0707 14:29:13.963280  1805 registrar.cpp:490] Successfully updated the 'registry' in 9.383936ms
I0707 14:29:13.963415  1805 registrar.cpp:376] Successfully recovered registrar
I0707 14:29:13.963654  1805 log.cpp:703] Attempting to truncate the log to 1
I0707 14:29:13.963666  1804 master.cpp:1214] Recovered 0 slaves from the Registry (82B) ; allowing 10mins for slaves to re-register
I0707 14:29:13.963744  1801 coordinator.cpp:340] Coordinator attempting to write TRUNCATE action at position 2
I0707 14:29:13.964228  1804 replica.cpp:511] Replica received write request for position 2
I0707 14:29:13.965783  1804 leveldb.cpp:343] Persisting action (16 bytes) to leveldb took 1.512643ms
I0707 14:29:13.965818  1804 replica.cpp:679] Persisted action at 2
I0707 14:29:13.966169  1801 replica.cpp:658] Replica received learned notice for position 2
I0707 14:29:13.967711  1801 leveldb.cpp:343] Persisting action (18 bytes) to leveldb took 1.504512ms
I0707 14:29:13.967772  1801 leveldb.cpp:401] Deleting ~1 keys from leveldb took 26192ns
I0707 14:29:13.967798  1801 replica.cpp:679] Persisted action at 2
I0707 14:29:13.967831  1801 replica.cpp:664] Replica learned TRUNCATE action at position 2
I0707 14:29:29.058068  1801 http.cpp:516] HTTP request for '/master/state.json'
I0707 14:29:39.083722  1798 http.cpp:516] HTTP request for '/master/state.json'
I0707 14:29:47.845497  1804 master.cpp:3818] Authenticating slave(1)@127.0.1.1:5051
I0707 14:29:47.845762  1804 master.cpp:3829] Using default CRAM-MD5 authenticator
I0707 14:29:47.849403  1804 authenticator.hpp:108] Initializing server SASL
I0707 14:29:47.853229  1804 authenticator.hpp:170] Creating new server SASL connection
I0707 14:29:47.889684  1798 authenticator.hpp:276] Received SASL authentication start
I0707 14:29:47.889858  1798 authenticator.hpp:398] Authentication requires more steps
I0707 14:29:47.891814  1799 authenticator.hpp:304] Received SASL authentication step
I0707 14:29:47.892086  1799 authenticator.hpp:390] Authentication success
I0707 14:29:47.892465  1799 master.cpp:3876] Successfully authenticated principal 'hannes' at slave(1)@127.0.1.1:5051
I0707 14:29:47.896757  1801 master.cpp:2943] Registering slave at slave(1)@127.0.1.1:5051 (AWM14X) with id 20150707-142913-16777343-5050-1796-S0
I0707 14:29:47.898008  1801 registrar.cpp:445] Applied 1 operations in 103378ns; attempting to update the 'registry'
I0707 14:29:47.901955  1801 log.cpp:684] Attempting to append 281 bytes to the log
I0707 14:29:47.902942  1800 coordinator.cpp:340] Coordinator attempting to write APPEND action at position 3
I0707 14:29:47.905963  1802 replica.cpp:511] Replica received write request for position 3
I0707 14:29:47.913050  1802 leveldb.cpp:343] Persisting action (300 bytes) to leveldb took 6.233719ms
I0707 14:29:47.913207  1802 replica.cpp:679] Persisted action at 3
I0707 14:29:47.914544  1804 replica.cpp:658] Replica received learned notice for position 3
I0707 14:29:47.917990  1804 leveldb.cpp:343] Persisting action (302 bytes) to leveldb took 3.320888ms
I0707 14:29:47.920145  1804 replica.cpp:679] Persisted action at 3
I0707 14:29:47.921453  1804 replica.cpp:664] Replica learned APPEND action at position 3
I0707 14:29:47.923632  1803 log.cpp:703] Attempting to truncate the log to 3
I0707 14:29:47.923789  1804 registrar.cpp:490] Successfully updated the 'registry' in 25.424896ms
I0707 14:29:47.924371  1803 coordinator.cpp:340] Coordinator attempting to write TRUNCATE action at position 4
I0707 14:29:47.925638  1800 replica.cpp:511] Replica received write request for position 4
I0707 14:29:47.927755  1804 master.cpp:3000] Registered slave 20150707-142913-16777343-5050-1796-S0 at slave(1)@127.0.1.1:5051 (AWM14X) with cpus(*):2; mem(*):2048; disk(*):83928; ports(*):[31000-32000]
I0707 14:29:47.928202  1805 hierarchical.hpp:455] Added slave 20150707-142913-16777343-5050-1796-S0 (AWM14X) with cpus(*):2; mem(*):2048; disk(*):83928; ports(*):[31000-32000] (and cpus(*):2; mem(*):2048; disk(*):83928; ports(*):[31000-32000] available)
I0707 14:29:47.928881  1800 leveldb.cpp:343] Persisting action (16 bytes) to leveldb took 3.134828ms
I0707 14:29:47.934720  1800 replica.cpp:679] Persisted action at 4
I0707 14:29:47.936271  1803 replica.cpp:658] Replica received learned notice for position 4
I0707 14:29:47.939312  1803 leveldb.cpp:343] Persisting action (18 bytes) to leveldb took 2.925473ms
I0707 14:29:47.940059  1803 leveldb.cpp:401] Deleting ~2 keys from leveldb took 64085ns
I0707 14:29:47.940160  1803 replica.cpp:679] Persisted action at 4
I0707 14:29:47.940357  1803 replica.cpp:664] Replica learned TRUNCATE action at position 4
I0707 14:29:49.099380  1804 http.cpp:516] HTTP request for '/master/state.json'
I0707 14:29:50.206087  1803 http.cpp:516] HTTP request for '/master/state.json'
I0707 14:30:00.224253  1799 http.cpp:516] HTTP request for '/master/state.json'
I0707 14:30:10.236104  1803 http.cpp:516] HTTP request for '/master/state.json'
I0707 14:30:20.251385  1804 http.cpp:516] HTTP request for '/master/state.json'
I0707 14:30:31.072420  1801 http.cpp:516] HTTP request for '/master/state.json'
I0707 14:30:42.077762  1798 http.cpp:516] HTTP request for '/master/state.json'
I0707 14:30:53.077180  1802 http.cpp:516] HTTP request for '/master/state.json'
I0707 14:31:04.073851  1803 http.cpp:516] HTTP request for '/master/state.json'
I0707 14:31:15.077582  1802 http.cpp:516] HTTP request for '/master/state.json'
I0707 14:31:26.074038  1798 http.cpp:516] HTTP request for '/master/state.json'
I0707 14:31:37.075665  1801 http.cpp:516] HTTP request for '/master/state.json'
I0707 14:31:48.077514  1805 http.cpp:516] HTTP request for '/master/state.json'
I0707 14:31:59.076643  1801 http.cpp:516] HTTP request for '/master/state.json'
I0707 14:32:10.077564  1805 http.cpp:516] HTTP request for '/master/state.json'
I0707 14:32:21.077955  1800 http.cpp:516] HTTP request for '/master/state.json'
I0707 14:32:32.074671  1800 http.cpp:516] HTTP request for '/master/state.json'
I0707 14:32:43.077523  1802 http.cpp:516] HTTP request for '/master/state.json'
I0707 14:32:54.077515  1800 http.cpp:516] HTTP request for '/master/state.json'
I0707 14:33:05.075582  1801 http.cpp:516] HTTP request for '/master/state.json'
I0707 14:33:16.077067  1802 http.cpp:516] HTTP request for '/master/state.json'
I0707 14:33:27.075268  1804 http.cpp:516] HTTP request for '/master/state.json'
I0707 14:33:38.077512  1800 http.cpp:516] HTTP request for '/master/state.json'
I0707 14:33:49.077211  1799 http.cpp:516] HTTP request for '/master/state.json'
I0707 14:34:00.077332  1798 http.cpp:516] HTTP request for '/master/state.json'
I0707 14:34:11.072425  1801 http.cpp:516] HTTP request for '/master/state.json'
I0707 14:34:22.076930  1804 http.cpp:516] HTTP request for '/master/state.json'
I0707 14:34:33.078291  1805 http.cpp:516] HTTP request for '/master/state.json'
I0707 14:34:44.077857  1800 http.cpp:516] HTTP request for '/master/state.json'
I0707 14:34:55.077528  1804 http.cpp:516] HTTP request for '/master/state.json'
I0707 14:35:06.076215  1801 http.cpp:516] HTTP request for '/master/state.json'
I0707 14:35:17.077463  1800 http.cpp:516] HTTP request for '/master/state.json'
I0707 14:35:28.075660  1804 http.cpp:516] HTTP request for '/master/state.json'
I0707 14:35:39.075726  1801 http.cpp:516] HTTP request for '/master/state.json'
I0707 14:35:50.072688  1800 http.cpp:516] HTTP request for '/master/state.json'
I0707 14:36:01.072561  1799 http.cpp:516] HTTP request for '/master/state.json'
I0707 14:36:12.072317  1804 http.cpp:516] HTTP request for '/master/state.json'
I0707 14:36:23.075952  1801 http.cpp:516] HTTP request for '/master/state.json'
I0707 14:36:34.072679  1799 http.cpp:516] HTTP request for '/master/state.json'
I0707 14:36:45.072408  1801 http.cpp:516] HTTP request for '/master/state.json'
I0707 14:36:56.077987  1802 http.cpp:516] HTTP request for '/master/state.json'
I0707 14:37:07.076999  1801 http.cpp:516] HTTP request for '/master/state.json'
I0707 14:37:18.077602  1803 http.cpp:516] HTTP request for '/master/state.json'
I0707 14:37:29.077419  1805 http.cpp:516] HTTP request for '/master/state.json'
I0707 14:37:40.078758  1803 http.cpp:516] HTTP request for '/master/state.json'
I0707 14:37:51.078938  1801 http.cpp:516] HTTP request for '/master/state.json'
I0707 14:38:02.076727  1804 http.cpp:516] HTTP request for '/master/state.json'
I0707 14:38:13.077178  1799 http.cpp:516] HTTP request for '/master/state.json'
I0707 14:38:24.076742  1803 http.cpp:516] HTTP request for '/master/state.json'
I0707 14:38:35.077247  1800 http.cpp:516] HTTP request for '/master/state.json'
I0707 14:38:46.077849  1799 http.cpp:516] HTTP request for '/master/state.json'
I0707 14:38:57.077510  1802 http.cpp:516] HTTP request for '/master/state.json'
I0707 14:39:08.081358  1804 http.cpp:516] HTTP request for '/master/state.json'
I0707 14:39:19.076735  1803 http.cpp:516] HTTP request for '/master/state.json'
I0707 14:39:30.077378  1800 http.cpp:516] HTTP request for '/master/state.json'
I0707 14:39:41.078073  1802 http.cpp:516] HTTP request for '/master/state.json'
I0707 14:39:52.078110  1805 http.cpp:516] HTTP request for '/master/state.json'
I0707 14:40:03.074491  1798 http.cpp:516] HTTP request for '/master/state.json'
I0707 14:40:14.079149  1799 http.cpp:516] HTTP request for '/master/state.json'
I0707 14:40:25.074864  1802 http.cpp:516] HTTP request for '/master/state.json'
I0707 14:40:36.076527  1805 http.cpp:516] HTTP request for '/master/state.json'
I0707 14:40:47.077435  1803 http.cpp:516] HTTP request for '/master/state.json'
I0707 14:40:58.076761  1801 http.cpp:516] HTTP request for '/master/state.json'
I0707 14:41:09.077244  1802 http.cpp:516] HTTP request for '/master/state.json'
I0707 14:41:20.078073  1798 http.cpp:516] HTTP request for '/master/state.json'
I0707 14:41:31.076805  1801 http.cpp:516] HTTP request for '/master/state.json'
I0707 14:41:42.075186  1799 http.cpp:516] HTTP request for '/master/state.json'
I0707 14:41:53.074542  1798 http.cpp:516] HTTP request for '/master/state.json'
I0707 14:42:04.077457  1799 http.cpp:516] HTTP request for '/master/state.json'
I0707 14:42:15.077579  1800 http.cpp:516] HTTP request for '/master/state.json'
I0707 14:42:26.075016  1802 http.cpp:516] HTTP request for '/master/state.json'
I0707 14:42:37.077821  1801 http.cpp:516] HTTP request for '/master/state.json'
I0707 14:42:48.077333  1798 http.cpp:516] HTTP request for '/master/state.json'
I0707 14:42:59.075556  1801 http.cpp:516] HTTP request for '/master/state.json'
I0707 14:43:10.078336  1798 http.cpp:516] HTTP request for '/master/state.json'
I0707 14:43:21.074573  1802 http.cpp:516] HTTP request for '/master/state.json'
I0707 14:43:32.076350  1800 http.cpp:516] HTTP request for '/master/state.json'
I0707 14:43:43.072597  1804 http.cpp:516] HTTP request for '/master/state.json'
I0707 14:43:54.072667  1805 http.cpp:516] HTTP request for '/master/state.json'
I0707 14:44:05.077262  1803 http.cpp:516] HTTP request for '/master/state.json'
I0707 14:44:16.077461  1800 http.cpp:516] HTTP request for '/master/state.json'
I0707 14:44:27.076478  1805 http.cpp:516] HTTP request for '/master/state.json'
I0707 14:44:38.072841  1802 http.cpp:516] HTTP request for '/master/state.json'
I0707 14:44:49.076524  1801 http.cpp:516] HTTP request for '/master/state.json'
I0707 14:45:00.074331  1801 http.cpp:516] HTTP request for '/master/state.json'
I0707 14:45:03.230736  1799 master.cpp:3818] Authenticating scheduler-eed21049-4f05-420b-8d01-06b99a18a2da@127.0.1.1:43847
I0707 14:45:03.230878  1799 master.cpp:3829] Using default CRAM-MD5 authenticator
I0707 14:45:03.231506  1803 authenticator.hpp:170] Creating new server SASL connection
I0707 14:45:03.233014  1805 authenticator.hpp:276] Received SASL authentication start
I0707 14:45:03.233120  1805 authenticator.hpp:398] Authentication requires more steps
I0707 14:45:03.234051  1801 authenticator.hpp:304] Received SASL authentication step
I0707 14:45:03.234184  1801 authenticator.hpp:390] Authentication success
I0707 14:45:03.234454  1800 master.cpp:3876] Successfully authenticated principal 'hannes' at scheduler-eed21049-4f05-420b-8d01-06b99a18a2da@127.0.1.1:43847
I0707 14:45:03.235870  1798 master.cpp:1574] Received registration request for framework 'BioBox-Mesos-Framework_7292' at scheduler-eed21049-4f05-420b-8d01-06b99a18a2da@127.0.1.1:43847
W0707 14:45:03.236042  1798 master.cpp:1419] Framework at scheduler-eed21049-4f05-420b-8d01-06b99a18a2da@127.0.1.1:43847 (authenticated as 'hannes') does not specify principal in its FrameworkInfo
I0707 14:45:03.236392  1798 master.cpp:1638] Registering framework 20150707-142913-16777343-5050-1796-0000 (BioBox-Mesos-Framework_7292) at scheduler-eed21049-4f05-420b-8d01-06b99a18a2da@127.0.1.1:43847
I0707 14:45:03.236790  1802 hierarchical.hpp:321] Added framework 20150707-142913-16777343-5050-1796-0000
I0707 14:45:03.237772  1800 master.cpp:3760] Sending 1 offers to framework 20150707-142913-16777343-5050-1796-0000 (BioBox-Mesos-Framework_7292) at scheduler-eed21049-4f05-420b-8d01-06b99a18a2da@127.0.1.1:43847
I0707 14:45:03.501194  1803 master.cpp:2273] Processing ACCEPT call for offers: [ 20150707-142913-16777343-5050-1796-O0 ] on slave 20150707-142913-16777343-5050-1796-S0 at slave(1)@127.0.1.1:5051 (AWM14X) for framework 20150707-142913-16777343-5050-1796-0000 (BioBox-Mesos-Framework_7292) at scheduler-eed21049-4f05-420b-8d01-06b99a18a2da@127.0.1.1:43847
I0707 14:45:03.502074  1803 hierarchical.hpp:648] Recovered cpus(*):2; mem(*):2048; disk(*):83928; ports(*):[31000-32000] (total allocatable: cpus(*):2; mem(*):2048; disk(*):83928; ports(*):[31000-32000]) on slave 20150707-142913-16777343-5050-1796-S0 from framework 20150707-142913-16777343-5050-1796-0000
I0707 14:45:09.000095  1800 master.cpp:3760] Sending 1 offers to framework 20150707-142913-16777343-5050-1796-0000 (BioBox-Mesos-Framework_7292) at scheduler-eed21049-4f05-420b-8d01-06b99a18a2da@127.0.1.1:43847
I0707 14:45:09.005656  1803 master.cpp:2273] Processing ACCEPT call for offers: [ 20150707-142913-16777343-5050-1796-O1 ] on slave 20150707-142913-16777343-5050-1796-S0 at slave(1)@127.0.1.1:5051 (AWM14X) for framework 20150707-142913-16777343-5050-1796-0000 (BioBox-Mesos-Framework_7292) at scheduler-eed21049-4f05-420b-8d01-06b99a18a2da@127.0.1.1:43847
I0707 14:45:09.007392  1802 hierarchical.hpp:648] Recovered cpus(*):2; mem(*):2048; disk(*):83928; ports(*):[31000-32000] (total allocatable: cpus(*):2; mem(*):2048; disk(*):83928; ports(*):[31000-32000]) on slave 20150707-142913-16777343-5050-1796-S0 from framework 20150707-142913-16777343-5050-1796-0000
I0707 14:45:11.076619  1800 http.cpp:516] HTTP request for '/master/state.json'
I0707 14:45:15.009347  1803 master.cpp:3760] Sending 1 offers to framework 20150707-142913-16777343-5050-1796-0000 (BioBox-Mesos-Framework_7292) at scheduler-eed21049-4f05-420b-8d01-06b99a18a2da@127.0.1.1:43847
I0707 14:45:15.015815  1805 master.cpp:2273] Processing ACCEPT call for offers: [ 20150707-142913-16777343-5050-1796-O2 ] on slave 20150707-142913-16777343-5050-1796-S0 at slave(1)@127.0.1.1:5051 (AWM14X) for framework 20150707-142913-16777343-5050-1796-0000 (BioBox-Mesos-Framework_7292) at scheduler-eed21049-4f05-420b-8d01-06b99a18a2da@127.0.1.1:43847
I0707 14:45:15.017238  1805 hierarchical.hpp:648] Recovered cpus(*):2; mem(*):2048; disk(*):83928; ports(*):[31000-32000] (total allocatable: cpus(*):2; mem(*):2048; disk(*):83928; ports(*):[31000-32000]) on slave 20150707-142913-16777343-5050-1796-S0 from framework 20150707-142913-16777343-5050-1796-0000
I0707 14:45:21.017343  1805 master.cpp:3760] Sending 1 offers to framework 20150707-142913-16777343-5050-1796-0000 (BioBox-Mesos-Framework_7292) at scheduler-eed21049-4f05-420b-8d01-06b99a18a2da@127.0.1.1:43847
I0707 14:45:21.022626  1802 master.cpp:2273] Processing ACCEPT call for offers: [ 20150707-142913-16777343-5050-1796-O3 ] on slave 20150707-142913-16777343-5050-1796-S0 at slave(1)@127.0.1.1:5051 (AWM14X) for framework 20150707-142913-16777343-5050-1796-0000 (BioBox-Mesos-Framework_7292) at scheduler-eed21049-4f05-420b-8d01-06b99a18a2da@127.0.1.1:43847
I0707 14:45:21.024783  1803 master.hpp:822] Adding task 1 with resources cpus(*):1; mem(*):256 on slave 20150707-142913-16777343-5050-1796-S0 (AWM14X)
I0707 14:45:21.024981  1803 master.cpp:2550] Launching task 1 of framework 20150707-142913-16777343-5050-1796-0000 (BioBox-Mesos-Framework_7292) at scheduler-eed21049-4f05-420b-8d01-06b99a18a2da@127.0.1.1:43847 with resources cpus(*):1; mem(*):256 on slave 20150707-142913-16777343-5050-1796-S0 at slave(1)@127.0.1.1:5051 (AWM14X)
I0707 14:45:21.025764  1800 hierarchical.hpp:648] Recovered cpus(*):1; mem(*):1792; disk(*):83928; ports(*):[31000-32000] (total allocatable: cpus(*):1; mem(*):1792; disk(*):83928; ports(*):[31000-32000]) on slave 20150707-142913-16777343-5050-1796-S0 from framework 20150707-142913-16777343-5050-1796-0000
I0707 14:45:21.429468  1805 master.cpp:3300] Status update TASK_RUNNING (UUID: 0a324946-114d-4bbb-bd2c-c529f854f4bb) for task 1 of framework 20150707-142913-16777343-5050-1796-0000 from slave 20150707-142913-16777343-5050-1796-S0 at slave(1)@127.0.1.1:5051 (AWM14X)
I0707 14:45:21.429662  1805 master.cpp:3341] Forwarding status update TASK_RUNNING (UUID: 0a324946-114d-4bbb-bd2c-c529f854f4bb) for task 1 of framework 20150707-142913-16777343-5050-1796-0000
I0707 14:45:21.429980  1805 master.cpp:4623] Updating the latest state of task 1 of framework 20150707-142913-16777343-5050-1796-0000 to TASK_RUNNING
I0707 14:45:21.445199  1803 master.cpp:2787] Forwarding status update acknowledgement 0a324946-114d-4bbb-bd2c-c529f854f4bb for task 1 of framework 20150707-142913-16777343-5050-1796-0000 (BioBox-Mesos-Framework_7292) at scheduler-eed21049-4f05-420b-8d01-06b99a18a2da@127.0.1.1:43847 to slave 20150707-142913-16777343-5050-1796-S0 at slave(1)@127.0.1.1:5051 (AWM14X)
I0707 14:45:21.585989  1802 master.cpp:3300] Status update TASK_FINISHED (UUID: e25dae99-dc07-4165-9a03-629b498de607) for task 1 of framework 20150707-142913-16777343-5050-1796-0000 from slave 20150707-142913-16777343-5050-1796-S0 at slave(1)@127.0.1.1:5051 (AWM14X)
I0707 14:45:21.586115  1802 master.cpp:3341] Forwarding status update TASK_FINISHED (UUID: e25dae99-dc07-4165-9a03-629b498de607) for task 1 of framework 20150707-142913-16777343-5050-1796-0000
I0707 14:45:21.586546  1802 master.cpp:4623] Updating the latest state of task 1 of framework 20150707-142913-16777343-5050-1796-0000 to TASK_FINISHED
I0707 14:45:21.586812  1804 hierarchical.hpp:648] Recovered cpus(*):1; mem(*):256 (total allocatable: cpus(*):2; mem(*):2048; disk(*):83928; ports(*):[31000-32000]) on slave 20150707-142913-16777343-5050-1796-S0 from framework 20150707-142913-16777343-5050-1796-0000
I0707 14:45:21.589469  1802 master.cpp:4690] Removing task 1 with resources cpus(*):1; mem(*):256 of framework 20150707-142913-16777343-5050-1796-0000 on slave 20150707-142913-16777343-5050-1796-S0 at slave(1)@127.0.1.1:5051 (AWM14X)
I0707 14:45:21.589746  1802 master.cpp:2787] Forwarding status update acknowledgement e25dae99-dc07-4165-9a03-629b498de607 for task 1 of framework 20150707-142913-16777343-5050-1796-0000 (BioBox-Mesos-Framework_7292) at scheduler-eed21049-4f05-420b-8d01-06b99a18a2da@127.0.1.1:43847 to slave 20150707-142913-16777343-5050-1796-S0 at slave(1)@127.0.1.1:5051 (AWM14X)
I0707 14:45:22.019667  1801 master.cpp:3760] Sending 1 offers to framework 20150707-142913-16777343-5050-1796-0000 (BioBox-Mesos-Framework_7292) at scheduler-eed21049-4f05-420b-8d01-06b99a18a2da@127.0.1.1:43847
I0707 14:45:22.025192  1803 master.cpp:2273] Processing ACCEPT call for offers: [ 20150707-142913-16777343-5050-1796-O4 ] on slave 20150707-142913-16777343-5050-1796-S0 at slave(1)@127.0.1.1:5051 (AWM14X) for framework 20150707-142913-16777343-5050-1796-0000 (BioBox-Mesos-Framework_7292) at scheduler-eed21049-4f05-420b-8d01-06b99a18a2da@127.0.1.1:43847
I0707 14:45:22.026317  1803 hierarchical.hpp:648] Recovered cpus(*):2; mem(*):2048; disk(*):83928; ports(*):[31000-32000] (total allocatable: cpus(*):2; mem(*):2048; disk(*):83928; ports(*):[31000-32000]) on slave 20150707-142913-16777343-5050-1796-S0 from framework 20150707-142913-16777343-5050-1796-0000
I0707 14:45:22.072831  1798 http.cpp:516] HTTP request for '/master/state.json'
I0707 14:45:28.028559  1799 master.cpp:3760] Sending 1 offers to framework 20150707-142913-16777343-5050-1796-0000 (BioBox-Mesos-Framework_7292) at scheduler-eed21049-4f05-420b-8d01-06b99a18a2da@127.0.1.1:43847
I0707 14:45:28.035951  1800 master.cpp:2273] Processing ACCEPT call for offers: [ 20150707-142913-16777343-5050-1796-O5 ] on slave 20150707-142913-16777343-5050-1796-S0 at slave(1)@127.0.1.1:5051 (AWM14X) for framework 20150707-142913-16777343-5050-1796-0000 (BioBox-Mesos-Framework_7292) at scheduler-eed21049-4f05-420b-8d01-06b99a18a2da@127.0.1.1:43847
I0707 14:45:28.037451  1798 hierarchical.hpp:648] Recovered cpus(*):2; mem(*):2048; disk(*):83928; ports(*):[31000-32000] (total allocatable: cpus(*):2; mem(*):2048; disk(*):83928; ports(*):[31000-32000]) on slave 20150707-142913-16777343-5050-1796-S0 from framework 20150707-142913-16777343-5050-1796-0000
I0707 14:45:32.086776  1803 http.cpp:516] HTTP request for '/master/state.json'
I0707 14:45:34.036656  1805 master.cpp:3760] Sending 1 offers to framework 20150707-142913-16777343-5050-1796-0000 (BioBox-Mesos-Framework_7292) at scheduler-eed21049-4f05-420b-8d01-06b99a18a2da@127.0.1.1:43847
I0707 14:45:34.043217  1800 master.cpp:2273] Processing ACCEPT call for offers: [ 20150707-142913-16777343-5050-1796-O6 ] on slave 20150707-142913-16777343-5050-1796-S0 at slave(1)@127.0.1.1:5051 (AWM14X) for framework 20150707-142913-16777343-5050-1796-0000 (BioBox-Mesos-Framework_7292) at scheduler-eed21049-4f05-420b-8d01-06b99a18a2da@127.0.1.1:43847
I0707 14:45:34.044492  1800 hierarchical.hpp:648] Recovered cpus(*):2; mem(*):2048; disk(*):83928; ports(*):[31000-32000] (total allocatable: cpus(*):2; mem(*):2048; disk(*):83928; ports(*):[31000-32000]) on slave 20150707-142913-16777343-5050-1796-S0 from framework 20150707-142913-16777343-5050-1796-0000
I0707 14:45:40.046975  1805 master.cpp:3760] Sending 1 offers to framework 20150707-142913-16777343-5050-1796-0000 (BioBox-Mesos-Framework_7292) at scheduler-eed21049-4f05-420b-8d01-06b99a18a2da@127.0.1.1:43847
I0707 14:45:40.053585  1800 master.cpp:2273] Processing ACCEPT call for offers: [ 20150707-142913-16777343-5050-1796-O7 ] on slave 20150707-142913-16777343-5050-1796-S0 at slave(1)@127.0.1.1:5051 (AWM14X) for framework 20150707-142913-16777343-5050-1796-0000 (BioBox-Mesos-Framework_7292) at scheduler-eed21049-4f05-420b-8d01-06b99a18a2da@127.0.1.1:43847
I0707 14:45:40.054790  1800 hierarchical.hpp:648] Recovered cpus(*):2; mem(*):2048; disk(*):83928; ports(*):[31000-32000] (total allocatable: cpus(*):2; mem(*):2048; disk(*):83928; ports(*):[31000-32000]) on slave 20150707-142913-16777343-5050-1796-S0 from framework 20150707-142913-16777343-5050-1796-0000
I0707 14:45:42.106204  1798 http.cpp:516] HTTP request for '/master/state.json'
I0707 14:45:46.057837  1801 master.cpp:3760] Sending 1 offers to framework 20150707-142913-16777343-5050-1796-0000 (BioBox-Mesos-Framework_7292) at scheduler-eed21049-4f05-420b-8d01-06b99a18a2da@127.0.1.1:43847
I0707 14:45:46.064688  1805 master.cpp:2273] Processing ACCEPT call for offers: [ 20150707-142913-16777343-5050-1796-O8 ] on slave 20150707-142913-16777343-5050-1796-S0 at slave(1)@127.0.1.1:5051 (AWM14X) for framework 20150707-142913-16777343-5050-1796-0000 (BioBox-Mesos-Framework_7292) at scheduler-eed21049-4f05-420b-8d01-06b99a18a2da@127.0.1.1:43847
I0707 14:45:46.066038  1805 hierarchical.hpp:648] Recovered cpus(*):2; mem(*):2048; disk(*):83928; ports(*):[31000-32000] (total allocatable: cpus(*):2; mem(*):2048; disk(*):83928; ports(*):[31000-32000]) on slave 20150707-142913-16777343-5050-1796-S0 from framework 20150707-142913-16777343-5050-1796-0000
I0707 14:45:52.069080  1805 master.cpp:3760] Sending 1 offers to framework 20150707-142913-16777343-5050-1796-0000 (BioBox-Mesos-Framework_7292) at scheduler-eed21049-4f05-420b-8d01-06b99a18a2da@127.0.1.1:43847
I0707 14:45:52.075203  1800 master.cpp:2273] Processing ACCEPT call for offers: [ 20150707-142913-16777343-5050-1796-O9 ] on slave 20150707-142913-16777343-5050-1796-S0 at slave(1)@127.0.1.1:5051 (AWM14X) for framework 20150707-142913-16777343-5050-1796-0000 (BioBox-Mesos-Framework_7292) at scheduler-eed21049-4f05-420b-8d01-06b99a18a2da@127.0.1.1:43847
I0707 14:45:52.076455  1800 hierarchical.hpp:648] Recovered cpus(*):2; mem(*):2048; disk(*):83928; ports(*):[31000-32000] (total allocatable: cpus(*):2; mem(*):2048; disk(*):83928; ports(*):[31000-32000]) on slave 20150707-142913-16777343-5050-1796-S0 from framework 20150707-142913-16777343-5050-1796-0000
I0707 14:45:52.124620  1804 http.cpp:516] HTTP request for '/master/state.json'
I0707 14:45:58.079252  1799 master.cpp:3760] Sending 1 offers to framework 20150707-142913-16777343-5050-1796-0000 (BioBox-Mesos-Framework_7292) at scheduler-eed21049-4f05-420b-8d01-06b99a18a2da@127.0.1.1:43847
I0707 14:45:58.085948  1802 master.cpp:2273] Processing ACCEPT call for offers: [ 20150707-142913-16777343-5050-1796-O10 ] on slave 20150707-142913-16777343-5050-1796-S0 at slave(1)@127.0.1.1:5051 (AWM14X) for framework 20150707-142913-16777343-5050-1796-0000 (BioBox-Mesos-Framework_7292) at scheduler-eed21049-4f05-420b-8d01-06b99a18a2da@127.0.1.1:43847
I0707 14:45:58.087087  1798 hierarchical.hpp:648] Recovered cpus(*):2; mem(*):2048; disk(*):83928; ports(*):[31000-32000] (total allocatable: cpus(*):2; mem(*):2048; disk(*):83928; ports(*):[31000-32000]) on slave 20150707-142913-16777343-5050-1796-S0 from framework 20150707-142913-16777343-5050-1796-0000
I0707 14:46:02.142009  1803 http.cpp:516] HTTP request for '/master/state.json'
I0707 14:46:04.089396  1804 master.cpp:3760] Sending 1 offers to framework 20150707-142913-16777343-5050-1796-0000 (BioBox-Mesos-Framework_7292) at scheduler-eed21049-4f05-420b-8d01-06b99a18a2da@127.0.1.1:43847
I0707 14:46:04.095741  1805 master.cpp:2273] Processing ACCEPT call for offers: [ 20150707-142913-16777343-5050-1796-O11 ] on slave 20150707-142913-16777343-5050-1796-S0 at slave(1)@127.0.1.1:5051 (AWM14X) for framework 20150707-142913-16777343-5050-1796-0000 (BioBox-Mesos-Framework_7292) at scheduler-eed21049-4f05-420b-8d01-06b99a18a2da@127.0.1.1:43847
I0707 14:46:04.097002  1805 hierarchical.hpp:648] Recovered cpus(*):2; mem(*):2048; disk(*):83928; ports(*):[31000-32000] (total allocatable: cpus(*):2; mem(*):2048; disk(*):83928; ports(*):[31000-32000]) on slave 20150707-142913-16777343-5050-1796-S0 from framework 20150707-142913-16777343-5050-1796-0000
I0707 14:46:10.099190  1804 master.cpp:3760] Sending 1 offers to framework 20150707-142913-16777343-5050-1796-0000 (BioBox-Mesos-Framework_7292) at scheduler-eed21049-4f05-420b-8d01-06b99a18a2da@127.0.1.1:43847
I0707 14:46:10.105487  1805 master.cpp:2273] Processing ACCEPT call for offers: [ 20150707-142913-16777343-5050-1796-O12 ] on slave 20150707-142913-16777343-5050-1796-S0 at slave(1)@127.0.1.1:5051 (AWM14X) for framework 20150707-142913-16777343-5050-1796-0000 (BioBox-Mesos-Framework_7292) at scheduler-eed21049-4f05-420b-8d01-06b99a18a2da@127.0.1.1:43847
I0707 14:46:10.107240  1800 hierarchical.hpp:648] Recovered cpus(*):2; mem(*):2048; disk(*):83928; ports(*):[31000-32000] (total allocatable: cpus(*):2; mem(*):2048; disk(*):83928; ports(*):[31000-32000]) on slave 20150707-142913-16777343-5050-1796-S0 from framework 20150707-142913-16777343-5050-1796-0000
I0707 14:46:12.163370  1805 http.cpp:516] HTTP request for '/master/state.json'
I0707 14:46:16.108481  1803 master.cpp:3760] Sending 1 offers to framework 20150707-142913-16777343-5050-1796-0000 (BioBox-Mesos-Framework_7292) at scheduler-eed21049-4f05-420b-8d01-06b99a18a2da@127.0.1.1:43847
I0707 14:46:16.115001  1799 master.cpp:2273] Processing ACCEPT call for offers: [ 20150707-142913-16777343-5050-1796-O13 ] on slave 20150707-142913-16777343-5050-1796-S0 at slave(1)@127.0.1.1:5051 (AWM14X) for framework 20150707-142913-16777343-5050-1796-0000 (BioBox-Mesos-Framework_7292) at scheduler-eed21049-4f05-420b-8d01-06b99a18a2da@127.0.1.1:43847
I0707 14:46:16.116168  1799 hierarchical.hpp:648] Recovered cpus(*):2; mem(*):2048; disk(*):83928; ports(*):[31000-32000] (total allocatable: cpus(*):2; mem(*):2048; disk(*):83928; ports(*):[31000-32000]) on slave 20150707-142913-16777343-5050-1796-S0 from framework 20150707-142913-16777343-5050-1796-0000
I0707 14:46:22.118409  1799 master.cpp:3760] Sending 1 offers to framework 20150707-142913-16777343-5050-1796-0000 (BioBox-Mesos-Framework_7292) at scheduler-eed21049-4f05-420b-8d01-06b99a18a2da@127.0.1.1:43847
I0707 14:46:22.124749  1804 master.cpp:2273] Processing ACCEPT call for offers: [ 20150707-142913-16777343-5050-1796-O14 ] on slave 20150707-142913-16777343-5050-1796-S0 at slave(1)@127.0.1.1:5051 (AWM14X) for framework 20150707-142913-16777343-5050-1796-0000 (BioBox-Mesos-Framework_7292) at scheduler-eed21049-4f05-420b-8d01-06b99a18a2da@127.0.1.1:43847
I0707 14:46:22.126323  1801 hierarchical.hpp:648] Recovered cpus(*):2; mem(*):2048; disk(*):83928; ports(*):[31000-32000] (total allocatable: cpus(*):2; mem(*):2048; disk(*):83928; ports(*):[31000-32000]) on slave 20150707-142913-16777343-5050-1796-S0 from framework 20150707-142913-16777343-5050-1796-0000
I0707 14:46:22.181284  1804 http.cpp:516] HTTP request for '/master/state.json'
I0707 14:46:28.129525  1803 master.cpp:3760] Sending 1 offers to framework 20150707-142913-16777343-5050-1796-0000 (BioBox-Mesos-Framework_7292) at scheduler-eed21049-4f05-420b-8d01-06b99a18a2da@127.0.1.1:43847
I0707 14:46:28.136250  1802 master.cpp:2273] Processing ACCEPT call for offers: [ 20150707-142913-16777343-5050-1796-O15 ] on slave 20150707-142913-16777343-5050-1796-S0 at slave(1)@127.0.1.1:5051 (AWM14X) for framework 20150707-142913-16777343-5050-1796-0000 (BioBox-Mesos-Framework_7292) at scheduler-eed21049-4f05-420b-8d01-06b99a18a2da@127.0.1.1:43847
I0707 14:46:28.137547  1804 hierarchical.hpp:648] Recovered cpus(*):2; mem(*):2048; disk(*):83928; ports(*):[31000-32000] (total allocatable: cpus(*):2; mem(*):2048; disk(*):83928; ports(*):[31000-32000]) on slave 20150707-142913-16777343-5050-1796-S0 from framework 20150707-142913-16777343-5050-1796-0000
I0707 14:46:32.197715  1801 http.cpp:516] HTTP request for '/master/state.json'
I0707 14:46:34.139798  1798 master.cpp:3760] Sending 1 offers to framework 20150707-142913-16777343-5050-1796-0000 (BioBox-Mesos-Framework_7292) at scheduler-eed21049-4f05-420b-8d01-06b99a18a2da@127.0.1.1:43847
I0707 14:46:34.146617  1804 master.cpp:2273] Processing ACCEPT call for offers: [ 20150707-142913-16777343-5050-1796-O16 ] on slave 20150707-142913-16777343-5050-1796-S0 at slave(1)@127.0.1.1:5051 (AWM14X) for framework 20150707-142913-16777343-5050-1796-0000 (BioBox-Mesos-Framework_7292) at scheduler-eed21049-4f05-420b-8d01-06b99a18a2da@127.0.1.1:43847
I0707 14:46:34.148017  1804 hierarchical.hpp:648] Recovered cpus(*):2; mem(*):2048; disk(*):83928; ports(*):[31000-32000] (total allocatable: cpus(*):2; mem(*):2048; disk(*):83928; ports(*):[31000-32000]) on slave 20150707-142913-16777343-5050-1796-S0 from framework 20150707-142913-16777343-5050-1796-0000
I0707 14:46:40.148315  1799 master.cpp:3760] Sending 1 offers to framework 20150707-142913-16777343-5050-1796-0000 (BioBox-Mesos-Framework_7292) at scheduler-eed21049-4f05-420b-8d01-06b99a18a2da@127.0.1.1:43847
I0707 14:46:40.156075  1805 master.cpp:2273] Processing ACCEPT call for offers: [ 20150707-142913-16777343-5050-1796-O17 ] on slave 20150707-142913-16777343-5050-1796-S0 at slave(1)@127.0.1.1:5051 (AWM14X) for framework 20150707-142913-16777343-5050-1796-0000 (BioBox-Mesos-Framework_7292) at scheduler-eed21049-4f05-420b-8d01-06b99a18a2da@127.0.1.1:43847
I0707 14:46:40.158928  1805 master.hpp:822] Adding task 2 with resources cpus(*):2; mem(*):256 on slave 20150707-142913-16777343-5050-1796-S0 (AWM14X)
I0707 14:46:40.159191  1805 master.cpp:2550] Launching task 2 of framework 20150707-142913-16777343-5050-1796-0000 (BioBox-Mesos-Framework_7292) at scheduler-eed21049-4f05-420b-8d01-06b99a18a2da@127.0.1.1:43847 with resources cpus(*):2; mem(*):256 on slave 20150707-142913-16777343-5050-1796-S0 at slave(1)@127.0.1.1:5051 (AWM14X)
I0707 14:46:40.160394  1803 hierarchical.hpp:648] Recovered mem(*):1792; disk(*):83928; ports(*):[31000-32000] (total allocatable: mem(*):1792; disk(*):83928; ports(*):[31000-32000]) on slave 20150707-142913-16777343-5050-1796-S0 from framework 20150707-142913-16777343-5050-1796-0000
I0707 14:46:40.487195  1805 master.cpp:3300] Status update TASK_RUNNING (UUID: 00ba7845-1e1e-4293-86f8-51104f2daa98) for task 2 of framework 20150707-142913-16777343-5050-1796-0000 from slave 20150707-142913-16777343-5050-1796-S0 at slave(1)@127.0.1.1:5051 (AWM14X)
I0707 14:46:40.487319  1805 master.cpp:3341] Forwarding status update TASK_RUNNING (UUID: 00ba7845-1e1e-4293-86f8-51104f2daa98) for task 2 of framework 20150707-142913-16777343-5050-1796-0000
I0707 14:46:40.487612  1805 master.cpp:4623] Updating the latest state of task 2 of framework 20150707-142913-16777343-5050-1796-0000 to TASK_RUNNING
I0707 14:46:40.489959  1801 master.cpp:2787] Forwarding status update acknowledgement 00ba7845-1e1e-4293-86f8-51104f2daa98 for task 2 of framework 20150707-142913-16777343-5050-1796-0000 (BioBox-Mesos-Framework_7292) at scheduler-eed21049-4f05-420b-8d01-06b99a18a2da@127.0.1.1:43847 to slave 20150707-142913-16777343-5050-1796-S0 at slave(1)@127.0.1.1:5051 (AWM14X)
I0707 14:46:40.746604  1799 master.cpp:3300] Status update TASK_FINISHED (UUID: 6f42250a-ff3e-435c-bcb6-2d7990f4e7e5) for task 2 of framework 20150707-142913-16777343-5050-1796-0000 from slave 20150707-142913-16777343-5050-1796-S0 at slave(1)@127.0.1.1:5051 (AWM14X)
I0707 14:46:40.746734  1799 master.cpp:3341] Forwarding status update TASK_FINISHED (UUID: 6f42250a-ff3e-435c-bcb6-2d7990f4e7e5) for task 2 of framework 20150707-142913-16777343-5050-1796-0000
I0707 14:46:40.747033  1799 master.cpp:4623] Updating the latest state of task 2 of framework 20150707-142913-16777343-5050-1796-0000 to TASK_FINISHED
I0707 14:46:40.747283  1804 hierarchical.hpp:648] Recovered cpus(*):2; mem(*):256 (total allocatable: mem(*):2048; disk(*):83928; ports(*):[31000-32000]; cpus(*):2) on slave 20150707-142913-16777343-5050-1796-S0 from framework 20150707-142913-16777343-5050-1796-0000
I0707 14:46:40.749760  1803 master.cpp:4690] Removing task 2 with resources cpus(*):2; mem(*):256 of framework 20150707-142913-16777343-5050-1796-0000 on slave 20150707-142913-16777343-5050-1796-S0 at slave(1)@127.0.1.1:5051 (AWM14X)
I0707 14:46:40.750102  1803 master.cpp:2787] Forwarding status update acknowledgement 6f42250a-ff3e-435c-bcb6-2d7990f4e7e5 for task 2 of framework 20150707-142913-16777343-5050-1796-0000 (BioBox-Mesos-Framework_7292) at scheduler-eed21049-4f05-420b-8d01-06b99a18a2da@127.0.1.1:43847 to slave 20150707-142913-16777343-5050-1796-S0 at slave(1)@127.0.1.1:5051 (AWM14X)
I0707 14:46:41.150667  1802 master.cpp:3760] Sending 1 offers to framework 20150707-142913-16777343-5050-1796-0000 (BioBox-Mesos-Framework_7292) at scheduler-eed21049-4f05-420b-8d01-06b99a18a2da@127.0.1.1:43847
I0707 14:46:41.157158  1800 master.cpp:2273] Processing ACCEPT call for offers: [ 20150707-142913-16777343-5050-1796-O18 ] on slave 20150707-142913-16777343-5050-1796-S0 at slave(1)@127.0.1.1:5051 (AWM14X) for framework 20150707-142913-16777343-5050-1796-0000 (BioBox-Mesos-Framework_7292) at scheduler-eed21049-4f05-420b-8d01-06b99a18a2da@127.0.1.1:43847
I0707 14:46:41.158429  1799 hierarchical.hpp:648] Recovered mem(*):2048; disk(*):83928; ports(*):[31000-32000]; cpus(*):2 (total allocatable: mem(*):2048; disk(*):83928; ports(*):[31000-32000]; cpus(*):2) on slave 20150707-142913-16777343-5050-1796-S0 from framework 20150707-142913-16777343-5050-1796-0000
I0707 14:46:42.218925  1804 http.cpp:516] HTTP request for '/master/state.json'
I0707 14:46:47.160410  1803 master.cpp:3760] Sending 1 offers to framework 20150707-142913-16777343-5050-1796-0000 (BioBox-Mesos-Framework_7292) at scheduler-eed21049-4f05-420b-8d01-06b99a18a2da@127.0.1.1:43847
I0707 14:46:47.166699  1805 master.cpp:2273] Processing ACCEPT call for offers: [ 20150707-142913-16777343-5050-1796-O19 ] on slave 20150707-142913-16777343-5050-1796-S0 at slave(1)@127.0.1.1:5051 (AWM14X) for framework 20150707-142913-16777343-5050-1796-0000 (BioBox-Mesos-Framework_7292) at scheduler-eed21049-4f05-420b-8d01-06b99a18a2da@127.0.1.1:43847
I0707 14:46:47.168256  1799 hierarchical.hpp:648] Recovered mem(*):2048; disk(*):83928; ports(*):[31000-32000]; cpus(*):2 (total allocatable: mem(*):2048; disk(*):83928; ports(*):[31000-32000]; cpus(*):2) on slave 20150707-142913-16777343-5050-1796-S0 from framework 20150707-142913-16777343-5050-1796-0000
I0707 14:46:52.242092  1803 http.cpp:516] HTTP request for '/master/state.json'
I0707 14:46:53.170384  1804 master.cpp:3760] Sending 1 offers to framework 20150707-142913-16777343-5050-1796-0000 (BioBox-Mesos-Framework_7292) at scheduler-eed21049-4f05-420b-8d01-06b99a18a2da@127.0.1.1:43847
I0707 14:46:53.176923  1800 master.cpp:2273] Processing ACCEPT call for offers: [ 20150707-142913-16777343-5050-1796-O20 ] on slave 20150707-142913-16777343-5050-1796-S0 at slave(1)@127.0.1.1:5051 (AWM14X) for framework 20150707-142913-16777343-5050-1796-0000 (BioBox-Mesos-Framework_7292) at scheduler-eed21049-4f05-420b-8d01-06b99a18a2da@127.0.1.1:43847
I0707 14:46:53.178921  1801 hierarchical.hpp:648] Recovered mem(*):2048; disk(*):83928; ports(*):[31000-32000]; cpus(*):2 (total allocatable: mem(*):2048; disk(*):83928; ports(*):[31000-32000]; cpus(*):2) on slave 20150707-142913-16777343-5050-1796-S0 from framework 20150707-142913-16777343-5050-1796-0000
I0707 14:46:59.180990  1804 master.cpp:3760] Sending 1 offers to framework 20150707-142913-16777343-5050-1796-0000 (BioBox-Mesos-Framework_7292) at scheduler-eed21049-4f05-420b-8d01-06b99a18a2da@127.0.1.1:43847
I0707 14:46:59.187926  1801 master.cpp:2273] Processing ACCEPT call for offers: [ 20150707-142913-16777343-5050-1796-O21 ] on slave 20150707-142913-16777343-5050-1796-S0 at slave(1)@127.0.1.1:5051 (AWM14X) for framework 20150707-142913-16777343-5050-1796-0000 (BioBox-Mesos-Framework_7292) at scheduler-eed21049-4f05-420b-8d01-06b99a18a2da@127.0.1.1:43847
I0707 14:46:59.190057  1800 hierarchical.hpp:648] Recovered mem(*):2048; disk(*):83928; ports(*):[31000-32000]; cpus(*):2 (total allocatable: mem(*):2048; disk(*):83928; ports(*):[31000-32000]; cpus(*):2) on slave 20150707-142913-16777343-5050-1796-S0 from framework 20150707-142913-16777343-5050-1796-0000
I0707 14:47:02.262249  1798 http.cpp:516] HTTP request for '/master/state.json'
I0707 14:47:05.190176  1802 master.cpp:3760] Sending 1 offers to framework 20150707-142913-16777343-5050-1796-0000 (BioBox-Mesos-Framework_7292) at scheduler-eed21049-4f05-420b-8d01-06b99a18a2da@127.0.1.1:43847
I0707 14:47:05.196655  1801 master.cpp:2273] Processing ACCEPT call for offers: [ 20150707-142913-16777343-5050-1796-O22 ] on slave 20150707-142913-16777343-5050-1796-S0 at slave(1)@127.0.1.1:5051 (AWM14X) for framework 20150707-142913-16777343-5050-1796-0000 (BioBox-Mesos-Framework_7292) at scheduler-eed21049-4f05-420b-8d01-06b99a18a2da@127.0.1.1:43847
I0707 14:47:05.198086  1801 hierarchical.hpp:648] Recovered mem(*):2048; disk(*):83928; ports(*):[31000-32000]; cpus(*):2 (total allocatable: mem(*):2048; disk(*):83928; ports(*):[31000-32000]; cpus(*):2) on slave 20150707-142913-16777343-5050-1796-S0 from framework 20150707-142913-16777343-5050-1796-0000
I0707 14:47:11.200263  1802 master.cpp:3760] Sending 1 offers to framework 20150707-142913-16777343-5050-1796-0000 (BioBox-Mesos-Framework_7292) at scheduler-eed21049-4f05-420b-8d01-06b99a18a2da@127.0.1.1:43847
I0707 14:47:11.206576  1801 master.cpp:2273] Processing ACCEPT call for offers: [ 20150707-142913-16777343-5050-1796-O23 ] on slave 20150707-142913-16777343-5050-1796-S0 at slave(1)@127.0.1.1:5051 (AWM14X) for framework 20150707-142913-16777343-5050-1796-0000 (BioBox-Mesos-Framework_7292) at scheduler-eed21049-4f05-420b-8d01-06b99a18a2da@127.0.1.1:43847
I0707 14:47:11.207725  1801 hierarchical.hpp:648] Recovered mem(*):2048; disk(*):83928; ports(*):[31000-32000]; cpus(*):2 (total allocatable: mem(*):2048; disk(*):83928; ports(*):[31000-32000]; cpus(*):2) on slave 20150707-142913-16777343-5050-1796-S0 from framework 20150707-142913-16777343-5050-1796-0000
I0707 14:47:12.282553  1804 http.cpp:516] HTTP request for '/master/state.json'
I0707 14:47:17.210063  1798 master.cpp:3760] Sending 1 offers to framework 20150707-142913-16777343-5050-1796-0000 (BioBox-Mesos-Framework_7292) at scheduler-eed21049-4f05-420b-8d01-06b99a18a2da@127.0.1.1:43847
I0707 14:47:17.216171  1799 master.cpp:2273] Processing ACCEPT call for offers: [ 20150707-142913-16777343-5050-1796-O24 ] on slave 20150707-142913-16777343-5050-1796-S0 at slave(1)@127.0.1.1:5051 (AWM14X) for framework 20150707-142913-16777343-5050-1796-0000 (BioBox-Mesos-Framework_7292) at scheduler-eed21049-4f05-420b-8d01-06b99a18a2da@127.0.1.1:43847
I0707 14:47:17.218006  1800 hierarchical.hpp:648] Recovered mem(*):2048; disk(*):83928; ports(*):[31000-32000]; cpus(*):2 (total allocatable: mem(*):2048; disk(*):83928; ports(*):[31000-32000]; cpus(*):2) on slave 20150707-142913-16777343-5050-1796-S0 from framework 20150707-142913-16777343-5050-1796-0000
I0707 14:47:22.301345  1800 http.cpp:516] HTTP request for '/master/state.json'
I0707 14:47:23.220203  1803 master.cpp:3760] Sending 1 offers to framework 20150707-142913-16777343-5050-1796-0000 (BioBox-Mesos-Framework_7292) at scheduler-eed21049-4f05-420b-8d01-06b99a18a2da@127.0.1.1:43847
I0707 14:47:23.225972  1798 master.cpp:2273] Processing ACCEPT call for offers: [ 20150707-142913-16777343-5050-1796-O25 ] on slave 20150707-142913-16777343-5050-1796-S0 at slave(1)@127.0.1.1:5051 (AWM14X) for framework 20150707-142913-16777343-5050-1796-0000 (BioBox-Mesos-Framework_7292) at scheduler-eed21049-4f05-420b-8d01-06b99a18a2da@127.0.1.1:43847
I0707 14:47:23.227257  1801 hierarchical.hpp:648] Recovered mem(*):2048; disk(*):83928; ports(*):[31000-32000]; cpus(*):2 (total allocatable: mem(*):2048; disk(*):83928; ports(*):[31000-32000]; cpus(*):2) on slave 20150707-142913-16777343-5050-1796-S0 from framework 20150707-142913-16777343-5050-1796-0000
I0707 14:47:29.229975  1803 master.cpp:3760] Sending 1 offers to framework 20150707-142913-16777343-5050-1796-0000 (BioBox-Mesos-Framework_7292) at scheduler-eed21049-4f05-420b-8d01-06b99a18a2da@127.0.1.1:43847
I0707 14:47:29.237028  1801 master.cpp:2273] Processing ACCEPT call for offers: [ 20150707-142913-16777343-5050-1796-O26 ] on slave 20150707-142913-16777343-5050-1796-S0 at slave(1)@127.0.1.1:5051 (AWM14X) for framework 20150707-142913-16777343-5050-1796-0000 (BioBox-Mesos-Framework_7292) at scheduler-eed21049-4f05-420b-8d01-06b99a18a2da@127.0.1.1:43847
I0707 14:47:29.239159  1798 hierarchical.hpp:648] Recovered mem(*):2048; disk(*):83928; ports(*):[31000-32000]; cpus(*):2 (total allocatable: mem(*):2048; disk(*):83928; ports(*):[31000-32000]; cpus(*):2) on slave 20150707-142913-16777343-5050-1796-S0 from framework 20150707-142913-16777343-5050-1796-0000
I0707 14:47:32.321079  1800 http.cpp:516] HTTP request for '/master/state.json'
I0707 14:47:35.239832  1798 master.cpp:3760] Sending 1 offers to framework 20150707-142913-16777343-5050-1796-0000 (BioBox-Mesos-Framework_7292) at scheduler-eed21049-4f05-420b-8d01-06b99a18a2da@127.0.1.1:43847
I0707 14:47:35.245838  1805 master.cpp:2273] Processing ACCEPT call for offers: [ 20150707-142913-16777343-5050-1796-O27 ] on slave 20150707-142913-16777343-5050-1796-S0 at slave(1)@127.0.1.1:5051 (AWM14X) for framework 20150707-142913-16777343-5050-1796-0000 (BioBox-Mesos-Framework_7292) at scheduler-eed21049-4f05-420b-8d01-06b99a18a2da@127.0.1.1:43847
I0707 14:47:35.246966  1805 hierarchical.hpp:648] Recovered mem(*):2048; disk(*):83928; ports(*):[31000-32000]; cpus(*):2 (total allocatable: mem(*):2048; disk(*):83928; ports(*):[31000-32000]; cpus(*):2) on slave 20150707-142913-16777343-5050-1796-S0 from framework 20150707-142913-16777343-5050-1796-0000
I0707 14:47:40.248854  1800 master.cpp:3760] Sending 1 offers to framework 20150707-142913-16777343-5050-1796-0000 (BioBox-Mesos-Framework_7292) at scheduler-eed21049-4f05-420b-8d01-06b99a18a2da@127.0.1.1:43847
I0707 14:47:40.255825  1798 master.cpp:2273] Processing ACCEPT call for offers: [ 20150707-142913-16777343-5050-1796-O28 ] on slave 20150707-142913-16777343-5050-1796-S0 at slave(1)@127.0.1.1:5051 (AWM14X) for framework 20150707-142913-16777343-5050-1796-0000 (BioBox-Mesos-Framework_7292) at scheduler-eed21049-4f05-420b-8d01-06b99a18a2da@127.0.1.1:43847
I0707 14:47:40.257313  1798 hierarchical.hpp:648] Recovered mem(*):2048; disk(*):83928; ports(*):[31000-32000]; cpus(*):2 (total allocatable: mem(*):2048; disk(*):83928; ports(*):[31000-32000]; cpus(*):2) on slave 20150707-142913-16777343-5050-1796-S0 from framework 20150707-142913-16777343-5050-1796-0000
I0707 14:47:42.340405  1801 http.cpp:516] HTTP request for '/master/state.json'
I0707 14:47:46.259814  1803 master.cpp:3760] Sending 1 offers to framework 20150707-142913-16777343-5050-1796-0000 (BioBox-Mesos-Framework_7292) at scheduler-eed21049-4f05-420b-8d01-06b99a18a2da@127.0.1.1:43847
I0707 14:47:46.266378  1798 master.cpp:2273] Processing ACCEPT call for offers: [ 20150707-142913-16777343-5050-1796-O29 ] on slave 20150707-142913-16777343-5050-1796-S0 at slave(1)@127.0.1.1:5051 (AWM14X) for framework 20150707-142913-16777343-5050-1796-0000 (BioBox-Mesos-Framework_7292) at scheduler-eed21049-4f05-420b-8d01-06b99a18a2da@127.0.1.1:43847
I0707 14:47:46.267663  1798 hierarchical.hpp:648] Recovered mem(*):2048; disk(*):83928; ports(*):[31000-32000]; cpus(*):2 (total allocatable: mem(*):2048; disk(*):83928; ports(*):[31000-32000]; cpus(*):2) on slave 20150707-142913-16777343-5050-1796-S0 from framework 20150707-142913-16777343-5050-1796-0000
I0707 14:47:52.269776  1798 master.cpp:3760] Sending 1 offers to framework 20150707-142913-16777343-5050-1796-0000 (BioBox-Mesos-Framework_7292) at scheduler-eed21049-4f05-420b-8d01-06b99a18a2da@127.0.1.1:43847
I0707 14:47:52.276264  1805 master.cpp:2273] Processing ACCEPT call for offers: [ 20150707-142913-16777343-5050-1796-O30 ] on slave 20150707-142913-16777343-5050-1796-S0 at slave(1)@127.0.1.1:5051 (AWM14X) for framework 20150707-142913-16777343-5050-1796-0000 (BioBox-Mesos-Framework_7292) at scheduler-eed21049-4f05-420b-8d01-06b99a18a2da@127.0.1.1:43847
I0707 14:47:52.277503  1805 hierarchical.hpp:648] Recovered mem(*):2048; disk(*):83928; ports(*):[31000-32000]; cpus(*):2 (total allocatable: mem(*):2048; disk(*):83928; ports(*):[31000-32000]; cpus(*):2) on slave 20150707-142913-16777343-5050-1796-S0 from framework 20150707-142913-16777343-5050-1796-0000
I0707 14:47:52.360095  1802 http.cpp:516] HTTP request for '/master/state.json'
I0707 14:47:58.280031  1798 master.cpp:3760] Sending 1 offers to framework 20150707-142913-16777343-5050-1796-0000 (BioBox-Mesos-Framework_7292) at scheduler-eed21049-4f05-420b-8d01-06b99a18a2da@127.0.1.1:43847
I0707 14:47:58.286777  1805 master.cpp:2273] Processing ACCEPT call for offers: [ 20150707-142913-16777343-5050-1796-O31 ] on slave 20150707-142913-16777343-5050-1796-S0 at slave(1)@127.0.1.1:5051 (AWM14X) for framework 20150707-142913-16777343-5050-1796-0000 (BioBox-Mesos-Framework_7292) at scheduler-eed21049-4f05-420b-8d01-06b99a18a2da@127.0.1.1:43847
I0707 14:47:58.288012  1805 hierarchical.hpp:648] Recovered mem(*):2048; disk(*):83928; ports(*):[31000-32000]; cpus(*):2 (total allocatable: mem(*):2048; disk(*):83928; ports(*):[31000-32000]; cpus(*):2) on slave 20150707-142913-16777343-5050-1796-S0 from framework 20150707-142913-16777343-5050-1796-0000
I0707 14:48:02.379019  1801 http.cpp:516] HTTP request for '/master/state.json'
I0707 14:48:04.290954  1805 master.cpp:3760] Sending 1 offers to framework 20150707-142913-16777343-5050-1796-0000 (BioBox-Mesos-Framework_7292) at scheduler-eed21049-4f05-420b-8d01-06b99a18a2da@127.0.1.1:43847
I0707 14:48:04.297925  1802 master.cpp:2273] Processing ACCEPT call for offers: [ 20150707-142913-16777343-5050-1796-O32 ] on slave 20150707-142913-16777343-5050-1796-S0 at slave(1)@127.0.1.1:5051 (AWM14X) for framework 20150707-142913-16777343-5050-1796-0000 (BioBox-Mesos-Framework_7292) at scheduler-eed21049-4f05-420b-8d01-06b99a18a2da@127.0.1.1:43847
I0707 14:48:04.299226  1802 hierarchical.hpp:648] Recovered mem(*):2048; disk(*):83928; ports(*):[31000-32000]; cpus(*):2 (total allocatable: mem(*):2048; disk(*):83928; ports(*):[31000-32000]; cpus(*):2) on slave 20150707-142913-16777343-5050-1796-S0 from framework 20150707-142913-16777343-5050-1796-0000
I0707 14:48:10.301681  1805 master.cpp:3760] Sending 1 offers to framework 20150707-142913-16777343-5050-1796-0000 (BioBox-Mesos-Framework_7292) at scheduler-eed21049-4f05-420b-8d01-06b99a18a2da@127.0.1.1:43847
I0707 14:48:10.308420  1802 master.cpp:2273] Processing ACCEPT call for offers: [ 20150707-142913-16777343-5050-1796-O33 ] on slave 20150707-142913-16777343-5050-1796-S0 at slave(1)@127.0.1.1:5051 (AWM14X) for framework 20150707-142913-16777343-5050-1796-0000 (BioBox-Mesos-Framework_7292) at scheduler-eed21049-4f05-420b-8d01-06b99a18a2da@127.0.1.1:43847
I0707 14:48:10.309994  1798 hierarchical.hpp:648] Recovered mem(*):2048; disk(*):83928; ports(*):[31000-32000]; cpus(*):2 (total allocatable: mem(*):2048; disk(*):83928; ports(*):[31000-32000]; cpus(*):2) on slave 20150707-142913-16777343-5050-1796-S0 from framework 20150707-142913-16777343-5050-1796-0000
I0707 14:48:12.399468  1800 http.cpp:516] HTTP request for '/master/state.json'
I0707 14:48:16.312381  1802 master.cpp:3760] Sending 1 offers to framework 20150707-142913-16777343-5050-1796-0000 (BioBox-Mesos-Framework_7292) at scheduler-eed21049-4f05-420b-8d01-06b99a18a2da@127.0.1.1:43847
I0707 14:48:16.318943  1804 master.cpp:2273] Processing ACCEPT call for offers: [ 20150707-142913-16777343-5050-1796-O34 ] on slave 20150707-142913-16777343-5050-1796-S0 at slave(1)@127.0.1.1:5051 (AWM14X) for framework 20150707-142913-16777343-5050-1796-0000 (BioBox-Mesos-Framework_7292) at scheduler-eed21049-4f05-420b-8d01-06b99a18a2da@127.0.1.1:43847
I0707 14:48:16.320622  1798 hierarchical.hpp:648] Recovered mem(*):2048; disk(*):83928; ports(*):[31000-32000]; cpus(*):2 (total allocatable: mem(*):2048; disk(*):83928; ports(*):[31000-32000]; cpus(*):2) on slave 20150707-142913-16777343-5050-1796-S0 from framework 20150707-142913-16777343-5050-1796-0000
I0707 14:48:22.323583  1801 master.cpp:3760] Sending 1 offers to framework 20150707-142913-16777343-5050-1796-0000 (BioBox-Mesos-Framework_7292) at scheduler-eed21049-4f05-420b-8d01-06b99a18a2da@127.0.1.1:43847
I0707 14:48:22.330600  1798 master.cpp:2273] Processing ACCEPT call for offers: [ 20150707-142913-16777343-5050-1796-O35 ] on slave 20150707-142913-16777343-5050-1796-S0 at slave(1)@127.0.1.1:5051 (AWM14X) for framework 20150707-142913-16777343-5050-1796-0000 (BioBox-Mesos-Framework_7292) at scheduler-eed21049-4f05-420b-8d01-06b99a18a2da@127.0.1.1:43847
I0707 14:48:22.332535  1803 hierarchical.hpp:648] Recovered mem(*):2048; disk(*):83928; ports(*):[31000-32000]; cpus(*):2 (total allocatable: mem(*):2048; disk(*):83928; ports(*):[31000-32000]; cpus(*):2) on slave 20150707-142913-16777343-5050-1796-S0 from framework 20150707-142913-16777343-5050-1796-0000
I0707 14:48:22.418133  1798 http.cpp:516] HTTP request for '/master/state.json'
I0707 14:48:28.331595  1801 master.cpp:3760] Sending 1 offers to framework 20150707-142913-16777343-5050-1796-0000 (BioBox-Mesos-Framework_7292) at scheduler-eed21049-4f05-420b-8d01-06b99a18a2da@127.0.1.1:43847
I0707 14:48:28.335209  1799 master.cpp:2273] Processing ACCEPT call for offers: [ 20150707-142913-16777343-5050-1796-O36 ] on slave 20150707-142913-16777343-5050-1796-S0 at slave(1)@127.0.1.1:5051 (AWM14X) for framework 20150707-142913-16777343-5050-1796-0000 (BioBox-Mesos-Framework_7292) at scheduler-eed21049-4f05-420b-8d01-06b99a18a2da@127.0.1.1:43847
I0707 14:48:28.335829  1799 hierarchical.hpp:648] Recovered mem(*):2048; disk(*):83928; ports(*):[31000-32000]; cpus(*):2 (total allocatable: mem(*):2048; disk(*):83928; ports(*):[31000-32000]; cpus(*):2) on slave 20150707-142913-16777343-5050-1796-S0 from framework 20150707-142913-16777343-5050-1796-0000
I0707 14:48:32.435734  1800 http.cpp:516] HTTP request for '/master/state.json'
I0707 14:48:33.339640  1804 master.cpp:3760] Sending 1 offers to framework 20150707-142913-16777343-5050-1796-0000 (BioBox-Mesos-Framework_7292) at scheduler-eed21049-4f05-420b-8d01-06b99a18a2da@127.0.1.1:43847
I0707 14:48:33.343122  1803 master.cpp:2273] Processing ACCEPT call for offers: [ 20150707-142913-16777343-5050-1796-O37 ] on slave 20150707-142913-16777343-5050-1796-S0 at slave(1)@127.0.1.1:5051 (AWM14X) for framework 20150707-142913-16777343-5050-1796-0000 (BioBox-Mesos-Framework_7292) at scheduler-eed21049-4f05-420b-8d01-06b99a18a2da@127.0.1.1:43847
I0707 14:48:33.343930  1803 hierarchical.hpp:648] Recovered mem(*):2048; disk(*):83928; ports(*):[31000-32000]; cpus(*):2 (total allocatable: mem(*):2048; disk(*):83928; ports(*):[31000-32000]; cpus(*):2) on slave 20150707-142913-16777343-5050-1796-S0 from framework 20150707-142913-16777343-5050-1796-0000
I0707 14:48:38.346290  1804 master.cpp:3760] Sending 1 offers to framework 20150707-142913-16777343-5050-1796-0000 (BioBox-Mesos-Framework_7292) at scheduler-eed21049-4f05-420b-8d01-06b99a18a2da@127.0.1.1:43847
I0707 14:48:38.351197  1803 master.cpp:2273] Processing ACCEPT call for offers: [ 20150707-142913-16777343-5050-1796-O38 ] on slave 20150707-142913-16777343-5050-1796-S0 at slave(1)@127.0.1.1:5051 (AWM14X) for framework 20150707-142913-16777343-5050-1796-0000 (BioBox-Mesos-Framework_7292) at scheduler-eed21049-4f05-420b-8d01-06b99a18a2da@127.0.1.1:43847
I0707 14:48:38.352027  1805 hierarchical.hpp:648] Recovered mem(*):2048; disk(*):83928; ports(*):[31000-32000]; cpus(*):2 (total allocatable: mem(*):2048; disk(*):83928; ports(*):[31000-32000]; cpus(*):2) on slave 20150707-142913-16777343-5050-1796-S0 from framework 20150707-142913-16777343-5050-1796-0000
I0707 14:48:42.454032  1799 http.cpp:516] HTTP request for '/master/state.json'
I0707 14:48:43.354279  1804 master.cpp:3760] Sending 1 offers to framework 20150707-142913-16777343-5050-1796-0000 (BioBox-Mesos-Framework_7292) at scheduler-eed21049-4f05-420b-8d01-06b99a18a2da@127.0.1.1:43847
I0707 14:48:43.361048  1805 master.cpp:2273] Processing ACCEPT call for offers: [ 20150707-142913-16777343-5050-1796-O39 ] on slave 20150707-142913-16777343-5050-1796-S0 at slave(1)@127.0.1.1:5051 (AWM14X) for framework 20150707-142913-16777343-5050-1796-0000 (BioBox-Mesos-Framework_7292) at scheduler-eed21049-4f05-420b-8d01-06b99a18a2da@127.0.1.1:43847
I0707 14:48:43.362388  1805 hierarchical.hpp:648] Recovered mem(*):2048; disk(*):83928; ports(*):[31000-32000]; cpus(*):2 (total allocatable: mem(*):2048; disk(*):83928; ports(*):[31000-32000]; cpus(*):2) on slave 20150707-142913-16777343-5050-1796-S0 from framework 20150707-142913-16777343-5050-1796-0000
I0707 14:48:49.365134  1805 master.cpp:3760] Sending 1 offers to framework 20150707-142913-16777343-5050-1796-0000 (BioBox-Mesos-Framework_7292) at scheduler-eed21049-4f05-420b-8d01-06b99a18a2da@127.0.1.1:43847
I0707 14:48:49.371556  1802 master.cpp:2273] Processing ACCEPT call for offers: [ 20150707-142913-16777343-5050-1796-O40 ] on slave 20150707-142913-16777343-5050-1796-S0 at slave(1)@127.0.1.1:5051 (AWM14X) for framework 20150707-142913-16777343-5050-1796-0000 (BioBox-Mesos-Framework_7292) at scheduler-eed21049-4f05-420b-8d01-06b99a18a2da@127.0.1.1:43847
I0707 14:48:49.373358  1803 hierarchical.hpp:648] Recovered mem(*):2048; disk(*):83928; ports(*):[31000-32000]; cpus(*):2 (total allocatable: mem(*):2048; disk(*):83928; ports(*):[31000-32000]; cpus(*):2) on slave 20150707-142913-16777343-5050-1796-S0 from framework 20150707-142913-16777343-5050-1796-0000
I0707 14:48:52.474076  1799 http.cpp:516] HTTP request for '/master/state.json'
I0707 14:48:55.375634  1805 master.cpp:3760] Sending 1 offers to framework 20150707-142913-16777343-5050-1796-0000 (BioBox-Mesos-Framework_7292) at scheduler-eed21049-4f05-420b-8d01-06b99a18a2da@127.0.1.1:43847
I0707 14:48:55.381954  1798 master.cpp:2273] Processing ACCEPT call for offers: [ 20150707-142913-16777343-5050-1796-O41 ] on slave 20150707-142913-16777343-5050-1796-S0 at slave(1)@127.0.1.1:5051 (AWM14X) for framework 20150707-142913-16777343-5050-1796-0000 (BioBox-Mesos-Framework_7292) at scheduler-eed21049-4f05-420b-8d01-06b99a18a2da@127.0.1.1:43847
I0707 14:48:55.383488  1801 hierarchical.hpp:648] Recovered mem(*):2048; disk(*):83928; ports(*):[31000-32000]; cpus(*):2 (total allocatable: mem(*):2048; disk(*):83928; ports(*):[31000-32000]; cpus(*):2) on slave 20150707-142913-16777343-5050-1796-S0 from framework 20150707-142913-16777343-5050-1796-0000
I0707 14:49:01.385663  1805 master.cpp:3760] Sending 1 offers to framework 20150707-142913-16777343-5050-1796-0000 (BioBox-Mesos-Framework_7292) at scheduler-eed21049-4f05-420b-8d01-06b99a18a2da@127.0.1.1:43847
I0707 14:49:01.392781  1801 master.cpp:2273] Processing ACCEPT call for offers: [ 20150707-142913-16777343-5050-1796-O42 ] on slave 20150707-142913-16777343-5050-1796-S0 at slave(1)@127.0.1.1:5051 (AWM14X) for framework 20150707-142913-16777343-5050-1796-0000 (BioBox-Mesos-Framework_7292) at scheduler-eed21049-4f05-420b-8d01-06b99a18a2da@127.0.1.1:43847
I0707 14:49:01.394734  1803 hierarchical.hpp:648] Recovered mem(*):2048; disk(*):83928; ports(*):[31000-32000]; cpus(*):2 (total allocatable: mem(*):2048; disk(*):83928; ports(*):[31000-32000]; cpus(*):2) on slave 20150707-142913-16777343-5050-1796-S0 from framework 20150707-142913-16777343-5050-1796-0000
I0707 14:49:02.494542  1804 http.cpp:516] HTTP request for '/master/state.json'
I0707 14:49:07.397020  1805 master.cpp:3760] Sending 1 offers to framework 20150707-142913-16777343-5050-1796-0000 (BioBox-Mesos-Framework_7292) at scheduler-eed21049-4f05-420b-8d01-06b99a18a2da@127.0.1.1:43847
I0707 14:49:07.403328  1799 master.cpp:2273] Processing ACCEPT call for offers: [ 20150707-142913-16777343-5050-1796-O43 ] on slave 20150707-142913-16777343-5050-1796-S0 at slave(1)@127.0.1.1:5051 (AWM14X) for framework 20150707-142913-16777343-5050-1796-0000 (BioBox-Mesos-Framework_7292) at scheduler-eed21049-4f05-420b-8d01-06b99a18a2da@127.0.1.1:43847
I0707 14:49:07.404708  1804 hierarchical.hpp:648] Recovered mem(*):2048; disk(*):83928; ports(*):[31000-32000]; cpus(*):2 (total allocatable: mem(*):2048; disk(*):83928; ports(*):[31000-32000]; cpus(*):2) on slave 20150707-142913-16777343-5050-1796-S0 from framework 20150707-142913-16777343-5050-1796-0000
I0707 14:49:12.509799  1802 http.cpp:516] HTTP request for '/master/state.json'
I0707 14:49:13.404130  1805 master.cpp:3760] Sending 1 offers to framework 20150707-142913-16777343-5050-1796-0000 (BioBox-Mesos-Framework_7292) at scheduler-eed21049-4f05-420b-8d01-06b99a18a2da@127.0.1.1:43847
I0707 14:49:13.407215  1802 master.cpp:2273] Processing ACCEPT call for offers: [ 20150707-142913-16777343-5050-1796-O44 ] on slave 20150707-142913-16777343-5050-1796-S0 at slave(1)@127.0.1.1:5051 (AWM14X) for framework 20150707-142913-16777343-5050-1796-0000 (BioBox-Mesos-Framework_7292) at scheduler-eed21049-4f05-420b-8d01-06b99a18a2da@127.0.1.1:43847
I0707 14:49:13.407829  1804 hierarchical.hpp:648] Recovered mem(*):2048; disk(*):83928; ports(*):[31000-32000]; cpus(*):2 (total allocatable: mem(*):2048; disk(*):83928; ports(*):[31000-32000]; cpus(*):2) on slave 20150707-142913-16777343-5050-1796-S0 from framework 20150707-142913-16777343-5050-1796-0000
I0707 14:49:18.411399  1805 master.cpp:3760] Sending 1 offers to framework 20150707-142913-16777343-5050-1796-0000 (BioBox-Mesos-Framework_7292) at scheduler-eed21049-4f05-420b-8d01-06b99a18a2da@127.0.1.1:43847
I0707 14:49:18.417525  1804 master.cpp:2273] Processing ACCEPT call for offers: [ 20150707-142913-16777343-5050-1796-O45 ] on slave 20150707-142913-16777343-5050-1796-S0 at slave(1)@127.0.1.1:5051 (AWM14X) for framework 20150707-142913-16777343-5050-1796-0000 (BioBox-Mesos-Framework_7292) at scheduler-eed21049-4f05-420b-8d01-06b99a18a2da@127.0.1.1:43847
I0707 14:49:18.418869  1804 hierarchical.hpp:648] Recovered mem(*):2048; disk(*):83928; ports(*):[31000-32000]; cpus(*):2 (total allocatable: mem(*):2048; disk(*):83928; ports(*):[31000-32000]; cpus(*):2) on slave 20150707-142913-16777343-5050-1796-S0 from framework 20150707-142913-16777343-5050-1796-0000
I0707 14:49:22.524813  1801 http.cpp:516] HTTP request for '/master/state.json'
I0707 14:49:23.420874  1805 master.cpp:3760] Sending 1 offers to framework 20150707-142913-16777343-5050-1796-0000 (BioBox-Mesos-Framework_7292) at scheduler-eed21049-4f05-420b-8d01-06b99a18a2da@127.0.1.1:43847
I0707 14:49:23.425107  1804 master.cpp:2273] Processing ACCEPT call for offers: [ 20150707-142913-16777343-5050-1796-O46 ] on slave 20150707-142913-16777343-5050-1796-S0 at slave(1)@127.0.1.1:5051 (AWM14X) for framework 20150707-142913-16777343-5050-1796-0000 (BioBox-Mesos-Framework_7292) at scheduler-eed21049-4f05-420b-8d01-06b99a18a2da@127.0.1.1:43847
I0707 14:49:23.426513  1804 hierarchical.hpp:648] Recovered mem(*):2048; disk(*):83928; ports(*):[31000-32000]; cpus(*):2 (total allocatable: mem(*):2048; disk(*):83928; ports(*):[31000-32000]; cpus(*):2) on slave 20150707-142913-16777343-5050-1796-S0 from framework 20150707-142913-16777343-5050-1796-0000
I0707 14:49:28.429318  1802 master.cpp:3760] Sending 1 offers to framework 20150707-142913-16777343-5050-1796-0000 (BioBox-Mesos-Framework_7292) at scheduler-eed21049-4f05-420b-8d01-06b99a18a2da@127.0.1.1:43847
I0707 14:49:28.436424  1804 master.cpp:2273] Processing ACCEPT call for offers: [ 20150707-142913-16777343-5050-1796-O47 ] on slave 20150707-142913-16777343-5050-1796-S0 at slave(1)@127.0.1.1:5051 (AWM14X) for framework 20150707-142913-16777343-5050-1796-0000 (BioBox-Mesos-Framework_7292) at scheduler-eed21049-4f05-420b-8d01-06b99a18a2da@127.0.1.1:43847
I0707 14:49:28.438539  1803 hierarchical.hpp:648] Recovered mem(*):2048; disk(*):83928; ports(*):[31000-32000]; cpus(*):2 (total allocatable: mem(*):2048; disk(*):83928; ports(*):[31000-32000]; cpus(*):2) on slave 20150707-142913-16777343-5050-1796-S0 from framework 20150707-142913-16777343-5050-1796-0000
I0707 14:49:32.545367  1798 http.cpp:516] HTTP request for '/master/state.json'
I0707 14:49:34.438138  1800 master.cpp:3760] Sending 1 offers to framework 20150707-142913-16777343-5050-1796-0000 (BioBox-Mesos-Framework_7292) at scheduler-eed21049-4f05-420b-8d01-06b99a18a2da@127.0.1.1:43847
I0707 14:49:34.444667  1799 master.cpp:2273] Processing ACCEPT call for offers: [ 20150707-142913-16777343-5050-1796-O48 ] on slave 20150707-142913-16777343-5050-1796-S0 at slave(1)@127.0.1.1:5051 (AWM14X) for framework 20150707-142913-16777343-5050-1796-0000 (BioBox-Mesos-Framework_7292) at scheduler-eed21049-4f05-420b-8d01-06b99a18a2da@127.0.1.1:43847
I0707 14:49:34.446112  1799 hierarchical.hpp:648] Recovered mem(*):2048; disk(*):83928; ports(*):[31000-32000]; cpus(*):2 (total allocatable: mem(*):2048; disk(*):83928; ports(*):[31000-32000]; cpus(*):2) on slave 20150707-142913-16777343-5050-1796-S0 from framework 20150707-142913-16777343-5050-1796-0000
I0707 14:49:40.447824  1800 master.cpp:3760] Sending 1 offers to framework 20150707-142913-16777343-5050-1796-0000 (BioBox-Mesos-Framework_7292) at scheduler-eed21049-4f05-420b-8d01-06b99a18a2da@127.0.1.1:43847
I0707 14:49:40.454277  1799 master.cpp:2273] Processing ACCEPT call for offers: [ 20150707-142913-16777343-5050-1796-O49 ] on slave 20150707-142913-16777343-5050-1796-S0 at slave(1)@127.0.1.1:5051 (AWM14X) for framework 20150707-142913-16777343-5050-1796-0000 (BioBox-Mesos-Framework_7292) at scheduler-eed21049-4f05-420b-8d01-06b99a18a2da@127.0.1.1:43847
I0707 14:49:40.455540  1799 hierarchical.hpp:648] Recovered mem(*):2048; disk(*):83928; ports(*):[31000-32000]; cpus(*):2 (total allocatable: mem(*):2048; disk(*):83928; ports(*):[31000-32000]; cpus(*):2) on slave 20150707-142913-16777343-5050-1796-S0 from framework 20150707-142913-16777343-5050-1796-0000
I0707 14:49:42.565345  1798 http.cpp:516] HTTP request for '/master/state.json'
I0707 14:49:46.457425  1799 master.cpp:3760] Sending 1 offers to framework 20150707-142913-16777343-5050-1796-0000 (BioBox-Mesos-Framework_7292) at scheduler-eed21049-4f05-420b-8d01-06b99a18a2da@127.0.1.1:43847
I0707 14:49:46.464179  1805 master.cpp:2273] Processing ACCEPT call for offers: [ 20150707-142913-16777343-5050-1796-O50 ] on slave 20150707-142913-16777343-5050-1796-S0 at slave(1)@127.0.1.1:5051 (AWM14X) for framework 20150707-142913-16777343-5050-1796-0000 (BioBox-Mesos-Framework_7292) at scheduler-eed21049-4f05-420b-8d01-06b99a18a2da@127.0.1.1:43847
I0707 14:49:46.466125  1802 hierarchical.hpp:648] Recovered mem(*):2048; disk(*):83928; ports(*):[31000-32000]; cpus(*):2 (total allocatable: mem(*):2048; disk(*):83928; ports(*):[31000-32000]; cpus(*):2) on slave 20150707-142913-16777343-5050-1796-S0 from framework 20150707-142913-16777343-5050-1796-0000
I0707 14:49:52.467743  1802 master.cpp:3760] Sending 1 offers to framework 20150707-142913-16777343-5050-1796-0000 (BioBox-Mesos-Framework_7292) at scheduler-eed21049-4f05-420b-8d01-06b99a18a2da@127.0.1.1:43847
I0707 14:49:52.474366  1805 master.cpp:2273] Processing ACCEPT call for offers: [ 20150707-142913-16777343-5050-1796-O51 ] on slave 20150707-142913-16777343-5050-1796-S0 at slave(1)@127.0.1.1:5051 (AWM14X) for framework 20150707-142913-16777343-5050-1796-0000 (BioBox-Mesos-Framework_7292) at scheduler-eed21049-4f05-420b-8d01-06b99a18a2da@127.0.1.1:43847
I0707 14:49:52.475723  1805 hierarchical.hpp:648] Recovered mem(*):2048; disk(*):83928; ports(*):[31000-32000]; cpus(*):2 (total allocatable: mem(*):2048; disk(*):83928; ports(*):[31000-32000]; cpus(*):2) on slave 20150707-142913-16777343-5050-1796-S0 from framework 20150707-142913-16777343-5050-1796-0000
I0707 14:49:52.585986  1804 http.cpp:516] HTTP request for '/master/state.json'
I0707 14:49:58.477594  1805 master.cpp:3760] Sending 1 offers to framework 20150707-142913-16777343-5050-1796-0000 (BioBox-Mesos-Framework_7292) at scheduler-eed21049-4f05-420b-8d01-06b99a18a2da@127.0.1.1:43847
I0707 14:49:58.484527  1799 master.cpp:2273] Processing ACCEPT call for offers: [ 20150707-142913-16777343-5050-1796-O52 ] on slave 20150707-142913-16777343-5050-1796-S0 at slave(1)@127.0.1.1:5051 (AWM14X) for framework 20150707-142913-16777343-5050-1796-0000 (BioBox-Mesos-Framework_7292) at scheduler-eed21049-4f05-420b-8d01-06b99a18a2da@127.0.1.1:43847
I0707 14:49:58.486143  1798 hierarchical.hpp:648] Recovered mem(*):2048; disk(*):83928; ports(*):[31000-32000]; cpus(*):2 (total allocatable: mem(*):2048; disk(*):83928; ports(*):[31000-32000]; cpus(*):2) on slave 20150707-142913-16777343-5050-1796-S0 from framework 20150707-142913-16777343-5050-1796-0000
I0707 14:50:02.606699  1800 http.cpp:516] HTTP request for '/master/state.json'
I0707 14:50:04.488212  1804 master.cpp:3760] Sending 1 offers to framework 20150707-142913-16777343-5050-1796-0000 (BioBox-Mesos-Framework_7292) at scheduler-eed21049-4f05-420b-8d01-06b99a18a2da@127.0.1.1:43847
I0707 14:50:04.495015  1802 master.cpp:2273] Processing ACCEPT call for offers: [ 20150707-142913-16777343-5050-1796-O53 ] on slave 20150707-142913-16777343-5050-1796-S0 at slave(1)@127.0.1.1:5051 (AWM14X) for framework 20150707-142913-16777343-5050-1796-0000 (BioBox-Mesos-Framework_7292) at scheduler-eed21049-4f05-420b-8d01-06b99a18a2da@127.0.1.1:43847
I0707 14:50:04.496999  1801 hierarchical.hpp:648] Recovered mem(*):2048; disk(*):83928; ports(*):[31000-32000]; cpus(*):2 (total allocatable: mem(*):2048; disk(*):83928; ports(*):[31000-32000]; cpus(*):2) on slave 20150707-142913-16777343-5050-1796-S0 from framework 20150707-142913-16777343-5050-1796-0000
I0707 14:50:10.498250  1801 master.cpp:3760] Sending 1 offers to framework 20150707-142913-16777343-5050-1796-0000 (BioBox-Mesos-Framework_7292) at scheduler-eed21049-4f05-420b-8d01-06b99a18a2da@127.0.1.1:43847
I0707 14:50:10.504670  1800 master.cpp:2273] Processing ACCEPT call for offers: [ 20150707-142913-16777343-5050-1796-O54 ] on slave 20150707-142913-16777343-5050-1796-S0 at slave(1)@127.0.1.1:5051 (AWM14X) for framework 20150707-142913-16777343-5050-1796-0000 (BioBox-Mesos-Framework_7292) at scheduler-eed21049-4f05-420b-8d01-06b99a18a2da@127.0.1.1:43847
I0707 14:50:10.506151  1800 hierarchical.hpp:648] Recovered mem(*):2048; disk(*):83928; ports(*):[31000-32000]; cpus(*):2 (total allocatable: mem(*):2048; disk(*):83928; ports(*):[31000-32000]; cpus(*):2) on slave 20150707-142913-16777343-5050-1796-S0 from framework 20150707-142913-16777343-5050-1796-0000
I0707 14:50:12.625737  1799 http.cpp:516] HTTP request for '/master/state.json'
I0707 14:50:16.508599  1804 master.cpp:3760] Sending 1 offers to framework 20150707-142913-16777343-5050-1796-0000 (BioBox-Mesos-Framework_7292) at scheduler-eed21049-4f05-420b-8d01-06b99a18a2da@127.0.1.1:43847
I0707 14:50:16.515210  1803 master.cpp:2273] Processing ACCEPT call for offers: [ 20150707-142913-16777343-5050-1796-O55 ] on slave 20150707-142913-16777343-5050-1796-S0 at slave(1)@127.0.1.1:5051 (AWM14X) for framework 20150707-142913-16777343-5050-1796-0000 (BioBox-Mesos-Framework_7292) at scheduler-eed21049-4f05-420b-8d01-06b99a18a2da@127.0.1.1:43847
I0707 14:50:16.516461  1800 hierarchical.hpp:648] Recovered mem(*):2048; disk(*):83928; ports(*):[31000-32000]; cpus(*):2 (total allocatable: mem(*):2048; disk(*):83928; ports(*):[31000-32000]; cpus(*):2) on slave 20150707-142913-16777343-5050-1796-S0 from framework 20150707-142913-16777343-5050-1796-0000
I0707 14:50:21.518473  1804 master.cpp:3760] Sending 1 offers to framework 20150707-142913-16777343-5050-1796-0000 (BioBox-Mesos-Framework_7292) at scheduler-eed21049-4f05-420b-8d01-06b99a18a2da@127.0.1.1:43847
I0707 14:50:21.525632  1800 master.cpp:2273] Processing ACCEPT call for offers: [ 20150707-142913-16777343-5050-1796-O56 ] on slave 20150707-142913-16777343-5050-1796-S0 at slave(1)@127.0.1.1:5051 (AWM14X) for framework 20150707-142913-16777343-5050-1796-0000 (BioBox-Mesos-Framework_7292) at scheduler-eed21049-4f05-420b-8d01-06b99a18a2da@127.0.1.1:43847
I0707 14:50:21.527680  1803 hierarchical.hpp:648] Recovered mem(*):2048; disk(*):83928; ports(*):[31000-32000]; cpus(*):2 (total allocatable: mem(*):2048; disk(*):83928; ports(*):[31000-32000]; cpus(*):2) on slave 20150707-142913-16777343-5050-1796-S0 from framework 20150707-142913-16777343-5050-1796-0000
I0707 14:50:22.645694  1802 http.cpp:516] HTTP request for '/master/state.json'
I0707 14:50:27.528821  1799 master.cpp:3760] Sending 1 offers to framework 20150707-142913-16777343-5050-1796-0000 (BioBox-Mesos-Framework_7292) at scheduler-eed21049-4f05-420b-8d01-06b99a18a2da@127.0.1.1:43847
I0707 14:50:27.535267  1804 master.cpp:2273] Processing ACCEPT call for offers: [ 20150707-142913-16777343-5050-1796-O57 ] on slave 20150707-142913-16777343-5050-1796-S0 at slave(1)@127.0.1.1:5051 (AWM14X) for framework 20150707-142913-16777343-5050-1796-0000 (BioBox-Mesos-Framework_7292) at scheduler-eed21049-4f05-420b-8d01-06b99a18a2da@127.0.1.1:43847
I0707 14:50:27.536759  1804 hierarchical.hpp:648] Recovered mem(*):2048; disk(*):83928; ports(*):[31000-32000]; cpus(*):2 (total allocatable: mem(*):2048; disk(*):83928; ports(*):[31000-32000]; cpus(*):2) on slave 20150707-142913-16777343-5050-1796-S0 from framework 20150707-142913-16777343-5050-1796-0000
I0707 14:50:32.665851  1805 http.cpp:516] HTTP request for '/master/state.json'
I0707 14:50:33.538672  1801 master.cpp:3760] Sending 1 offers to framework 20150707-142913-16777343-5050-1796-0000 (BioBox-Mesos-Framework_7292) at scheduler-eed21049-4f05-420b-8d01-06b99a18a2da@127.0.1.1:43847
I0707 14:50:33.545146  1804 master.cpp:2273] Processing ACCEPT call for offers: [ 20150707-142913-16777343-5050-1796-O58 ] on slave 20150707-142913-16777343-5050-1796-S0 at slave(1)@127.0.1.1:5051 (AWM14X) for framework 20150707-142913-16777343-5050-1796-0000 (BioBox-Mesos-Framework_7292) at scheduler-eed21049-4f05-420b-8d01-06b99a18a2da@127.0.1.1:43847
I0707 14:50:33.546499  1804 hierarchical.hpp:648] Recovered mem(*):2048; disk(*):83928; ports(*):[31000-32000]; cpus(*):2 (total allocatable: mem(*):2048; disk(*):83928; ports(*):[31000-32000]; cpus(*):2) on slave 20150707-142913-16777343-5050-1796-S0 from framework 20150707-142913-16777343-5050-1796-0000
I0707 14:50:39.548164  1804 master.cpp:3760] Sending 1 offers to framework 20150707-142913-16777343-5050-1796-0000 (BioBox-Mesos-Framework_7292) at scheduler-eed21049-4f05-420b-8d01-06b99a18a2da@127.0.1.1:43847
I0707 14:50:39.554458  1801 master.cpp:2273] Processing ACCEPT call for offers: [ 20150707-142913-16777343-5050-1796-O59 ] on slave 20150707-142913-16777343-5050-1796-S0 at slave(1)@127.0.1.1:5051 (AWM14X) for framework 20150707-142913-16777343-5050-1796-0000 (BioBox-Mesos-Framework_7292) at scheduler-eed21049-4f05-420b-8d01-06b99a18a2da@127.0.1.1:43847
I0707 14:50:39.555771  1801 hierarchical.hpp:648] Recovered mem(*):2048; disk(*):83928; ports(*):[31000-32000]; cpus(*):2 (total allocatable: mem(*):2048; disk(*):83928; ports(*):[31000-32000]; cpus(*):2) on slave 20150707-142913-16777343-5050-1796-S0 from framework 20150707-142913-16777343-5050-1796-0000
I0707 14:50:42.685432  1800 http.cpp:516] HTTP request for '/master/state.json'
I0707 14:50:44.557183  1801 master.cpp:3760] Sending 1 offers to framework 20150707-142913-16777343-5050-1796-0000 (BioBox-Mesos-Framework_7292) at scheduler-eed21049-4f05-420b-8d01-06b99a18a2da@127.0.1.1:43847
I0707 14:50:44.563387  1803 master.cpp:2273] Processing ACCEPT call for offers: [ 20150707-142913-16777343-5050-1796-O60 ] on slave 20150707-142913-16777343-5050-1796-S0 at slave(1)@127.0.1.1:5051 (AWM14X) for framework 20150707-142913-16777343-5050-1796-0000 (BioBox-Mesos-Framework_7292) at scheduler-eed21049-4f05-420b-8d01-06b99a18a2da@127.0.1.1:43847
I0707 14:50:44.565143  1804 hierarchical.hpp:648] Recovered mem(*):2048; disk(*):83928; ports(*):[31000-32000]; cpus(*):2 (total allocatable: mem(*):2048; disk(*):83928; ports(*):[31000-32000]; cpus(*):2) on slave 20150707-142913-16777343-5050-1796-S0 from framework 20150707-142913-16777343-5050-1796-0000
I0707 14:50:50.568121  1804 master.cpp:3760] Sending 1 offers to framework 20150707-142913-16777343-5050-1796-0000 (BioBox-Mesos-Framework_7292) at scheduler-eed21049-4f05-420b-8d01-06b99a18a2da@127.0.1.1:43847
I0707 14:50:50.574579  1803 master.cpp:2273] Processing ACCEPT call for offers: [ 20150707-142913-16777343-5050-1796-O61 ] on slave 20150707-142913-16777343-5050-1796-S0 at slave(1)@127.0.1.1:5051 (AWM14X) for framework 20150707-142913-16777343-5050-1796-0000 (BioBox-Mesos-Framework_7292) at scheduler-eed21049-4f05-420b-8d01-06b99a18a2da@127.0.1.1:43847
I0707 14:50:50.575698  1802 hierarchical.hpp:648] Recovered mem(*):2048; disk(*):83928; ports(*):[31000-32000]; cpus(*):2 (total allocatable: mem(*):2048; disk(*):83928; ports(*):[31000-32000]; cpus(*):2) on slave 20150707-142913-16777343-5050-1796-S0 from framework 20150707-142913-16777343-5050-1796-0000
I0707 14:50:52.705334  1805 http.cpp:516] HTTP request for '/master/state.json'
I0707 14:50:56.577128  1801 master.cpp:3760] Sending 1 offers to framework 20150707-142913-16777343-5050-1796-0000 (BioBox-Mesos-Framework_7292) at scheduler-eed21049-4f05-420b-8d01-06b99a18a2da@127.0.1.1:43847
I0707 14:50:56.580662  1798 master.cpp:2273] Processing ACCEPT call for offers: [ 20150707-142913-16777343-5050-1796-O62 ] on slave 20150707-142913-16777343-5050-1796-S0 at slave(1)@127.0.1.1:5051 (AWM14X) for framework 20150707-142913-16777343-5050-1796-0000 (BioBox-Mesos-Framework_7292) at scheduler-eed21049-4f05-420b-8d01-06b99a18a2da@127.0.1.1:43847
I0707 14:50:56.581384  1803 hierarchical.hpp:648] Recovered mem(*):2048; disk(*):83928; ports(*):[31000-32000]; cpus(*):2 (total allocatable: mem(*):2048; disk(*):83928; ports(*):[31000-32000]; cpus(*):2) on slave 20150707-142913-16777343-5050-1796-S0 from framework 20150707-142913-16777343-5050-1796-0000
I0707 14:51:01.585938  1799 master.cpp:3760] Sending 1 offers to framework 20150707-142913-16777343-5050-1796-0000 (BioBox-Mesos-Framework_7292) at scheduler-eed21049-4f05-420b-8d01-06b99a18a2da@127.0.1.1:43847
I0707 14:51:01.592463  1801 master.cpp:2273] Processing ACCEPT call for offers: [ 20150707-142913-16777343-5050-1796-O63 ] on slave 20150707-142913-16777343-5050-1796-S0 at slave(1)@127.0.1.1:5051 (AWM14X) for framework 20150707-142913-16777343-5050-1796-0000 (BioBox-Mesos-Framework_7292) at scheduler-eed21049-4f05-420b-8d01-06b99a18a2da@127.0.1.1:43847
I0707 14:51:01.593886  1801 hierarchical.hpp:648] Recovered mem(*):2048; disk(*):83928; ports(*):[31000-32000]; cpus(*):2 (total allocatable: mem(*):2048; disk(*):83928; ports(*):[31000-32000]; cpus(*):2) on slave 20150707-142913-16777343-5050-1796-S0 from framework 20150707-142913-16777343-5050-1796-0000
I0707 14:51:02.725190  1800 http.cpp:516] HTTP request for '/master/state.json'
I0707 14:51:07.596856  1805 master.cpp:3760] Sending 1 offers to framework 20150707-142913-16777343-5050-1796-0000 (BioBox-Mesos-Framework_7292) at scheduler-eed21049-4f05-420b-8d01-06b99a18a2da@127.0.1.1:43847
I0707 14:51:07.603405  1802 master.cpp:2273] Processing ACCEPT call for offers: [ 20150707-142913-16777343-5050-1796-O64 ] on slave 20150707-142913-16777343-5050-1796-S0 at slave(1)@127.0.1.1:5051 (AWM14X) for framework 20150707-142913-16777343-5050-1796-0000 (BioBox-Mesos-Framework_7292) at scheduler-eed21049-4f05-420b-8d01-06b99a18a2da@127.0.1.1:43847
I0707 14:51:07.604744  1802 hierarchical.hpp:648] Recovered mem(*):2048; disk(*):83928; ports(*):[31000-32000]; cpus(*):2 (total allocatable: mem(*):2048; disk(*):83928; ports(*):[31000-32000]; cpus(*):2) on slave 20150707-142913-16777343-5050-1796-S0 from framework 20150707-142913-16777343-5050-1796-0000
I0707 14:51:12.745203  1803 http.cpp:516] HTTP request for '/master/state.json'
I0707 14:51:13.606201  1798 master.cpp:3760] Sending 1 offers to framework 20150707-142913-16777343-5050-1796-0000 (BioBox-Mesos-Framework_7292) at scheduler-eed21049-4f05-420b-8d01-06b99a18a2da@127.0.1.1:43847
I0707 14:51:13.612601  1802 master.cpp:2273] Processing ACCEPT call for offers: [ 20150707-142913-16777343-5050-1796-O65 ] on slave 20150707-142913-16777343-5050-1796-S0 at slave(1)@127.0.1.1:5051 (AWM14X) for framework 20150707-142913-16777343-5050-1796-0000 (BioBox-Mesos-Framework_7292) at scheduler-eed21049-4f05-420b-8d01-06b99a18a2da@127.0.1.1:43847
I0707 14:51:13.613814  1802 hierarchical.hpp:648] Recovered mem(*):2048; disk(*):83928; ports(*):[31000-32000]; cpus(*):2 (total allocatable: mem(*):2048; disk(*):83928; ports(*):[31000-32000]; cpus(*):2) on slave 20150707-142913-16777343-5050-1796-S0 from framework 20150707-142913-16777343-5050-1796-0000
I0707 14:51:19.614675  1802 master.cpp:3760] Sending 1 offers to framework 20150707-142913-16777343-5050-1796-0000 (BioBox-Mesos-Framework_7292) at scheduler-eed21049-4f05-420b-8d01-06b99a18a2da@127.0.1.1:43847
I0707 14:51:19.618685  1800 master.cpp:2273] Processing ACCEPT call for offers: [ 20150707-142913-16777343-5050-1796-O66 ] on slave 20150707-142913-16777343-5050-1796-S0 at slave(1)@127.0.1.1:5051 (AWM14X) for framework 20150707-142913-16777343-5050-1796-0000 (BioBox-Mesos-Framework_7292) at scheduler-eed21049-4f05-420b-8d01-06b99a18a2da@127.0.1.1:43847
I0707 14:51:19.619815  1803 hierarchical.hpp:648] Recovered mem(*):2048; disk(*):83928; ports(*):[31000-32000]; cpus(*):2 (total allocatable: mem(*):2048; disk(*):83928; ports(*):[31000-32000]; cpus(*):2) on slave 20150707-142913-16777343-5050-1796-S0 from framework 20150707-142913-16777343-5050-1796-0000
I0707 14:51:22.767462  1804 http.cpp:516] HTTP request for '/master/state.json'
I0707 14:51:24.622931  1805 master.cpp:3760] Sending 1 offers to framework 20150707-142913-16777343-5050-1796-0000 (BioBox-Mesos-Framework_7292) at scheduler-eed21049-4f05-420b-8d01-06b99a18a2da@127.0.1.1:43847
I0707 14:51:24.629133  1802 master.cpp:2273] Processing ACCEPT call for offers: [ 20150707-142913-16777343-5050-1796-O67 ] on slave 20150707-142913-16777343-5050-1796-S0 at slave(1)@127.0.1.1:5051 (AWM14X) for framework 20150707-142913-16777343-5050-1796-0000 (BioBox-Mesos-Framework_7292) at scheduler-eed21049-4f05-420b-8d01-06b99a18a2da@127.0.1.1:43847
I0707 14:51:24.630712  1800 hierarchical.hpp:648] Recovered mem(*):2048; disk(*):83928; ports(*):[31000-32000]; cpus(*):2 (total allocatable: mem(*):2048; disk(*):83928; ports(*):[31000-32000]; cpus(*):2) on slave 20150707-142913-16777343-5050-1796-S0 from framework 20150707-142913-16777343-5050-1796-0000
I0707 14:51:29.632637  1804 master.cpp:3760] Sending 1 offers to framework 20150707-142913-16777343-5050-1796-0000 (BioBox-Mesos-Framework_7292) at scheduler-eed21049-4f05-420b-8d01-06b99a18a2da@127.0.1.1:43847
I0707 14:51:29.639334  1805 master.cpp:2273] Processing ACCEPT call for offers: [ 20150707-142913-16777343-5050-1796-O68 ] on slave 20150707-142913-16777343-5050-1796-S0 at slave(1)@127.0.1.1:5051 (AWM14X) for framework 20150707-142913-16777343-5050-1796-0000 (BioBox-Mesos-Framework_7292) at scheduler-eed21049-4f05-420b-8d01-06b99a18a2da@127.0.1.1:43847
I0707 14:51:29.640799  1800 hierarchical.hpp:648] Recovered mem(*):2048; disk(*):83928; ports(*):[31000-32000]; cpus(*):2 (total allocatable: mem(*):2048; disk(*):83928; ports(*):[31000-32000]; cpus(*):2) on slave 20150707-142913-16777343-5050-1796-S0 from framework 20150707-142913-16777343-5050-1796-0000
I0707 14:51:32.787145  1803 http.cpp:516] HTTP request for '/master/state.json'
I0707 14:51:35.643539  1800 master.cpp:3760] Sending 1 offers to framework 20150707-142913-16777343-5050-1796-0000 (BioBox-Mesos-Framework_7292) at scheduler-eed21049-4f05-420b-8d01-06b99a18a2da@127.0.1.1:43847
I0707 14:51:35.649993  1805 master.cpp:2273] Processing ACCEPT call for offers: [ 20150707-142913-16777343-5050-1796-O69 ] on slave 20150707-142913-16777343-5050-1796-S0 at slave(1)@127.0.1.1:5051 (AWM14X) for framework 20150707-142913-16777343-5050-1796-0000 (BioBox-Mesos-Framework_7292) at scheduler-eed21049-4f05-420b-8d01-06b99a18a2da@127.0.1.1:43847
I0707 14:51:35.651741  1805 hierarchical.hpp:648] Recovered mem(*):2048; disk(*):83928; ports(*):[31000-32000]; cpus(*):2 (total allocatable: mem(*):2048; disk(*):83928; ports(*):[31000-32000]; cpus(*):2) on slave 20150707-142913-16777343-5050-1796-S0 from framework 20150707-142913-16777343-5050-1796-0000
I0707 14:51:41.653798  1800 master.cpp:3760] Sending 1 offers to framework 20150707-142913-16777343-5050-1796-0000 (BioBox-Mesos-Framework_7292) at scheduler-eed21049-4f05-420b-8d01-06b99a18a2da@127.0.1.1:43847
I0707 14:51:41.660652  1805 master.cpp:2273] Processing ACCEPT call for offers: [ 20150707-142913-16777343-5050-1796-O70 ] on slave 20150707-142913-16777343-5050-1796-S0 at slave(1)@127.0.1.1:5051 (AWM14X) for framework 20150707-142913-16777343-5050-1796-0000 (BioBox-Mesos-Framework_7292) at scheduler-eed21049-4f05-420b-8d01-06b99a18a2da@127.0.1.1:43847
I0707 14:51:41.662009  1805 hierarchical.hpp:648] Recovered mem(*):2048; disk(*):83928; ports(*):[31000-32000]; cpus(*):2 (total allocatable: mem(*):2048; disk(*):83928; ports(*):[31000-32000]; cpus(*):2) on slave 20150707-142913-16777343-5050-1796-S0 from framework 20150707-142913-16777343-5050-1796-0000
I0707 14:51:42.807833  1801 http.cpp:516] HTTP request for '/master/state.json'
I0707 14:51:47.664422  1804 master.cpp:3760] Sending 1 offers to framework 20150707-142913-16777343-5050-1796-0000 (BioBox-Mesos-Framework_7292) at scheduler-eed21049-4f05-420b-8d01-06b99a18a2da@127.0.1.1:43847
I0707 14:51:47.671442  1798 master.cpp:2273] Processing ACCEPT call for offers: [ 20150707-142913-16777343-5050-1796-O71 ] on slave 20150707-142913-16777343-5050-1796-S0 at slave(1)@127.0.1.1:5051 (AWM14X) for framework 20150707-142913-16777343-5050-1796-0000 (BioBox-Mesos-Framework_7292) at scheduler-eed21049-4f05-420b-8d01-06b99a18a2da@127.0.1.1:43847
I0707 14:51:47.673208  1802 hierarchical.hpp:648] Recovered mem(*):2048; disk(*):83928; ports(*):[31000-32000]; cpus(*):2 (total allocatable: mem(*):2048; disk(*):83928; ports(*):[31000-32000]; cpus(*):2) on slave 20150707-142913-16777343-5050-1796-S0 from framework 20150707-142913-16777343-5050-1796-0000
I0707 14:51:52.823143  1802 http.cpp:516] HTTP request for '/master/state.json'
I0707 14:51:53.674218  1801 master.cpp:3760] Sending 1 offers to framework 20150707-142913-16777343-5050-1796-0000 (BioBox-Mesos-Framework_7292) at scheduler-eed21049-4f05-420b-8d01-06b99a18a2da@127.0.1.1:43847
I0707 14:51:53.680871  1803 master.cpp:2273] Processing ACCEPT call for offers: [ 20150707-142913-16777343-5050-1796-O72 ] on slave 20150707-142913-16777343-5050-1796-S0 at slave(1)@127.0.1.1:5051 (AWM14X) for framework 20150707-142913-16777343-5050-1796-0000 (BioBox-Mesos-Framework_7292) at scheduler-eed21049-4f05-420b-8d01-06b99a18a2da@127.0.1.1:43847
I0707 14:51:53.682862  1802 hierarchical.hpp:648] Recovered mem(*):2048; disk(*):83928; ports(*):[31000-32000]; cpus(*):2 (total allocatable: mem(*):2048; disk(*):83928; ports(*):[31000-32000]; cpus(*):2) on slave 20150707-142913-16777343-5050-1796-S0 from framework 20150707-142913-16777343-5050-1796-0000
I0707 14:51:59.685087  1802 master.cpp:3760] Sending 1 offers to framework 20150707-142913-16777343-5050-1796-0000 (BioBox-Mesos-Framework_7292) at scheduler-eed21049-4f05-420b-8d01-06b99a18a2da@127.0.1.1:43847
I0707 14:51:59.690469  1799 master.cpp:2273] Processing ACCEPT call for offers: [ 20150707-142913-16777343-5050-1796-O73 ] on slave 20150707-142913-16777343-5050-1796-S0 at slave(1)@127.0.1.1:5051 (AWM14X) for framework 20150707-142913-16777343-5050-1796-0000 (BioBox-Mesos-Framework_7292) at scheduler-eed21049-4f05-420b-8d01-06b99a18a2da@127.0.1.1:43847
I0707 14:51:59.691376  1799 hierarchical.hpp:648] Recovered mem(*):2048; disk(*):83928; ports(*):[31000-32000]; cpus(*):2 (total allocatable: mem(*):2048; disk(*):83928; ports(*):[31000-32000]; cpus(*):2) on slave 20150707-142913-16777343-5050-1796-S0 from framework 20150707-142913-16777343-5050-1796-0000
I0707 14:52:02.837141  1800 http.cpp:516] HTTP request for '/master/state.json'
I0707 14:52:04.693362  1801 master.cpp:3760] Sending 1 offers to framework 20150707-142913-16777343-5050-1796-0000 (BioBox-Mesos-Framework_7292) at scheduler-eed21049-4f05-420b-8d01-06b99a18a2da@127.0.1.1:43847
I0707 14:52:04.700141  1805 master.cpp:2273] Processing ACCEPT call for offers: [ 20150707-142913-16777343-5050-1796-O74 ] on slave 20150707-142913-16777343-5050-1796-S0 at slave(1)@127.0.1.1:5051 (AWM14X) for framework 20150707-142913-16777343-5050-1796-0000 (BioBox-Mesos-Framework_7292) at scheduler-eed21049-4f05-420b-8d01-06b99a18a2da@127.0.1.1:43847
I0707 14:52:04.701510  1805 hierarchical.hpp:648] Recovered mem(*):2048; disk(*):83928; ports(*):[31000-32000]; cpus(*):2 (total allocatable: mem(*):2048; disk(*):83928; ports(*):[31000-32000]; cpus(*):2) on slave 20150707-142913-16777343-5050-1796-S0 from framework 20150707-142913-16777343-5050-1796-0000
I0707 14:52:10.703935  1801 master.cpp:3760] Sending 1 offers to framework 20150707-142913-16777343-5050-1796-0000 (BioBox-Mesos-Framework_7292) at scheduler-eed21049-4f05-420b-8d01-06b99a18a2da@127.0.1.1:43847
I0707 14:52:10.710386  1805 master.cpp:2273] Processing ACCEPT call for offers: [ 20150707-142913-16777343-5050-1796-O75 ] on slave 20150707-142913-16777343-5050-1796-S0 at slave(1)@127.0.1.1:5051 (AWM14X) for framework 20150707-142913-16777343-5050-1796-0000 (BioBox-Mesos-Framework_7292) at scheduler-eed21049-4f05-420b-8d01-06b99a18a2da@127.0.1.1:43847
I0707 14:52:10.711694  1805 hierarchical.hpp:648] Recovered mem(*):2048; disk(*):83928; ports(*):[31000-32000]; cpus(*):2 (total allocatable: mem(*):2048; disk(*):83928; ports(*):[31000-32000]; cpus(*):2) on slave 20150707-142913-16777343-5050-1796-S0 from framework 20150707-142913-16777343-5050-1796-0000
I0707 14:52:12.856690  1798 http.cpp:516] HTTP request for '/master/state.json'
I0707 14:52:16.714567  1800 master.cpp:3760] Sending 1 offers to framework 20150707-142913-16777343-5050-1796-0000 (BioBox-Mesos-Framework_7292) at scheduler-eed21049-4f05-420b-8d01-06b99a18a2da@127.0.1.1:43847
I0707 14:52:16.720823  1799 master.cpp:2273] Processing ACCEPT call for offers: [ 20150707-142913-16777343-5050-1796-O76 ] on slave 20150707-142913-16777343-5050-1796-S0 at slave(1)@127.0.1.1:5051 (AWM14X) for framework 20150707-142913-16777343-5050-1796-0000 (BioBox-Mesos-Framework_7292) at scheduler-eed21049-4f05-420b-8d01-06b99a18a2da@127.0.1.1:43847
I0707 14:52:16.722059  1799 hierarchical.hpp:648] Recovered mem(*):2048; disk(*):83928; ports(*):[31000-32000]; cpus(*):2 (total allocatable: mem(*):2048; disk(*):83928; ports(*):[31000-32000]; cpus(*):2) on slave 20150707-142913-16777343-5050-1796-S0 from framework 20150707-142913-16777343-5050-1796-0000
I0707 14:52:21.724439  1799 master.cpp:3760] Sending 1 offers to framework 20150707-142913-16777343-5050-1796-0000 (BioBox-Mesos-Framework_7292) at scheduler-eed21049-4f05-420b-8d01-06b99a18a2da@127.0.1.1:43847
I0707 14:52:21.730671  1800 master.cpp:2273] Processing ACCEPT call for offers: [ 20150707-142913-16777343-5050-1796-O77 ] on slave 20150707-142913-16777343-5050-1796-S0 at slave(1)@127.0.1.1:5051 (AWM14X) for framework 20150707-142913-16777343-5050-1796-0000 (BioBox-Mesos-Framework_7292) at scheduler-eed21049-4f05-420b-8d01-06b99a18a2da@127.0.1.1:43847
I0707 14:52:21.732151  1800 hierarchical.hpp:648] Recovered mem(*):2048; disk(*):83928; ports(*):[31000-32000]; cpus(*):2 (total allocatable: mem(*):2048; disk(*):83928; ports(*):[31000-32000]; cpus(*):2) on slave 20150707-142913-16777343-5050-1796-S0 from framework 20150707-142913-16777343-5050-1796-0000
I0707 14:52:22.876478  1801 http.cpp:516] HTTP request for '/master/state.json'
I0707 14:52:27.733619  1802 master.cpp:3760] Sending 1 offers to framework 20150707-142913-16777343-5050-1796-0000 (BioBox-Mesos-Framework_7292) at scheduler-eed21049-4f05-420b-8d01-06b99a18a2da@127.0.1.1:43847
I0707 14:52:27.738991  1804 master.cpp:2273] Processing ACCEPT call for offers: [ 20150707-142913-16777343-5050-1796-O78 ] on slave 20150707-142913-16777343-5050-1796-S0 at slave(1)@127.0.1.1:5051 (AWM14X) for framework 20150707-142913-16777343-5050-1796-0000 (BioBox-Mesos-Framework_7292) at scheduler-eed21049-4f05-420b-8d01-06b99a18a2da@127.0.1.1:43847
I0707 14:52:27.740022  1800 hierarchical.hpp:648] Recovered mem(*):2048; disk(*):83928; ports(*):[31000-32000]; cpus(*):2 (total allocatable: mem(*):2048; disk(*):83928; ports(*):[31000-32000]; cpus(*):2) on slave 20150707-142913-16777343-5050-1796-S0 from framework 20150707-142913-16777343-5050-1796-0000
I0707 14:52:32.742342  1798 master.cpp:3760] Sending 1 offers to framework 20150707-142913-16777343-5050-1796-0000 (BioBox-Mesos-Framework_7292) at scheduler-eed21049-4f05-420b-8d01-06b99a18a2da@127.0.1.1:43847
I0707 14:52:32.748664  1805 master.cpp:2273] Processing ACCEPT call for offers: [ 20150707-142913-16777343-5050-1796-O79 ] on slave 20150707-142913-16777343-5050-1796-S0 at slave(1)@127.0.1.1:5051 (AWM14X) for framework 20150707-142913-16777343-5050-1796-0000 (BioBox-Mesos-Framework_7292) at scheduler-eed21049-4f05-420b-8d01-06b99a18a2da@127.0.1.1:43847
I0707 14:52:32.750000  1805 hierarchical.hpp:648] Recovered mem(*):2048; disk(*):83928; ports(*):[31000-32000]; cpus(*):2 (total allocatable: mem(*):2048; disk(*):83928; ports(*):[31000-32000]; cpus(*):2) on slave 20150707-142913-16777343-5050-1796-S0 from framework 20150707-142913-16777343-5050-1796-0000
I0707 14:52:32.895493  1802 http.cpp:516] HTTP request for '/master/state.json'
I0707 14:52:38.753155  1801 master.cpp:3760] Sending 1 offers to framework 20150707-142913-16777343-5050-1796-0000 (BioBox-Mesos-Framework_7292) at scheduler-eed21049-4f05-420b-8d01-06b99a18a2da@127.0.1.1:43847
I0707 14:52:38.759486  1803 master.cpp:2273] Processing ACCEPT call for offers: [ 20150707-142913-16777343-5050-1796-O80 ] on slave 20150707-142913-16777343-5050-1796-S0 at slave(1)@127.0.1.1:5051 (AWM14X) for framework 20150707-142913-16777343-5050-1796-0000 (BioBox-Mesos-Framework_7292) at scheduler-eed21049-4f05-420b-8d01-06b99a18a2da@127.0.1.1:43847
I0707 14:52:38.761126  1798 hierarchical.hpp:648] Recovered mem(*):2048; disk(*):83928; ports(*):[31000-32000]; cpus(*):2 (total allocatable: mem(*):2048; disk(*):83928; ports(*):[31000-32000]; cpus(*):2) on slave 20150707-142913-16777343-5050-1796-S0 from framework 20150707-142913-16777343-5050-1796-0000
I0707 14:52:42.915529  1800 http.cpp:516] HTTP request for '/master/state.json'
I0707 14:52:44.762200  1800 master.cpp:3760] Sending 1 offers to framework 20150707-142913-16777343-5050-1796-0000 (BioBox-Mesos-Framework_7292) at scheduler-eed21049-4f05-420b-8d01-06b99a18a2da@127.0.1.1:43847
I0707 14:52:44.768591  1803 master.cpp:2273] Processing ACCEPT call for offers: [ 20150707-142913-16777343-5050-1796-O81 ] on slave 20150707-142913-16777343-5050-1796-S0 at slave(1)@127.0.1.1:5051 (AWM14X) for framework 20150707-142913-16777343-5050-1796-0000 (BioBox-Mesos-Framework_7292) at scheduler-eed21049-4f05-420b-8d01-06b99a18a2da@127.0.1.1:43847
I0707 14:52:44.769773  1803 hierarchical.hpp:648] Recovered mem(*):2048; disk(*):83928; ports(*):[31000-32000]; cpus(*):2 (total allocatable: mem(*):2048; disk(*):83928; ports(*):[31000-32000]; cpus(*):2) on slave 20150707-142913-16777343-5050-1796-S0 from framework 20150707-142913-16777343-5050-1796-0000
I0707 14:52:50.772745  1803 master.cpp:3760] Sending 1 offers to framework 20150707-142913-16777343-5050-1796-0000 (BioBox-Mesos-Framework_7292) at scheduler-eed21049-4f05-420b-8d01-06b99a18a2da@127.0.1.1:43847
I0707 14:52:50.779183  1802 master.cpp:2273] Processing ACCEPT call for offers: [ 20150707-142913-16777343-5050-1796-O82 ] on slave 20150707-142913-16777343-5050-1796-S0 at slave(1)@127.0.1.1:5051 (AWM14X) for framework 20150707-142913-16777343-5050-1796-0000 (BioBox-Mesos-Framework_7292) at scheduler-eed21049-4f05-420b-8d01-06b99a18a2da@127.0.1.1:43847
I0707 14:52:50.780473  1802 hierarchical.hpp:648] Recovered mem(*):2048; disk(*):83928; ports(*):[31000-32000]; cpus(*):2 (total allocatable: mem(*):2048; disk(*):83928; ports(*):[31000-32000]; cpus(*):2) on slave 20150707-142913-16777343-5050-1796-S0 from framework 20150707-142913-16777343-5050-1796-0000
I0707 14:52:52.930222  1805 http.cpp:516] HTTP request for '/master/state.json'
I0707 14:52:56.782995  1803 master.cpp:3760] Sending 1 offers to framework 20150707-142913-16777343-5050-1796-0000 (BioBox-Mesos-Framework_7292) at scheduler-eed21049-4f05-420b-8d01-06b99a18a2da@127.0.1.1:43847
I0707 14:52:56.789798  1801 master.cpp:2273] Processing ACCEPT call for offers: [ 20150707-142913-16777343-5050-1796-O83 ] on slave 20150707-142913-16777343-5050-1796-S0 at slave(1)@127.0.1.1:5051 (AWM14X) for framework 20150707-142913-16777343-5050-1796-0000 (BioBox-Mesos-Framework_7292) at scheduler-eed21049-4f05-420b-8d01-06b99a18a2da@127.0.1.1:43847
I0707 14:52:56.791409  1798 hierarchical.hpp:648] Recovered mem(*):2048; disk(*):83928; ports(*):[31000-32000]; cpus(*):2 (total allocatable: mem(*):2048; disk(*):83928; ports(*):[31000-32000]; cpus(*):2) on slave 20150707-142913-16777343-5050-1796-S0 from framework 20150707-142913-16777343-5050-1796-0000
I0707 14:53:02.793227  1803 master.cpp:3760] Sending 1 offers to framework 20150707-142913-16777343-5050-1796-0000 (BioBox-Mesos-Framework_7292) at scheduler-eed21049-4f05-420b-8d01-06b99a18a2da@127.0.1.1:43847
I0707 14:53:02.800608  1798 master.cpp:2273] Processing ACCEPT call for offers: [ 20150707-142913-16777343-5050-1796-O84 ] on slave 20150707-142913-16777343-5050-1796-S0 at slave(1)@127.0.1.1:5051 (AWM14X) for framework 20150707-142913-16777343-5050-1796-0000 (BioBox-Mesos-Framework_7292) at scheduler-eed21049-4f05-420b-8d01-06b99a18a2da@127.0.1.1:43847
I0707 14:53:02.802816  1800 hierarchical.hpp:648] Recovered mem(*):2048; disk(*):83928; ports(*):[31000-32000]; cpus(*):2 (total allocatable: mem(*):2048; disk(*):83928; ports(*):[31000-32000]; cpus(*):2) on slave 20150707-142913-16777343-5050-1796-S0 from framework 20150707-142913-16777343-5050-1796-0000
I0707 14:53:02.945992  1798 http.cpp:516] HTTP request for '/master/state.json'
I0707 14:53:08.803215  1798 master.cpp:3760] Sending 1 offers to framework 20150707-142913-16777343-5050-1796-0000 (BioBox-Mesos-Framework_7292) at scheduler-eed21049-4f05-420b-8d01-06b99a18a2da@127.0.1.1:43847
I0707 14:53:08.809835  1801 master.cpp:2273] Processing ACCEPT call for offers: [ 20150707-142913-16777343-5050-1796-O85 ] on slave 20150707-142913-16777343-5050-1796-S0 at slave(1)@127.0.1.1:5051 (AWM14X) for framework 20150707-142913-16777343-5050-1796-0000 (BioBox-Mesos-Framework_7292) at scheduler-eed21049-4f05-420b-8d01-06b99a18a2da@127.0.1.1:43847
I0707 14:53:08.811084  1801 hierarchical.hpp:648] Recovered mem(*):2048; disk(*):83928; ports(*):[31000-32000]; cpus(*):2 (total allocatable: mem(*):2048; disk(*):83928; ports(*):[31000-32000]; cpus(*):2) on slave 20150707-142913-16777343-5050-1796-S0 from framework 20150707-142913-16777343-5050-1796-0000
I0707 14:53:12.967761  1804 http.cpp:516] HTTP request for '/master/state.json'
I0707 14:53:14.813959  1801 master.cpp:3760] Sending 1 offers to framework 20150707-142913-16777343-5050-1796-0000 (BioBox-Mesos-Framework_7292) at scheduler-eed21049-4f05-420b-8d01-06b99a18a2da@127.0.1.1:43847
I0707 14:53:14.820440  1805 master.cpp:2273] Processing ACCEPT call for offers: [ 20150707-142913-16777343-5050-1796-O86 ] on slave 20150707-142913-16777343-5050-1796-S0 at slave(1)@127.0.1.1:5051 (AWM14X) for framework 20150707-142913-16777343-5050-1796-0000 (BioBox-Mesos-Framework_7292) at scheduler-eed21049-4f05-420b-8d01-06b99a18a2da@127.0.1.1:43847
I0707 14:53:14.821985  1799 hierarchical.hpp:648] Recovered mem(*):2048; disk(*):83928; ports(*):[31000-32000]; cpus(*):2 (total allocatable: mem(*):2048; disk(*):83928; ports(*):[31000-32000]; cpus(*):2) on slave 20150707-142913-16777343-5050-1796-S0 from framework 20150707-142913-16777343-5050-1796-0000
I0707 14:53:19.823544  1801 master.cpp:3760] Sending 1 offers to framework 20150707-142913-16777343-5050-1796-0000 (BioBox-Mesos-Framework_7292) at scheduler-eed21049-4f05-420b-8d01-06b99a18a2da@127.0.1.1:43847
I0707 14:53:19.829907  1799 master.cpp:2273] Processing ACCEPT call for offers: [ 20150707-142913-16777343-5050-1796-O87 ] on slave 20150707-142913-16777343-5050-1796-S0 at slave(1)@127.0.1.1:5051 (AWM14X) for framework 20150707-142913-16777343-5050-1796-0000 (BioBox-Mesos-Framework_7292) at scheduler-eed21049-4f05-420b-8d01-06b99a18a2da@127.0.1.1:43847
I0707 14:53:19.831267  1799 hierarchical.hpp:648] Recovered mem(*):2048; disk(*):83928; ports(*):[31000-32000]; cpus(*):2 (total allocatable: mem(*):2048; disk(*):83928; ports(*):[31000-32000]; cpus(*):2) on slave 20150707-142913-16777343-5050-1796-S0 from framework 20150707-142913-16777343-5050-1796-0000
I0707 14:53:22.987385  1802 http.cpp:516] HTTP request for '/master/state.json'
I0707 14:53:24.833225  1805 master.cpp:3760] Sending 1 offers to framework 20150707-142913-16777343-5050-1796-0000 (BioBox-Mesos-Framework_7292) at scheduler-eed21049-4f05-420b-8d01-06b99a18a2da@127.0.1.1:43847
I0707 14:53:24.839865  1803 master.cpp:2273] Processing ACCEPT call for offers: [ 20150707-142913-16777343-5050-1796-O88 ] on slave 20150707-142913-16777343-5050-1796-S0 at slave(1)@127.0.1.1:5051 (AWM14X) for framework 20150707-142913-16777343-5050-1796-0000 (BioBox-Mesos-Framework_7292) at scheduler-eed21049-4f05-420b-8d01-06b99a18a2da@127.0.1.1:43847
I0707 14:53:24.841336  1803 hierarchical.hpp:648] Recovered mem(*):2048; disk(*):83928; ports(*):[31000-32000]; cpus(*):2 (total allocatable: mem(*):2048; disk(*):83928; ports(*):[31000-32000]; cpus(*):2) on slave 20150707-142913-16777343-5050-1796-S0 from framework 20150707-142913-16777343-5050-1796-0000
I0707 14:53:30.842762  1803 master.cpp:3760] Sending 1 offers to framework 20150707-142913-16777343-5050-1796-0000 (BioBox-Mesos-Framework_7292) at scheduler-eed21049-4f05-420b-8d01-06b99a18a2da@127.0.1.1:43847
I0707 14:53:30.849712  1798 master.cpp:2273] Processing ACCEPT call for offers: [ 20150707-142913-16777343-5050-1796-O89 ] on slave 20150707-142913-16777343-5050-1796-S0 at slave(1)@127.0.1.1:5051 (AWM14X) for framework 20150707-142913-16777343-5050-1796-0000 (BioBox-Mesos-Framework_7292) at scheduler-eed21049-4f05-420b-8d01-06b99a18a2da@127.0.1.1:43847
I0707 14:53:30.851783  1800 hierarchical.hpp:648] Recovered mem(*):2048; disk(*):83928; ports(*):[31000-32000]; cpus(*):2 (total allocatable: mem(*):2048; disk(*):83928; ports(*):[31000-32000]; cpus(*):2) on slave 20150707-142913-16777343-5050-1796-S0 from framework 20150707-142913-16777343-5050-1796-0000
I0707 14:53:33.007385  1805 http.cpp:516] HTTP request for '/master/state.json'
I0707 14:53:36.852959  1798 master.cpp:3760] Sending 1 offers to framework 20150707-142913-16777343-5050-1796-0000 (BioBox-Mesos-Framework_7292) at scheduler-eed21049-4f05-420b-8d01-06b99a18a2da@127.0.1.1:43847
I0707 14:53:36.859577  1803 master.cpp:2273] Processing ACCEPT call for offers: [ 20150707-142913-16777343-5050-1796-O90 ] on slave 20150707-142913-16777343-5050-1796-S0 at slave(1)@127.0.1.1:5051 (AWM14X) for framework 20150707-142913-16777343-5050-1796-0000 (BioBox-Mesos-Framework_7292) at scheduler-eed21049-4f05-420b-8d01-06b99a18a2da@127.0.1.1:43847
I0707 14:53:36.860813  1803 hierarchical.hpp:648] Recovered mem(*):2048; disk(*):83928; ports(*):[31000-32000]; cpus(*):2 (total allocatable: mem(*):2048; disk(*):83928; ports(*):[31000-32000]; cpus(*):2) on slave 20150707-142913-16777343-5050-1796-S0 from framework 20150707-142913-16777343-5050-1796-0000
I0707 14:53:42.863267  1798 master.cpp:3760] Sending 1 offers to framework 20150707-142913-16777343-5050-1796-0000 (BioBox-Mesos-Framework_7292) at scheduler-eed21049-4f05-420b-8d01-06b99a18a2da@127.0.1.1:43847
I0707 14:53:42.869606  1803 master.cpp:2273] Processing ACCEPT call for offers: [ 20150707-142913-16777343-5050-1796-O91 ] on slave 20150707-142913-16777343-5050-1796-S0 at slave(1)@127.0.1.1:5051 (AWM14X) for framework 20150707-142913-16777343-5050-1796-0000 (BioBox-Mesos-Framework_7292) at scheduler-eed21049-4f05-420b-8d01-06b99a18a2da@127.0.1.1:43847
I0707 14:53:42.870909  1803 hierarchical.hpp:648] Recovered mem(*):2048; disk(*):83928; ports(*):[31000-32000]; cpus(*):2 (total allocatable: mem(*):2048; disk(*):83928; ports(*):[31000-32000]; cpus(*):2) on slave 20150707-142913-16777343-5050-1796-S0 from framework 20150707-142913-16777343-5050-1796-0000
I0707 14:53:43.027465  1799 http.cpp:516] HTTP request for '/master/state.json'
I0707 14:53:48.873322  1800 master.cpp:3760] Sending 1 offers to framework 20150707-142913-16777343-5050-1796-0000 (BioBox-Mesos-Framework_7292) at scheduler-eed21049-4f05-420b-8d01-06b99a18a2da@127.0.1.1:43847
I0707 14:53:48.879766  1799 master.cpp:2273] Processing ACCEPT call for offers: [ 20150707-142913-16777343-5050-1796-O92 ] on slave 20150707-142913-16777343-5050-1796-S0 at slave(1)@127.0.1.1:5051 (AWM14X) for framework 20150707-142913-16777343-5050-1796-0000 (BioBox-Mesos-Framework_7292) at scheduler-eed21049-4f05-420b-8d01-06b99a18a2da@127.0.1.1:43847
I0707 14:53:48.881141  1799 hierarchical.hpp:648] Recovered mem(*):2048; disk(*):83928; ports(*):[31000-32000]; cpus(*):2 (total allocatable: mem(*):2048; disk(*):83928; ports(*):[31000-32000]; cpus(*):2) on slave 20150707-142913-16777343-5050-1796-S0 from framework 20150707-142913-16777343-5050-1796-0000
I0707 14:53:53.046644  1804 http.cpp:516] HTTP request for '/master/state.json'
I0707 14:53:54.883224  1802 master.cpp:3760] Sending 1 offers to framework 20150707-142913-16777343-5050-1796-0000 (BioBox-Mesos-Framework_7292) at scheduler-eed21049-4f05-420b-8d01-06b99a18a2da@127.0.1.1:43847
I0707 14:53:54.890076  1803 master.cpp:2273] Processing ACCEPT call for offers: [ 20150707-142913-16777343-5050-1796-O93 ] on slave 20150707-142913-16777343-5050-1796-S0 at slave(1)@127.0.1.1:5051 (AWM14X) for framework 20150707-142913-16777343-5050-1796-0000 (BioBox-Mesos-Framework_7292) at scheduler-eed21049-4f05-420b-8d01-06b99a18a2da@127.0.1.1:43847
I0707 14:53:54.891437  1800 hierarchical.hpp:648] Recovered mem(*):2048; disk(*):83928; ports(*):[31000-32000]; cpus(*):2 (total allocatable: mem(*):2048; disk(*):83928; ports(*):[31000-32000]; cpus(*):2) on slave 20150707-142913-16777343-5050-1796-S0 from framework 20150707-142913-16777343-5050-1796-0000
I0707 14:54:00.893014  1805 master.cpp:3760] Sending 1 offers to framework 20150707-142913-16777343-5050-1796-0000 (BioBox-Mesos-Framework_7292) at scheduler-eed21049-4f05-420b-8d01-06b99a18a2da@127.0.1.1:43847
I0707 14:54:00.899237  1800 master.cpp:2273] Processing ACCEPT call for offers: [ 20150707-142913-16777343-5050-1796-O94 ] on slave 20150707-142913-16777343-5050-1796-S0 at slave(1)@127.0.1.1:5051 (AWM14X) for framework 20150707-142913-16777343-5050-1796-0000 (BioBox-Mesos-Framework_7292) at scheduler-eed21049-4f05-420b-8d01-06b99a18a2da@127.0.1.1:43847
I0707 14:54:00.900590  1800 hierarchical.hpp:648] Recovered mem(*):2048; disk(*):83928; ports(*):[31000-32000]; cpus(*):2 (total allocatable: mem(*):2048; disk(*):83928; ports(*):[31000-32000]; cpus(*):2) on slave 20150707-142913-16777343-5050-1796-S0 from framework 20150707-142913-16777343-5050-1796-0000
I0707 14:54:03.066629  1802 http.cpp:516] HTTP request for '/master/state.json'
I0707 14:54:06.903606  1801 master.cpp:3760] Sending 1 offers to framework 20150707-142913-16777343-5050-1796-0000 (BioBox-Mesos-Framework_7292) at scheduler-eed21049-4f05-420b-8d01-06b99a18a2da@127.0.1.1:43847
I0707 14:54:06.910712  1804 master.cpp:2273] Processing ACCEPT call for offers: [ 20150707-142913-16777343-5050-1796-O95 ] on slave 20150707-142913-16777343-5050-1796-S0 at slave(1)@127.0.1.1:5051 (AWM14X) for framework 20150707-142913-16777343-5050-1796-0000 (BioBox-Mesos-Framework_7292) at scheduler-eed21049-4f05-420b-8d01-06b99a18a2da@127.0.1.1:43847
I0707 14:54:06.912133  1804 hierarchical.hpp:648] Recovered mem(*):2048; disk(*):83928; ports(*):[31000-32000]; cpus(*):2 (total allocatable: mem(*):2048; disk(*):83928; ports(*):[31000-32000]; cpus(*):2) on slave 20150707-142913-16777343-5050-1796-S0 from framework 20150707-142913-16777343-5050-1796-0000
I0707 14:54:12.913947  1803 master.cpp:3760] Sending 1 offers to framework 20150707-142913-16777343-5050-1796-0000 (BioBox-Mesos-Framework_7292) at scheduler-eed21049-4f05-420b-8d01-06b99a18a2da@127.0.1.1:43847
I0707 14:54:12.920526  1804 master.cpp:2273] Processing ACCEPT call for offers: [ 20150707-142913-16777343-5050-1796-O96 ] on slave 20150707-142913-16777343-5050-1796-S0 at slave(1)@127.0.1.1:5051 (AWM14X) for framework 20150707-142913-16777343-5050-1796-0000 (BioBox-Mesos-Framework_7292) at scheduler-eed21049-4f05-420b-8d01-06b99a18a2da@127.0.1.1:43847
I0707 14:54:12.922140  1805 hierarchical.hpp:648] Recovered mem(*):2048; disk(*):83928; ports(*):[31000-32000]; cpus(*):2 (total allocatable: mem(*):2048; disk(*):83928; ports(*):[31000-32000]; cpus(*):2) on slave 20150707-142913-16777343-5050-1796-S0 from framework 20150707-142913-16777343-5050-1796-0000
I0707 14:54:13.086593  1804 http.cpp:516] HTTP request for '/master/state.json'
I0707 14:54:18.923588  1800 master.cpp:3760] Sending 1 offers to framework 20150707-142913-16777343-5050-1796-0000 (BioBox-Mesos-Framework_7292) at scheduler-eed21049-4f05-420b-8d01-06b99a18a2da@127.0.1.1:43847
I0707 14:54:18.929970  1804 master.cpp:2273] Processing ACCEPT call for offers: [ 20150707-142913-16777343-5050-1796-O97 ] on slave 20150707-142913-16777343-5050-1796-S0 at slave(1)@127.0.1.1:5051 (AWM14X) for framework 20150707-142913-16777343-5050-1796-0000 (BioBox-Mesos-Framework_7292) at scheduler-eed21049-4f05-420b-8d01-06b99a18a2da@127.0.1.1:43847
I0707 14:54:18.931362  1799 hierarchical.hpp:648] Recovered mem(*):2048; disk(*):83928; ports(*):[31000-32000]; cpus(*):2 (total allocatable: mem(*):2048; disk(*):83928; ports(*):[31000-32000]; cpus(*):2) on slave 20150707-142913-16777343-5050-1796-S0 from framework 20150707-142913-16777343-5050-1796-0000
I0707 14:54:23.107324  1801 http.cpp:516] HTTP request for '/master/state.json'
I0707 14:54:24.934010  1800 master.cpp:3760] Sending 1 offers to framework 20150707-142913-16777343-5050-1796-0000 (BioBox-Mesos-Framework_7292) at scheduler-eed21049-4f05-420b-8d01-06b99a18a2da@127.0.1.1:43847
I0707 14:54:24.940400  1798 master.cpp:2273] Processing ACCEPT call for offers: [ 20150707-142913-16777343-5050-1796-O98 ] on slave 20150707-142913-16777343-5050-1796-S0 at slave(1)@127.0.1.1:5051 (AWM14X) for framework 20150707-142913-16777343-5050-1796-0000 (BioBox-Mesos-Framework_7292) at scheduler-eed21049-4f05-420b-8d01-06b99a18a2da@127.0.1.1:43847
I0707 14:54:24.941784  1804 hierarchical.hpp:648] Recovered mem(*):2048; disk(*):83928; ports(*):[31000-32000]; cpus(*):2 (total allocatable: mem(*):2048; disk(*):83928; ports(*):[31000-32000]; cpus(*):2) on slave 20150707-142913-16777343-5050-1796-S0 from framework 20150707-142913-16777343-5050-1796-0000
I0707 14:54:30.943958  1800 master.cpp:3760] Sending 1 offers to framework 20150707-142913-16777343-5050-1796-0000 (BioBox-Mesos-Framework_7292) at scheduler-eed21049-4f05-420b-8d01-06b99a18a2da@127.0.1.1:43847
I0707 14:54:30.949939  1804 master.cpp:2273] Processing ACCEPT call for offers: [ 20150707-142913-16777343-5050-1796-O99 ] on slave 20150707-142913-16777343-5050-1796-S0 at slave(1)@127.0.1.1:5051 (AWM14X) for framework 20150707-142913-16777343-5050-1796-0000 (BioBox-Mesos-Framework_7292) at scheduler-eed21049-4f05-420b-8d01-06b99a18a2da@127.0.1.1:43847
I0707 14:54:30.951169  1804 hierarchical.hpp:648] Recovered mem(*):2048; disk(*):83928; ports(*):[31000-32000]; cpus(*):2 (total allocatable: mem(*):2048; disk(*):83928; ports(*):[31000-32000]; cpus(*):2) on slave 20150707-142913-16777343-5050-1796-S0 from framework 20150707-142913-16777343-5050-1796-0000
I0707 14:54:33.126760  1801 http.cpp:516] HTTP request for '/master/state.json'
I0707 14:54:35.953470  1798 master.cpp:3760] Sending 1 offers to framework 20150707-142913-16777343-5050-1796-0000 (BioBox-Mesos-Framework_7292) at scheduler-eed21049-4f05-420b-8d01-06b99a18a2da@127.0.1.1:43847
I0707 14:54:35.959414  1802 master.cpp:2273] Processing ACCEPT call for offers: [ 20150707-142913-16777343-5050-1796-O100 ] on slave 20150707-142913-16777343-5050-1796-S0 at slave(1)@127.0.1.1:5051 (AWM14X) for framework 20150707-142913-16777343-5050-1796-0000 (BioBox-Mesos-Framework_7292) at scheduler-eed21049-4f05-420b-8d01-06b99a18a2da@127.0.1.1:43847
I0707 14:54:35.960918  1802 hierarchical.hpp:648] Recovered mem(*):2048; disk(*):83928; ports(*):[31000-32000]; cpus(*):2 (total allocatable: mem(*):2048; disk(*):83928; ports(*):[31000-32000]; cpus(*):2) on slave 20150707-142913-16777343-5050-1796-S0 from framework 20150707-142913-16777343-5050-1796-0000
I0707 14:54:41.963006  1802 master.cpp:3760] Sending 1 offers to framework 20150707-142913-16777343-5050-1796-0000 (BioBox-Mesos-Framework_7292) at scheduler-eed21049-4f05-420b-8d01-06b99a18a2da@127.0.1.1:43847
I0707 14:54:41.968870  1800 master.cpp:2273] Processing ACCEPT call for offers: [ 20150707-142913-16777343-5050-1796-O101 ] on slave 20150707-142913-16777343-5050-1796-S0 at slave(1)@127.0.1.1:5051 (AWM14X) for framework 20150707-142913-16777343-5050-1796-0000 (BioBox-Mesos-Framework_7292) at scheduler-eed21049-4f05-420b-8d01-06b99a18a2da@127.0.1.1:43847
I0707 14:54:41.970003  1800 hierarchical.hpp:648] Recovered mem(*):2048; disk(*):83928; ports(*):[31000-32000]; cpus(*):2 (total allocatable: mem(*):2048; disk(*):83928; ports(*):[31000-32000]; cpus(*):2) on slave 20150707-142913-16777343-5050-1796-S0 from framework 20150707-142913-16777343-5050-1796-0000
I0707 14:54:43.146754  1805 http.cpp:516] HTTP request for '/master/state.json'
I0707 14:54:46.971930  1799 master.cpp:3760] Sending 1 offers to framework 20150707-142913-16777343-5050-1796-0000 (BioBox-Mesos-Framework_7292) at scheduler-eed21049-4f05-420b-8d01-06b99a18a2da@127.0.1.1:43847
I0707 14:54:46.978580  1803 master.cpp:2273] Processing ACCEPT call for offers: [ 20150707-142913-16777343-5050-1796-O102 ] on slave 20150707-142913-16777343-5050-1796-S0 at slave(1)@127.0.1.1:5051 (AWM14X) for framework 20150707-142913-16777343-5050-1796-0000 (BioBox-Mesos-Framework_7292) at scheduler-eed21049-4f05-420b-8d01-06b99a18a2da@127.0.1.1:43847
I0707 14:54:46.980116  1798 hierarchical.hpp:648] Recovered mem(*):2048; disk(*):83928; ports(*):[31000-32000]; cpus(*):2 (total allocatable: mem(*):2048; disk(*):83928; ports(*):[31000-32000]; cpus(*):2) on slave 20150707-142913-16777343-5050-1796-S0 from framework 20150707-142913-16777343-5050-1796-0000
I0707 14:54:52.981164  1798 master.cpp:3760] Sending 1 offers to framework 20150707-142913-16777343-5050-1796-0000 (BioBox-Mesos-Framework_7292) at scheduler-eed21049-4f05-420b-8d01-06b99a18a2da@127.0.1.1:43847
I0707 14:54:52.986246  1801 master.cpp:2273] Processing ACCEPT call for offers: [ 20150707-142913-16777343-5050-1796-O103 ] on slave 20150707-142913-16777343-5050-1796-S0 at slave(1)@127.0.1.1:5051 (AWM14X) for framework 20150707-142913-16777343-5050-1796-0000 (BioBox-Mesos-Framework_7292) at scheduler-eed21049-4f05-420b-8d01-06b99a18a2da@127.0.1.1:43847
I0707 14:54:52.987524  1803 hierarchical.hpp:648] Recovered mem(*):2048; disk(*):83928; ports(*):[31000-32000]; cpus(*):2 (total allocatable: mem(*):2048; disk(*):83928; ports(*):[31000-32000]; cpus(*):2) on slave 20150707-142913-16777343-5050-1796-S0 from framework 20150707-142913-16777343-5050-1796-0000
I0707 14:54:53.165963  1801 http.cpp:516] HTTP request for '/master/state.json'
I0707 14:54:57.989435  1798 master.cpp:3760] Sending 1 offers to framework 20150707-142913-16777343-5050-1796-0000 (BioBox-Mesos-Framework_7292) at scheduler-eed21049-4f05-420b-8d01-06b99a18a2da@127.0.1.1:43847
I0707 14:54:57.995616  1803 master.cpp:2273] Processing ACCEPT call for offers: [ 20150707-142913-16777343-5050-1796-O104 ] on slave 20150707-142913-16777343-5050-1796-S0 at slave(1)@127.0.1.1:5051 (AWM14X) for framework 20150707-142913-16777343-5050-1796-0000 (BioBox-Mesos-Framework_7292) at scheduler-eed21049-4f05-420b-8d01-06b99a18a2da@127.0.1.1:43847
I0707 14:54:57.997403  1802 hierarchical.hpp:648] Recovered mem(*):2048; disk(*):83928; ports(*):[31000-32000]; cpus(*):2 (total allocatable: mem(*):2048; disk(*):83928; ports(*):[31000-32000]; cpus(*):2) on slave 20150707-142913-16777343-5050-1796-S0 from framework 20150707-142913-16777343-5050-1796-0000
I0707 14:55:03.186545  1804 http.cpp:516] HTTP request for '/master/state.json'
I0707 14:55:03.999680  1799 master.cpp:3760] Sending 1 offers to framework 20150707-142913-16777343-5050-1796-0000 (BioBox-Mesos-Framework_7292) at scheduler-eed21049-4f05-420b-8d01-06b99a18a2da@127.0.1.1:43847
I0707 14:55:04.005658  1800 master.cpp:2273] Processing ACCEPT call for offers: [ 20150707-142913-16777343-5050-1796-O105 ] on slave 20150707-142913-16777343-5050-1796-S0 at slave(1)@127.0.1.1:5051 (AWM14X) for framework 20150707-142913-16777343-5050-1796-0000 (BioBox-Mesos-Framework_7292) at scheduler-eed21049-4f05-420b-8d01-06b99a18a2da@127.0.1.1:43847
I0707 14:55:04.006943  1800 hierarchical.hpp:648] Recovered mem(*):2048; disk(*):83928; ports(*):[31000-32000]; cpus(*):2 (total allocatable: mem(*):2048; disk(*):83928; ports(*):[31000-32000]; cpus(*):2) on slave 20150707-142913-16777343-5050-1796-S0 from framework 20150707-142913-16777343-5050-1796-0000
I0707 14:55:09.009011  1798 master.cpp:3760] Sending 1 offers to framework 20150707-142913-16777343-5050-1796-0000 (BioBox-Mesos-Framework_7292) at scheduler-eed21049-4f05-420b-8d01-06b99a18a2da@127.0.1.1:43847
I0707 14:55:09.015786  1799 master.cpp:2273] Processing ACCEPT call for offers: [ 20150707-142913-16777343-5050-1796-O106 ] on slave 20150707-142913-16777343-5050-1796-S0 at slave(1)@127.0.1.1:5051 (AWM14X) for framework 20150707-142913-16777343-5050-1796-0000 (BioBox-Mesos-Framework_7292) at scheduler-eed21049-4f05-420b-8d01-06b99a18a2da@127.0.1.1:43847
I0707 14:55:09.017542  1800 hierarchical.hpp:648] Recovered mem(*):2048; disk(*):83928; ports(*):[31000-32000]; cpus(*):2 (total allocatable: mem(*):2048; disk(*):83928; ports(*):[31000-32000]; cpus(*):2) on slave 20150707-142913-16777343-5050-1796-S0 from framework 20150707-142913-16777343-5050-1796-0000
I0707 14:55:13.209050  1802 http.cpp:516] HTTP request for '/master/state.json'
I0707 14:55:15.017737  1802 master.cpp:3760] Sending 1 offers to framework 20150707-142913-16777343-5050-1796-0000 (BioBox-Mesos-Framework_7292) at scheduler-eed21049-4f05-420b-8d01-06b99a18a2da@127.0.1.1:43847
I0707 14:55:15.023653  1799 master.cpp:2273] Processing ACCEPT call for offers: [ 20150707-142913-16777343-5050-1796-O107 ] on slave 20150707-142913-16777343-5050-1796-S0 at slave(1)@127.0.1.1:5051 (AWM14X) for framework 20150707-142913-16777343-5050-1796-0000 (BioBox-Mesos-Framework_7292) at scheduler-eed21049-4f05-420b-8d01-06b99a18a2da@127.0.1.1:43847
I0707 14:55:15.025145  1799 hierarchical.hpp:648] Recovered mem(*):2048; disk(*):83928; ports(*):[31000-32000]; cpus(*):2 (total allocatable: mem(*):2048; disk(*):83928; ports(*):[31000-32000]; cpus(*):2) on slave 20150707-142913-16777343-5050-1796-S0 from framework 20150707-142913-16777343-5050-1796-0000
I0707 14:55:21.027747  1799 master.cpp:3760] Sending 1 offers to framework 20150707-142913-16777343-5050-1796-0000 (BioBox-Mesos-Framework_7292) at scheduler-eed21049-4f05-420b-8d01-06b99a18a2da@127.0.1.1:43847
I0707 14:55:21.034173  1801 master.cpp:2273] Processing ACCEPT call for offers: [ 20150707-142913-16777343-5050-1796-O108 ] on slave 20150707-142913-16777343-5050-1796-S0 at slave(1)@127.0.1.1:5051 (AWM14X) for framework 20150707-142913-16777343-5050-1796-0000 (BioBox-Mesos-Framework_7292) at scheduler-eed21049-4f05-420b-8d01-06b99a18a2da@127.0.1.1:43847
I0707 14:55:21.035456  1801 hierarchical.hpp:648] Recovered mem(*):2048; disk(*):83928; ports(*):[31000-32000]; cpus(*):2 (total allocatable: mem(*):2048; disk(*):83928; ports(*):[31000-32000]; cpus(*):2) on slave 20150707-142913-16777343-5050-1796-S0 from framework 20150707-142913-16777343-5050-1796-0000
I0707 14:55:23.228899  1804 http.cpp:516] HTTP request for '/master/state.json'
I0707 14:55:27.038141  1805 master.cpp:3760] Sending 1 offers to framework 20150707-142913-16777343-5050-1796-0000 (BioBox-Mesos-Framework_7292) at scheduler-eed21049-4f05-420b-8d01-06b99a18a2da@127.0.1.1:43847
I0707 14:55:27.044484  1800 master.cpp:2273] Processing ACCEPT call for offers: [ 20150707-142913-16777343-5050-1796-O109 ] on slave 20150707-142913-16777343-5050-1796-S0 at slave(1)@127.0.1.1:5051 (AWM14X) for framework 20150707-142913-16777343-5050-1796-0000 (BioBox-Mesos-Framework_7292) at scheduler-eed21049-4f05-420b-8d01-06b99a18a2da@127.0.1.1:43847
I0707 14:55:27.045974  1800 hierarchical.hpp:648] Recovered mem(*):2048; disk(*):83928; ports(*):[31000-32000]; cpus(*):2 (total allocatable: mem(*):2048; disk(*):83928; ports(*):[31000-32000]; cpus(*):2) on slave 20150707-142913-16777343-5050-1796-S0 from framework 20150707-142913-16777343-5050-1796-0000
I0707 14:55:33.047919  1800 master.cpp:3760] Sending 1 offers to framework 20150707-142913-16777343-5050-1796-0000 (BioBox-Mesos-Framework_7292) at scheduler-eed21049-4f05-420b-8d01-06b99a18a2da@127.0.1.1:43847
I0707 14:55:33.054394  1804 master.cpp:2273] Processing ACCEPT call for offers: [ 20150707-142913-16777343-5050-1796-O110 ] on slave 20150707-142913-16777343-5050-1796-S0 at slave(1)@127.0.1.1:5051 (AWM14X) for framework 20150707-142913-16777343-5050-1796-0000 (BioBox-Mesos-Framework_7292) at scheduler-eed21049-4f05-420b-8d01-06b99a18a2da@127.0.1.1:43847
I0707 14:55:33.055905  1804 hierarchical.hpp:648] Recovered mem(*):2048; disk(*):83928; ports(*):[31000-32000]; cpus(*):2 (total allocatable: mem(*):2048; disk(*):83928; ports(*):[31000-32000]; cpus(*):2) on slave 20150707-142913-16777343-5050-1796-S0 from framework 20150707-142913-16777343-5050-1796-0000
I0707 14:55:33.249469  1799 http.cpp:516] HTTP request for '/master/state.json'
I0707 14:55:39.058092  1801 master.cpp:3760] Sending 1 offers to framework 20150707-142913-16777343-5050-1796-0000 (BioBox-Mesos-Framework_7292) at scheduler-eed21049-4f05-420b-8d01-06b99a18a2da@127.0.1.1:43847
I0707 14:55:39.064435  1798 master.cpp:2273] Processing ACCEPT call for offers: [ 20150707-142913-16777343-5050-1796-O111 ] on slave 20150707-142913-16777343-5050-1796-S0 at slave(1)@127.0.1.1:5051 (AWM14X) for framework 20150707-142913-16777343-5050-1796-0000 (BioBox-Mesos-Framework_7292) at scheduler-eed21049-4f05-420b-8d01-06b99a18a2da@127.0.1.1:43847
I0707 14:55:39.065840  1798 hierarchical.hpp:648] Recovered mem(*):2048; disk(*):83928; ports(*):[31000-32000]; cpus(*):2 (total allocatable: mem(*):2048; disk(*):83928; ports(*):[31000-32000]; cpus(*):2) on slave 20150707-142913-16777343-5050-1796-S0 from framework 20150707-142913-16777343-5050-1796-0000
I0707 14:55:43.270117  1805 http.cpp:516] HTTP request for '/master/state.json'
I0707 14:55:45.068145  1802 master.cpp:3760] Sending 1 offers to framework 20150707-142913-16777343-5050-1796-0000 (BioBox-Mesos-Framework_7292) at scheduler-eed21049-4f05-420b-8d01-06b99a18a2da@127.0.1.1:43847
I0707 14:55:45.075239  1798 master.cpp:2273] Processing ACCEPT call for offers: [ 20150707-142913-16777343-5050-1796-O112 ] on slave 20150707-142913-16777343-5050-1796-S0 at slave(1)@127.0.1.1:5051 (AWM14X) for framework 20150707-142913-16777343-5050-1796-0000 (BioBox-Mesos-Framework_7292) at scheduler-eed21049-4f05-420b-8d01-06b99a18a2da@127.0.1.1:43847
I0707 14:55:45.076714  1798 hierarchical.hpp:648] Recovered mem(*):2048; disk(*):83928; ports(*):[31000-32000]; cpus(*):2 (total allocatable: mem(*):2048; disk(*):83928; ports(*):[31000-32000]; cpus(*):2) on slave 20150707-142913-16777343-5050-1796-S0 from framework 20150707-142913-16777343-5050-1796-0000
I0707 14:55:51.077056  1802 master.cpp:3760] Sending 1 offers to framework 20150707-142913-16777343-5050-1796-0000 (BioBox-Mesos-Framework_7292) at scheduler-eed21049-4f05-420b-8d01-06b99a18a2da@127.0.1.1:43847
I0707 14:55:51.083256  1804 master.cpp:2273] Processing ACCEPT call for offers: [ 20150707-142913-16777343-5050-1796-O113 ] on slave 20150707-142913-16777343-5050-1796-S0 at slave(1)@127.0.1.1:5051 (AWM14X) for framework 20150707-142913-16777343-5050-1796-0000 (BioBox-Mesos-Framework_7292) at scheduler-eed21049-4f05-420b-8d01-06b99a18a2da@127.0.1.1:43847
I0707 14:55:51.084660  1804 hierarchical.hpp:648] Recovered mem(*):2048; disk(*):83928; ports(*):[31000-32000]; cpus(*):2 (total allocatable: mem(*):2048; disk(*):83928; ports(*):[31000-32000]; cpus(*):2) on slave 20150707-142913-16777343-5050-1796-S0 from framework 20150707-142913-16777343-5050-1796-0000
I0707 14:55:53.290614  1799 http.cpp:516] HTTP request for '/master/state.json'
I0707 14:55:57.087455  1800 master.cpp:3760] Sending 1 offers to framework 20150707-142913-16777343-5050-1796-0000 (BioBox-Mesos-Framework_7292) at scheduler-eed21049-4f05-420b-8d01-06b99a18a2da@127.0.1.1:43847
I0707 14:55:57.094408  1805 master.cpp:2273] Processing ACCEPT call for offers: [ 20150707-142913-16777343-5050-1796-O114 ] on slave 20150707-142913-16777343-5050-1796-S0 at slave(1)@127.0.1.1:5051 (AWM14X) for framework 20150707-142913-16777343-5050-1796-0000 (BioBox-Mesos-Framework_7292) at scheduler-eed21049-4f05-420b-8d01-06b99a18a2da@127.0.1.1:43847
I0707 14:55:57.096289  1803 hierarchical.hpp:648] Recovered mem(*):2048; disk(*):83928; ports(*):[31000-32000]; cpus(*):2 (total allocatable: mem(*):2048; disk(*):83928; ports(*):[31000-32000]; cpus(*):2) on slave 20150707-142913-16777343-5050-1796-S0 from framework 20150707-142913-16777343-5050-1796-0000
I0707 14:56:03.098081  1803 master.cpp:3760] Sending 1 offers to framework 20150707-142913-16777343-5050-1796-0000 (BioBox-Mesos-Framework_7292) at scheduler-eed21049-4f05-420b-8d01-06b99a18a2da@127.0.1.1:43847
I0707 14:56:03.104476  1805 master.cpp:2273] Processing ACCEPT call for offers: [ 20150707-142913-16777343-5050-1796-O115 ] on slave 20150707-142913-16777343-5050-1796-S0 at slave(1)@127.0.1.1:5051 (AWM14X) for framework 20150707-142913-16777343-5050-1796-0000 (BioBox-Mesos-Framework_7292) at scheduler-eed21049-4f05-420b-8d01-06b99a18a2da@127.0.1.1:43847
I0707 14:56:03.105824  1802 hierarchical.hpp:648] Recovered mem(*):2048; disk(*):83928; ports(*):[31000-32000]; cpus(*):2 (total allocatable: mem(*):2048; disk(*):83928; ports(*):[31000-32000]; cpus(*):2) on slave 20150707-142913-16777343-5050-1796-S0 from framework 20150707-142913-16777343-5050-1796-0000
I0707 14:56:03.311311  1801 http.cpp:516] HTTP request for '/master/state.json'
I0707 14:56:09.108579  1805 master.cpp:3760] Sending 1 offers to framework 20150707-142913-16777343-5050-1796-0000 (BioBox-Mesos-Framework_7292) at scheduler-eed21049-4f05-420b-8d01-06b99a18a2da@127.0.1.1:43847
I0707 14:56:09.114676  1804 master.cpp:2273] Processing ACCEPT call for offers: [ 20150707-142913-16777343-5050-1796-O116 ] on slave 20150707-142913-16777343-5050-1796-S0 at slave(1)@127.0.1.1:5051 (AWM14X) for framework 20150707-142913-16777343-5050-1796-0000 (BioBox-Mesos-Framework_7292) at scheduler-eed21049-4f05-420b-8d01-06b99a18a2da@127.0.1.1:43847
I0707 14:56:09.116447  1801 hierarchical.hpp:648] Recovered mem(*):2048; disk(*):83928; ports(*):[31000-32000]; cpus(*):2 (total allocatable: mem(*):2048; disk(*):83928; ports(*):[31000-32000]; cpus(*):2) on slave 20150707-142913-16777343-5050-1796-S0 from framework 20150707-142913-16777343-5050-1796-0000
I0707 14:56:13.331409  1803 http.cpp:516] HTTP request for '/master/state.json'
I0707 14:56:15.119395  1802 master.cpp:3760] Sending 1 offers to framework 20150707-142913-16777343-5050-1796-0000 (BioBox-Mesos-Framework_7292) at scheduler-eed21049-4f05-420b-8d01-06b99a18a2da@127.0.1.1:43847
I0707 14:56:15.125674  1805 master.cpp:2273] Processing ACCEPT call for offers: [ 20150707-142913-16777343-5050-1796-O117 ] on slave 20150707-142913-16777343-5050-1796-S0 at slave(1)@127.0.1.1:5051 (AWM14X) for framework 20150707-142913-16777343-5050-1796-0000 (BioBox-Mesos-Framework_7292) at scheduler-eed21049-4f05-420b-8d01-06b99a18a2da@127.0.1.1:43847
I0707 14:56:15.127430  1804 hierarchical.hpp:648] Recovered mem(*):2048; disk(*):83928; ports(*):[31000-32000]; cpus(*):2 (total allocatable: mem(*):2048; disk(*):83928; ports(*):[31000-32000]; cpus(*):2) on slave 20150707-142913-16777343-5050-1796-S0 from framework 20150707-142913-16777343-5050-1796-0000
I0707 14:56:20.129025  1802 master.cpp:3760] Sending 1 offers to framework 20150707-142913-16777343-5050-1796-0000 (BioBox-Mesos-Framework_7292) at scheduler-eed21049-4f05-420b-8d01-06b99a18a2da@127.0.1.1:43847
I0707 14:56:20.135375  1804 master.cpp:2273] Processing ACCEPT call for offers: [ 20150707-142913-16777343-5050-1796-O118 ] on slave 20150707-142913-16777343-5050-1796-S0 at slave(1)@127.0.1.1:5051 (AWM14X) for framework 20150707-142913-16777343-5050-1796-0000 (BioBox-Mesos-Framework_7292) at scheduler-eed21049-4f05-420b-8d01-06b99a18a2da@127.0.1.1:43847
I0707 14:56:20.136765  1804 hierarchical.hpp:648] Recovered mem(*):2048; disk(*):83928; ports(*):[31000-32000]; cpus(*):2 (total allocatable: mem(*):2048; disk(*):83928; ports(*):[31000-32000]; cpus(*):2) on slave 20150707-142913-16777343-5050-1796-S0 from framework 20150707-142913-16777343-5050-1796-0000
I0707 14:56:23.349829  1799 http.cpp:516] HTTP request for '/master/state.json'
I0707 14:56:25.138294  1798 master.cpp:3760] Sending 1 offers to framework 20150707-142913-16777343-5050-1796-0000 (BioBox-Mesos-Framework_7292) at scheduler-eed21049-4f05-420b-8d01-06b99a18a2da@127.0.1.1:43847
I0707 14:56:25.144635  1804 master.cpp:2273] Processing ACCEPT call for offers: [ 20150707-142913-16777343-5050-1796-O119 ] on slave 20150707-142913-16777343-5050-1796-S0 at slave(1)@127.0.1.1:5051 (AWM14X) for framework 20150707-142913-16777343-5050-1796-0000 (BioBox-Mesos-Framework_7292) at scheduler-eed21049-4f05-420b-8d01-06b99a18a2da@127.0.1.1:43847
I0707 14:56:25.145839  1804 hierarchical.hpp:648] Recovered mem(*):2048; disk(*):83928; ports(*):[31000-32000]; cpus(*):2 (total allocatable: mem(*):2048; disk(*):83928; ports(*):[31000-32000]; cpus(*):2) on slave 20150707-142913-16777343-5050-1796-S0 from framework 20150707-142913-16777343-5050-1796-0000
I0707 14:56:30.147466  1800 master.cpp:3760] Sending 1 offers to framework 20150707-142913-16777343-5050-1796-0000 (BioBox-Mesos-Framework_7292) at scheduler-eed21049-4f05-420b-8d01-06b99a18a2da@127.0.1.1:43847
I0707 14:56:30.153717  1798 master.cpp:2273] Processing ACCEPT call for offers: [ 20150707-142913-16777343-5050-1796-O120 ] on slave 20150707-142913-16777343-5050-1796-S0 at slave(1)@127.0.1.1:5051 (AWM14X) for framework 20150707-142913-16777343-5050-1796-0000 (BioBox-Mesos-Framework_7292) at scheduler-eed21049-4f05-420b-8d01-06b99a18a2da@127.0.1.1:43847
I0707 14:56:30.155300  1804 hierarchical.hpp:648] Recovered mem(*):2048; disk(*):83928; ports(*):[31000-32000]; cpus(*):2 (total allocatable: mem(*):2048; disk(*):83928; ports(*):[31000-32000]; cpus(*):2) on slave 20150707-142913-16777343-5050-1796-S0 from framework 20150707-142913-16777343-5050-1796-0000
I0707 14:56:33.367226  1803 http.cpp:516] HTTP request for '/master/state.json'
I0707 14:56:36.157815  1805 master.cpp:3760] Sending 1 offers to framework 20150707-142913-16777343-5050-1796-0000 (BioBox-Mesos-Framework_7292) at scheduler-eed21049-4f05-420b-8d01-06b99a18a2da@127.0.1.1:43847
I0707 14:56:36.164021  1798 master.cpp:2273] Processing ACCEPT call for offers: [ 20150707-142913-16777343-5050-1796-O121 ] on slave 20150707-142913-16777343-5050-1796-S0 at slave(1)@127.0.1.1:5051 (AWM14X) for framework 20150707-142913-16777343-5050-1796-0000 (BioBox-Mesos-Framework_7292) at scheduler-eed21049-4f05-420b-8d01-06b99a18a2da@127.0.1.1:43847
I0707 14:56:36.165526  1798 hierarchical.hpp:648] Recovered mem(*):2048; disk(*):83928; ports(*):[31000-32000]; cpus(*):2 (total allocatable: mem(*):2048; disk(*):83928; ports(*):[31000-32000]; cpus(*):2) on slave 20150707-142913-16777343-5050-1796-S0 from framework 20150707-142913-16777343-5050-1796-0000
I0707 14:56:42.168212  1801 master.cpp:3760] Sending 1 offers to framework 20150707-142913-16777343-5050-1796-0000 (BioBox-Mesos-Framework_7292) at scheduler-eed21049-4f05-420b-8d01-06b99a18a2da@127.0.1.1:43847
I0707 14:56:42.174674  1798 master.cpp:2273] Processing ACCEPT call for offers: [ 20150707-142913-16777343-5050-1796-O122 ] on slave 20150707-142913-16777343-5050-1796-S0 at slave(1)@127.0.1.1:5051 (AWM14X) for framework 20150707-142913-16777343-5050-1796-0000 (BioBox-Mesos-Framework_7292) at scheduler-eed21049-4f05-420b-8d01-06b99a18a2da@127.0.1.1:43847
I0707 14:56:42.176146  1804 hierarchical.hpp:648] Recovered mem(*):2048; disk(*):83928; ports(*):[31000-32000]; cpus(*):2 (total allocatable: mem(*):2048; disk(*):83928; ports(*):[31000-32000]; cpus(*):2) on slave 20150707-142913-16777343-5050-1796-S0 from framework 20150707-142913-16777343-5050-1796-0000
I0707 14:56:43.385267  1799 http.cpp:516] HTTP request for '/master/state.json'
I0707 14:56:48.178817  1803 master.cpp:3760] Sending 1 offers to framework 20150707-142913-16777343-5050-1796-0000 (BioBox-Mesos-Framework_7292) at scheduler-eed21049-4f05-420b-8d01-06b99a18a2da@127.0.1.1:43847
I0707 14:56:48.185014  1805 master.cpp:2273] Processing ACCEPT call for offers: [ 20150707-142913-16777343-5050-1796-O123 ] on slave 20150707-142913-16777343-5050-1796-S0 at slave(1)@127.0.1.1:5051 (AWM14X) for framework 20150707-142913-16777343-5050-1796-0000 (BioBox-Mesos-Framework_7292) at scheduler-eed21049-4f05-420b-8d01-06b99a18a2da@127.0.1.1:43847
I0707 14:56:48.186223  1805 hierarchical.hpp:648] Recovered mem(*):2048; disk(*):83928; ports(*):[31000-32000]; cpus(*):2 (total allocatable: mem(*):2048; disk(*):83928; ports(*):[31000-32000]; cpus(*):2) on slave 20150707-142913-16777343-5050-1796-S0 from framework 20150707-142913-16777343-5050-1796-0000
I0707 14:56:53.187643  1798 master.cpp:3760] Sending 1 offers to framework 20150707-142913-16777343-5050-1796-0000 (BioBox-Mesos-Framework_7292) at scheduler-eed21049-4f05-420b-8d01-06b99a18a2da@127.0.1.1:43847
I0707 14:56:53.193892  1804 master.cpp:2273] Processing ACCEPT call for offers: [ 20150707-142913-16777343-5050-1796-O124 ] on slave 20150707-142913-16777343-5050-1796-S0 at slave(1)@127.0.1.1:5051 (AWM14X) for framework 20150707-142913-16777343-5050-1796-0000 (BioBox-Mesos-Framework_7292) at scheduler-eed21049-4f05-420b-8d01-06b99a18a2da@127.0.1.1:43847
I0707 14:56:53.195399  1804 hierarchical.hpp:648] Recovered mem(*):2048; disk(*):83928; ports(*):[31000-32000]; cpus(*):2 (total allocatable: mem(*):2048; disk(*):83928; ports(*):[31000-32000]; cpus(*):2) on slave 20150707-142913-16777343-5050-1796-S0 from framework 20150707-142913-16777343-5050-1796-0000
I0707 14:56:53.404552  1803 http.cpp:516] HTTP request for '/master/state.json'
I0707 14:56:59.196830  1803 master.cpp:3760] Sending 1 offers to framework 20150707-142913-16777343-5050-1796-0000 (BioBox-Mesos-Framework_7292) at scheduler-eed21049-4f05-420b-8d01-06b99a18a2da@127.0.1.1:43847
I0707 14:56:59.203438  1801 master.cpp:2273] Processing ACCEPT call for offers: [ 20150707-142913-16777343-5050-1796-O125 ] on slave 20150707-142913-16777343-5050-1796-S0 at slave(1)@127.0.1.1:5051 (AWM14X) for framework 20150707-142913-16777343-5050-1796-0000 (BioBox-Mesos-Framework_7292) at scheduler-eed21049-4f05-420b-8d01-06b99a18a2da@127.0.1.1:43847
I0707 14:56:59.204748  1799 hierarchical.hpp:648] Recovered mem(*):2048; disk(*):83928; ports(*):[31000-32000]; cpus(*):2 (total allocatable: mem(*):2048; disk(*):83928; ports(*):[31000-32000]; cpus(*):2) on slave 20150707-142913-16777343-5050-1796-S0 from framework 20150707-142913-16777343-5050-1796-0000
I0707 14:57:03.423425  1805 http.cpp:516] HTTP request for '/master/state.json'
I0707 14:57:05.207319  1804 master.cpp:3760] Sending 1 offers to framework 20150707-142913-16777343-5050-1796-0000 (BioBox-Mesos-Framework_7292) at scheduler-eed21049-4f05-420b-8d01-06b99a18a2da@127.0.1.1:43847
I0707 14:57:05.213995  1800 master.cpp:2273] Processing ACCEPT call for offers: [ 20150707-142913-16777343-5050-1796-O126 ] on slave 20150707-142913-16777343-5050-1796-S0 at slave(1)@127.0.1.1:5051 (AWM14X) for framework 20150707-142913-16777343-5050-1796-0000 (BioBox-Mesos-Framework_7292) at scheduler-eed21049-4f05-420b-8d01-06b99a18a2da@127.0.1.1:43847
I0707 14:57:05.215594  1805 hierarchical.hpp:648] Recovered mem(*):2048; disk(*):83928; ports(*):[31000-32000]; cpus(*):2 (total allocatable: mem(*):2048; disk(*):83928; ports(*):[31000-32000]; cpus(*):2) on slave 20150707-142913-16777343-5050-1796-S0 from framework 20150707-142913-16777343-5050-1796-0000
I0707 14:57:11.217417  1803 master.cpp:3760] Sending 1 offers to framework 20150707-142913-16777343-5050-1796-0000 (BioBox-Mesos-Framework_7292) at scheduler-eed21049-4f05-420b-8d01-06b99a18a2da@127.0.1.1:43847
I0707 14:57:11.224542  1805 master.cpp:2273] Processing ACCEPT call for offers: [ 20150707-142913-16777343-5050-1796-O127 ] on slave 20150707-142913-16777343-5050-1796-S0 at slave(1)@127.0.1.1:5051 (AWM14X) for framework 20150707-142913-16777343-5050-1796-0000 (BioBox-Mesos-Framework_7292) at scheduler-eed21049-4f05-420b-8d01-06b99a18a2da@127.0.1.1:43847
I0707 14:57:11.225942  1800 hierarchical.hpp:648] Recovered mem(*):2048; disk(*):83928; ports(*):[31000-32000]; cpus(*):2 (total allocatable: mem(*):2048; disk(*):83928; ports(*):[31000-32000]; cpus(*):2) on slave 20150707-142913-16777343-5050-1796-S0 from framework 20150707-142913-16777343-5050-1796-0000
I0707 14:57:13.442862  1801 http.cpp:516] HTTP request for '/master/state.json'
I0707 14:57:17.228001  1803 master.cpp:3760] Sending 1 offers to framework 20150707-142913-16777343-5050-1796-0000 (BioBox-Mesos-Framework_7292) at scheduler-eed21049-4f05-420b-8d01-06b99a18a2da@127.0.1.1:43847
I0707 14:57:17.234561  1798 master.cpp:2273] Processing ACCEPT call for offers: [ 20150707-142913-16777343-5050-1796-O128 ] on slave 20150707-142913-16777343-5050-1796-S0 at slave(1)@127.0.1.1:5051 (AWM14X) for framework 20150707-142913-16777343-5050-1796-0000 (BioBox-Mesos-Framework_7292) at scheduler-eed21049-4f05-420b-8d01-06b99a18a2da@127.0.1.1:43847
I0707 14:57:17.236222  1800 hierarchical.hpp:648] Recovered mem(*):2048; disk(*):83928; ports(*):[31000-32000]; cpus(*):2 (total allocatable: mem(*):2048; disk(*):83928; ports(*):[31000-32000]; cpus(*):2) on slave 20150707-142913-16777343-5050-1796-S0 from framework 20150707-142913-16777343-5050-1796-0000
I0707 14:57:23.239027  1800 master.cpp:3760] Sending 1 offers to framework 20150707-142913-16777343-5050-1796-0000 (BioBox-Mesos-Framework_7292) at scheduler-eed21049-4f05-420b-8d01-06b99a18a2da@127.0.1.1:43847
I0707 14:57:23.245353  1798 master.cpp:2273] Processing ACCEPT call for offers: [ 20150707-142913-16777343-5050-1796-O129 ] on slave 20150707-142913-16777343-5050-1796-S0 at slave(1)@127.0.1.1:5051 (AWM14X) for framework 20150707-142913-16777343-5050-1796-0000 (BioBox-Mesos-Framework_7292) at scheduler-eed21049-4f05-420b-8d01-06b99a18a2da@127.0.1.1:43847
I0707 14:57:23.246752  1799 hierarchical.hpp:648] Recovered mem(*):2048; disk(*):83928; ports(*):[31000-32000]; cpus(*):2 (total allocatable: mem(*):2048; disk(*):83928; ports(*):[31000-32000]; cpus(*):2) on slave 20150707-142913-16777343-5050-1796-S0 from framework 20150707-142913-16777343-5050-1796-0000
I0707 14:57:23.463048  1798 http.cpp:516] HTTP request for '/master/state.json'
I0707 14:57:29.249260  1802 master.cpp:3760] Sending 1 offers to framework 20150707-142913-16777343-5050-1796-0000 (BioBox-Mesos-Framework_7292) at scheduler-eed21049-4f05-420b-8d01-06b99a18a2da@127.0.1.1:43847
I0707 14:57:29.255120  1805 master.cpp:2273] Processing ACCEPT call for offers: [ 20150707-142913-16777343-5050-1796-O130 ] on slave 20150707-142913-16777343-5050-1796-S0 at slave(1)@127.0.1.1:5051 (AWM14X) for framework 20150707-142913-16777343-5050-1796-0000 (BioBox-Mesos-Framework_7292) at scheduler-eed21049-4f05-420b-8d01-06b99a18a2da@127.0.1.1:43847
I0707 14:57:29.256290  1800 hierarchical.hpp:648] Recovered mem(*):2048; disk(*):83928; ports(*):[31000-32000]; cpus(*):2 (total allocatable: mem(*):2048; disk(*):83928; ports(*):[31000-32000]; cpus(*):2) on slave 20150707-142913-16777343-5050-1796-S0 from framework 20150707-142913-16777343-5050-1796-0000
I0707 14:57:33.482367  1803 http.cpp:516] HTTP request for '/master/state.json'
I0707 14:57:34.257529  1802 master.cpp:3760] Sending 1 offers to framework 20150707-142913-16777343-5050-1796-0000 (BioBox-Mesos-Framework_7292) at scheduler-eed21049-4f05-420b-8d01-06b99a18a2da@127.0.1.1:43847
I0707 14:57:34.260288  1800 master.cpp:2273] Processing ACCEPT call for offers: [ 20150707-142913-16777343-5050-1796-O131 ] on slave 20150707-142913-16777343-5050-1796-S0 at slave(1)@127.0.1.1:5051 (AWM14X) for framework 20150707-142913-16777343-5050-1796-0000 (BioBox-Mesos-Framework_7292) at scheduler-eed21049-4f05-420b-8d01-06b99a18a2da@127.0.1.1:43847
I0707 14:57:34.260831  1800 hierarchical.hpp:648] Recovered mem(*):2048; disk(*):83928; ports(*):[31000-32000]; cpus(*):2 (total allocatable: mem(*):2048; disk(*):83928; ports(*):[31000-32000]; cpus(*):2) on slave 20150707-142913-16777343-5050-1796-S0 from framework 20150707-142913-16777343-5050-1796-0000
I0707 14:57:39.265897  1802 master.cpp:3760] Sending 1 offers to framework 20150707-142913-16777343-5050-1796-0000 (BioBox-Mesos-Framework_7292) at scheduler-eed21049-4f05-420b-8d01-06b99a18a2da@127.0.1.1:43847
I0707 14:57:39.269254  1799 master.cpp:2273] Processing ACCEPT call for offers: [ 20150707-142913-16777343-5050-1796-O132 ] on slave 20150707-142913-16777343-5050-1796-S0 at slave(1)@127.0.1.1:5051 (AWM14X) for framework 20150707-142913-16777343-5050-1796-0000 (BioBox-Mesos-Framework_7292) at scheduler-eed21049-4f05-420b-8d01-06b99a18a2da@127.0.1.1:43847
I0707 14:57:39.269904  1800 hierarchical.hpp:648] Recovered mem(*):2048; disk(*):83928; ports(*):[31000-32000]; cpus(*):2 (total allocatable: mem(*):2048; disk(*):83928; ports(*):[31000-32000]; cpus(*):2) on slave 20150707-142913-16777343-5050-1796-S0 from framework 20150707-142913-16777343-5050-1796-0000
I0707 14:57:43.501389  1804 http.cpp:516] HTTP request for '/master/state.json'
I0707 14:57:44.272145  1799 master.cpp:3760] Sending 1 offers to framework 20150707-142913-16777343-5050-1796-0000 (BioBox-Mesos-Framework_7292) at scheduler-eed21049-4f05-420b-8d01-06b99a18a2da@127.0.1.1:43847
I0707 14:57:44.278450  1800 master.cpp:2273] Processing ACCEPT call for offers: [ 20150707-142913-16777343-5050-1796-O133 ] on slave 20150707-142913-16777343-5050-1796-S0 at slave(1)@127.0.1.1:5051 (AWM14X) for framework 20150707-142913-16777343-5050-1796-0000 (BioBox-Mesos-Framework_7292) at scheduler-eed21049-4f05-420b-8d01-06b99a18a2da@127.0.1.1:43847
I0707 14:57:44.280102  1800 hierarchical.hpp:648] Recovered mem(*):2048; disk(*):83928; ports(*):[31000-32000]; cpus(*):2 (total allocatable: mem(*):2048; disk(*):83928; ports(*):[31000-32000]; cpus(*):2) on slave 20150707-142913-16777343-5050-1796-S0 from framework 20150707-142913-16777343-5050-1796-0000
I0707 14:57:50.282373  1800 master.cpp:3760] Sending 1 offers to framework 20150707-142913-16777343-5050-1796-0000 (BioBox-Mesos-Framework_7292) at scheduler-eed21049-4f05-420b-8d01-06b99a18a2da@127.0.1.1:43847
I0707 14:57:50.288903  1803 master.cpp:2273] Processing ACCEPT call for offers: [ 20150707-142913-16777343-5050-1796-O134 ] on slave 20150707-142913-16777343-5050-1796-S0 at slave(1)@127.0.1.1:5051 (AWM14X) for framework 20150707-142913-16777343-5050-1796-0000 (BioBox-Mesos-Framework_7292) at scheduler-eed21049-4f05-420b-8d01-06b99a18a2da@127.0.1.1:43847
I0707 14:57:50.290333  1805 hierarchical.hpp:648] Recovered mem(*):2048; disk(*):83928; ports(*):[31000-32000]; cpus(*):2 (total allocatable: mem(*):2048; disk(*):83928; ports(*):[31000-32000]; cpus(*):2) on slave 20150707-142913-16777343-5050-1796-S0 from framework 20150707-142913-16777343-5050-1796-0000
I0707 14:57:53.520989  1798 http.cpp:516] HTTP request for '/master/state.json'
I0707 14:57:56.292439  1799 master.cpp:3760] Sending 1 offers to framework 20150707-142913-16777343-5050-1796-0000 (BioBox-Mesos-Framework_7292) at scheduler-eed21049-4f05-420b-8d01-06b99a18a2da@127.0.1.1:43847
I0707 14:57:56.298773  1800 master.cpp:2273] Processing ACCEPT call for offers: [ 20150707-142913-16777343-5050-1796-O135 ] on slave 20150707-142913-16777343-5050-1796-S0 at slave(1)@127.0.1.1:5051 (AWM14X) for framework 20150707-142913-16777343-5050-1796-0000 (BioBox-Mesos-Framework_7292) at scheduler-eed21049-4f05-420b-8d01-06b99a18a2da@127.0.1.1:43847
I0707 14:57:56.300400  1804 hierarchical.hpp:648] Recovered mem(*):2048; disk(*):83928; ports(*):[31000-32000]; cpus(*):2 (total allocatable: mem(*):2048; disk(*):83928; ports(*):[31000-32000]; cpus(*):2) on slave 20150707-142913-16777343-5050-1796-S0 from framework 20150707-142913-16777343-5050-1796-0000
I0707 14:58:02.302335  1803 master.cpp:3760] Sending 1 offers to framework 20150707-142913-16777343-5050-1796-0000 (BioBox-Mesos-Framework_7292) at scheduler-eed21049-4f05-420b-8d01-06b99a18a2da@127.0.1.1:43847
I0707 14:58:02.308691  1799 master.cpp:2273] Processing ACCEPT call for offers: [ 20150707-142913-16777343-5050-1796-O136 ] on slave 20150707-142913-16777343-5050-1796-S0 at slave(1)@127.0.1.1:5051 (AWM14X) for framework 20150707-142913-16777343-5050-1796-0000 (BioBox-Mesos-Framework_7292) at scheduler-eed21049-4f05-420b-8d01-06b99a18a2da@127.0.1.1:43847
I0707 14:58:02.310387  1804 hierarchical.hpp:648] Recovered mem(*):2048; disk(*):83928; ports(*):[31000-32000]; cpus(*):2 (total allocatable: mem(*):2048; disk(*):83928; ports(*):[31000-32000]; cpus(*):2) on slave 20150707-142913-16777343-5050-1796-S0 from framework 20150707-142913-16777343-5050-1796-0000
I0707 14:58:03.541319  1798 http.cpp:516] HTTP request for '/master/state.json'
I0707 14:58:08.312274  1801 master.cpp:3760] Sending 1 offers to framework 20150707-142913-16777343-5050-1796-0000 (BioBox-Mesos-Framework_7292) at scheduler-eed21049-4f05-420b-8d01-06b99a18a2da@127.0.1.1:43847
I0707 14:58:08.319505  1804 master.cpp:2273] Processing ACCEPT call for offers: [ 20150707-142913-16777343-5050-1796-O137 ] on slave 20150707-142913-16777343-5050-1796-S0 at slave(1)@127.0.1.1:5051 (AWM14X) for framework 20150707-142913-16777343-5050-1796-0000 (BioBox-Mesos-Framework_7292) at scheduler-eed21049-4f05-420b-8d01-06b99a18a2da@127.0.1.1:43847
I0707 14:58:08.321643  1802 hierarchical.hpp:648] Recovered mem(*):2048; disk(*):83928; ports(*):[31000-32000]; cpus(*):2 (total allocatable: mem(*):2048; disk(*):83928; ports(*):[31000-32000]; cpus(*):2) on slave 20150707-142913-16777343-5050-1796-S0 from framework 20150707-142913-16777343-5050-1796-0000
I0707 14:58:13.560673  1801 http.cpp:516] HTTP request for '/master/state.json'
I0707 14:58:14.321897  1805 master.cpp:3760] Sending 1 offers to framework 20150707-142913-16777343-5050-1796-0000 (BioBox-Mesos-Framework_7292) at scheduler-eed21049-4f05-420b-8d01-06b99a18a2da@127.0.1.1:43847
I0707 14:58:14.328253  1804 master.cpp:2273] Processing ACCEPT call for offers: [ 20150707-142913-16777343-5050-1796-O138 ] on slave 20150707-142913-16777343-5050-1796-S0 at slave(1)@127.0.1.1:5051 (AWM14X) for framework 20150707-142913-16777343-5050-1796-0000 (BioBox-Mesos-Framework_7292) at scheduler-eed21049-4f05-420b-8d01-06b99a18a2da@127.0.1.1:43847
I0707 14:58:14.329479  1804 hierarchical.hpp:648] Recovered mem(*):2048; disk(*):83928; ports(*):[31000-32000]; cpus(*):2 (total allocatable: mem(*):2048; disk(*):83928; ports(*):[31000-32000]; cpus(*):2) on slave 20150707-142913-16777343-5050-1796-S0 from framework 20150707-142913-16777343-5050-1796-0000
I0707 14:58:20.332552  1805 master.cpp:3760] Sending 1 offers to framework 20150707-142913-16777343-5050-1796-0000 (BioBox-Mesos-Framework_7292) at scheduler-eed21049-4f05-420b-8d01-06b99a18a2da@127.0.1.1:43847
I0707 14:58:20.338455  1803 master.cpp:2273] Processing ACCEPT call for offers: [ 20150707-142913-16777343-5050-1796-O139 ] on slave 20150707-142913-16777343-5050-1796-S0 at slave(1)@127.0.1.1:5051 (AWM14X) for framework 20150707-142913-16777343-5050-1796-0000 (BioBox-Mesos-Framework_7292) at scheduler-eed21049-4f05-420b-8d01-06b99a18a2da@127.0.1.1:43847
I0707 14:58:20.339706  1800 hierarchical.hpp:648] Recovered mem(*):2048; disk(*):83928; ports(*):[31000-32000]; cpus(*):2 (total allocatable: mem(*):2048; disk(*):83928; ports(*):[31000-32000]; cpus(*):2) on slave 20150707-142913-16777343-5050-1796-S0 from framework 20150707-142913-16777343-5050-1796-0000
I0707 14:58:23.578791  1801 http.cpp:516] HTTP request for '/master/state.json'
I0707 14:58:25.341019  1804 master.cpp:3760] Sending 1 offers to framework 20150707-142913-16777343-5050-1796-0000 (BioBox-Mesos-Framework_7292) at scheduler-eed21049-4f05-420b-8d01-06b99a18a2da@127.0.1.1:43847
I0707 14:58:25.346210  1799 master.cpp:2273] Processing ACCEPT call for offers: [ 20150707-142913-16777343-5050-1796-O140 ] on slave 20150707-142913-16777343-5050-1796-S0 at slave(1)@127.0.1.1:5051 (AWM14X) for framework 20150707-142913-16777343-5050-1796-0000 (BioBox-Mesos-Framework_7292) at scheduler-eed21049-4f05-420b-8d01-06b99a18a2da@127.0.1.1:43847
I0707 14:58:25.350462  1800 hierarchical.hpp:648] Recovered mem(*):2048; disk(*):83928; ports(*):[31000-32000]; cpus(*):2 (total allocatable: mem(*):2048; disk(*):83928; ports(*):[31000-32000]; cpus(*):2) on slave 20150707-142913-16777343-5050-1796-S0 from framework 20150707-142913-16777343-5050-1796-0000
I0707 14:58:31.350425  1804 master.cpp:3760] Sending 1 offers to framework 20150707-142913-16777343-5050-1796-0000 (BioBox-Mesos-Framework_7292) at scheduler-eed21049-4f05-420b-8d01-06b99a18a2da@127.0.1.1:43847
I0707 14:58:31.356783  1800 master.cpp:2273] Processing ACCEPT call for offers: [ 20150707-142913-16777343-5050-1796-O141 ] on slave 20150707-142913-16777343-5050-1796-S0 at slave(1)@127.0.1.1:5051 (AWM14X) for framework 20150707-142913-16777343-5050-1796-0000 (BioBox-Mesos-Framework_7292) at scheduler-eed21049-4f05-420b-8d01-06b99a18a2da@127.0.1.1:43847
I0707 14:58:31.357990  1800 hierarchical.hpp:648] Recovered mem(*):2048; disk(*):83928; ports(*):[31000-32000]; cpus(*):2 (total allocatable: mem(*):2048; disk(*):83928; ports(*):[31000-32000]; cpus(*):2) on slave 20150707-142913-16777343-5050-1796-S0 from framework 20150707-142913-16777343-5050-1796-0000
I0707 14:58:33.599436  1799 http.cpp:516] HTTP request for '/master/state.json'
I0707 14:58:36.360324  1804 master.cpp:3760] Sending 1 offers to framework 20150707-142913-16777343-5050-1796-0000 (BioBox-Mesos-Framework_7292) at scheduler-eed21049-4f05-420b-8d01-06b99a18a2da@127.0.1.1:43847
I0707 14:58:36.366058  1800 master.cpp:2273] Processing ACCEPT call for offers: [ 20150707-142913-16777343-5050-1796-O142 ] on slave 20150707-142913-16777343-5050-1796-S0 at slave(1)@127.0.1.1:5051 (AWM14X) for framework 20150707-142913-16777343-5050-1796-0000 (BioBox-Mesos-Framework_7292) at scheduler-eed21049-4f05-420b-8d01-06b99a18a2da@127.0.1.1:43847
I0707 14:58:36.367667  1800 hierarchical.hpp:648] Recovered mem(*):2048; disk(*):83928; ports(*):[31000-32000]; cpus(*):2 (total allocatable: mem(*):2048; disk(*):83928; ports(*):[31000-32000]; cpus(*):2) on slave 20150707-142913-16777343-5050-1796-S0 from framework 20150707-142913-16777343-5050-1796-0000
I0707 14:58:41.369431  1802 master.cpp:3760] Sending 1 offers to framework 20150707-142913-16777343-5050-1796-0000 (BioBox-Mesos-Framework_7292) at scheduler-eed21049-4f05-420b-8d01-06b99a18a2da@127.0.1.1:43847
I0707 14:58:41.375774  1804 master.cpp:2273] Processing ACCEPT call for offers: [ 20150707-142913-16777343-5050-1796-O143 ] on slave 20150707-142913-16777343-5050-1796-S0 at slave(1)@127.0.1.1:5051 (AWM14X) for framework 20150707-142913-16777343-5050-1796-0000 (BioBox-Mesos-Framework_7292) at scheduler-eed21049-4f05-420b-8d01-06b99a18a2da@127.0.1.1:43847
I0707 14:58:41.377040  1804 hierarchical.hpp:648] Recovered mem(*):2048; disk(*):83928; ports(*):[31000-32000]; cpus(*):2 (total allocatable: mem(*):2048; disk(*):83928; ports(*):[31000-32000]; cpus(*):2) on slave 20150707-142913-16777343-5050-1796-S0 from framework 20150707-142913-16777343-5050-1796-0000
I0707 14:58:43.619351  1798 http.cpp:516] HTTP request for '/master/state.json'
I0707 14:58:47.379163  1801 master.cpp:3760] Sending 1 offers to framework 20150707-142913-16777343-5050-1796-0000 (BioBox-Mesos-Framework_7292) at scheduler-eed21049-4f05-420b-8d01-06b99a18a2da@127.0.1.1:43847
I0707 14:58:47.385615  1804 master.cpp:2273] Processing ACCEPT call for offers: [ 20150707-142913-16777343-5050-1796-O144 ] on slave 20150707-142913-16777343-5050-1796-S0 at slave(1)@127.0.1.1:5051 (AWM14X) for framework 20150707-142913-16777343-5050-1796-0000 (BioBox-Mesos-Framework_7292) at scheduler-eed21049-4f05-420b-8d01-06b99a18a2da@127.0.1.1:43847
I0707 14:58:47.386811  1804 hierarchical.hpp:648] Recovered mem(*):2048; disk(*):83928; ports(*):[31000-32000]; cpus(*):2 (total allocatable: mem(*):2048; disk(*):83928; ports(*):[31000-32000]; cpus(*):2) on slave 20150707-142913-16777343-5050-1796-S0 from framework 20150707-142913-16777343-5050-1796-0000
I0707 14:58:52.388274  1801 master.cpp:3760] Sending 1 offers to framework 20150707-142913-16777343-5050-1796-0000 (BioBox-Mesos-Framework_7292) at scheduler-eed21049-4f05-420b-8d01-06b99a18a2da@127.0.1.1:43847
I0707 14:58:52.394309  1804 master.cpp:2273] Processing ACCEPT call for offers: [ 20150707-142913-16777343-5050-1796-O145 ] on slave 20150707-142913-16777343-5050-1796-S0 at slave(1)@127.0.1.1:5051 (AWM14X) for framework 20150707-142913-16777343-5050-1796-0000 (BioBox-Mesos-Framework_7292) at scheduler-eed21049-4f05-420b-8d01-06b99a18a2da@127.0.1.1:43847
I0707 14:58:52.396037  1802 hierarchical.hpp:648] Recovered mem(*):2048; disk(*):83928; ports(*):[31000-32000]; cpus(*):2 (total allocatable: mem(*):2048; disk(*):83928; ports(*):[31000-32000]; cpus(*):2) on slave 20150707-142913-16777343-5050-1796-S0 from framework 20150707-142913-16777343-5050-1796-0000
I0707 14:58:53.638584  1800 http.cpp:516] HTTP request for '/master/state.json'
I0707 14:58:58.399029  1802 master.cpp:3760] Sending 1 offers to framework 20150707-142913-16777343-5050-1796-0000 (BioBox-Mesos-Framework_7292) at scheduler-eed21049-4f05-420b-8d01-06b99a18a2da@127.0.1.1:43847
I0707 14:58:58.405412  1804 master.cpp:2273] Processing ACCEPT call for offers: [ 20150707-142913-16777343-5050-1796-O146 ] on slave 20150707-142913-16777343-5050-1796-S0 at slave(1)@127.0.1.1:5051 (AWM14X) for framework 20150707-142913-16777343-5050-1796-0000 (BioBox-Mesos-Framework_7292) at scheduler-eed21049-4f05-420b-8d01-06b99a18a2da@127.0.1.1:43847
I0707 14:58:58.407182  1798 hierarchical.hpp:648] Recovered mem(*):2048; disk(*):83928; ports(*):[31000-32000]; cpus(*):2 (total allocatable: mem(*):2048; disk(*):83928; ports(*):[31000-32000]; cpus(*):2) on slave 20150707-142913-16777343-5050-1796-S0 from framework 20150707-142913-16777343-5050-1796-0000
I0707 14:59:03.658524  1798 http.cpp:516] HTTP request for '/master/state.json'
I0707 14:59:04.408578  1803 master.cpp:3760] Sending 1 offers to framework 20150707-142913-16777343-5050-1796-0000 (BioBox-Mesos-Framework_7292) at scheduler-eed21049-4f05-420b-8d01-06b99a18a2da@127.0.1.1:43847
I0707 14:59:04.414755  1804 master.cpp:2273] Processing ACCEPT call for offers: [ 20150707-142913-16777343-5050-1796-O147 ] on slave 20150707-142913-16777343-5050-1796-S0 at slave(1)@127.0.1.1:5051 (AWM14X) for framework 20150707-142913-16777343-5050-1796-0000 (BioBox-Mesos-Framework_7292) at scheduler-eed21049-4f05-420b-8d01-06b99a18a2da@127.0.1.1:43847
I0707 14:59:04.416512  1800 hierarchical.hpp:648] Recovered mem(*):2048; disk(*):83928; ports(*):[31000-32000]; cpus(*):2 (total allocatable: mem(*):2048; disk(*):83928; ports(*):[31000-32000]; cpus(*):2) on slave 20150707-142913-16777343-5050-1796-S0 from framework 20150707-142913-16777343-5050-1796-0000
I0707 14:59:10.419250  1803 master.cpp:3760] Sending 1 offers to framework 20150707-142913-16777343-5050-1796-0000 (BioBox-Mesos-Framework_7292) at scheduler-eed21049-4f05-420b-8d01-06b99a18a2da@127.0.1.1:43847
I0707 14:59:10.429342  1800 master.cpp:2273] Processing ACCEPT call for offers: [ 20150707-142913-16777343-5050-1796-O148 ] on slave 20150707-142913-16777343-5050-1796-S0 at slave(1)@127.0.1.1:5051 (AWM14X) for framework 20150707-142913-16777343-5050-1796-0000 (BioBox-Mesos-Framework_7292) at scheduler-eed21049-4f05-420b-8d01-06b99a18a2da@127.0.1.1:43847
I0707 14:59:10.431463  1804 hierarchical.hpp:648] Recovered mem(*):2048; disk(*):83928; ports(*):[31000-32000]; cpus(*):2 (total allocatable: mem(*):2048; disk(*):83928; ports(*):[31000-32000]; cpus(*):2) on slave 20150707-142913-16777343-5050-1796-S0 from framework 20150707-142913-16777343-5050-1796-0000
I0707 14:59:13.678268  1801 http.cpp:516] HTTP request for '/master/state.json'
I0707 14:59:16.429999  1803 master.cpp:3760] Sending 1 offers to framework 20150707-142913-16777343-5050-1796-0000 (BioBox-Mesos-Framework_7292) at scheduler-eed21049-4f05-420b-8d01-06b99a18a2da@127.0.1.1:43847
I0707 14:59:16.435986  1799 master.cpp:2273] Processing ACCEPT call for offers: [ 20150707-142913-16777343-5050-1796-O149 ] on slave 20150707-142913-16777343-5050-1796-S0 at slave(1)@127.0.1.1:5051 (AWM14X) for framework 20150707-142913-16777343-5050-1796-0000 (BioBox-Mesos-Framework_7292) at scheduler-eed21049-4f05-420b-8d01-06b99a18a2da@127.0.1.1:43847
I0707 14:59:16.437492  1799 hierarchical.hpp:648] Recovered mem(*):2048; disk(*):83928; ports(*):[31000-32000]; cpus(*):2 (total allocatable: mem(*):2048; disk(*):83928; ports(*):[31000-32000]; cpus(*):2) on slave 20150707-142913-16777343-5050-1796-S0 from framework 20150707-142913-16777343-5050-1796-0000
I0707 14:59:21.439133  1803 master.cpp:3760] Sending 1 offers to framework 20150707-142913-16777343-5050-1796-0000 (BioBox-Mesos-Framework_7292) at scheduler-eed21049-4f05-420b-8d01-06b99a18a2da@127.0.1.1:43847
I0707 14:59:21.445261  1799 master.cpp:2273] Processing ACCEPT call for offers: [ 20150707-142913-16777343-5050-1796-O150 ] on slave 20150707-142913-16777343-5050-1796-S0 at slave(1)@127.0.1.1:5051 (AWM14X) for framework 20150707-142913-16777343-5050-1796-0000 (BioBox-Mesos-Framework_7292) at scheduler-eed21049-4f05-420b-8d01-06b99a18a2da@127.0.1.1:43847
I0707 14:59:21.446699  1798 hierarchical.hpp:648] Recovered mem(*):2048; disk(*):83928; ports(*):[31000-32000]; cpus(*):2 (total allocatable: mem(*):2048; disk(*):83928; ports(*):[31000-32000]; cpus(*):2) on slave 20150707-142913-16777343-5050-1796-S0 from framework 20150707-142913-16777343-5050-1796-0000
I0707 14:59:23.700281  1805 http.cpp:516] HTTP request for '/master/state.json'
I0707 14:59:26.448381  1804 master.cpp:3760] Sending 1 offers to framework 20150707-142913-16777343-5050-1796-0000 (BioBox-Mesos-Framework_7292) at scheduler-eed21049-4f05-420b-8d01-06b99a18a2da@127.0.1.1:43847
I0707 14:59:26.454188  1800 master.cpp:2273] Processing ACCEPT call for offers: [ 20150707-142913-16777343-5050-1796-O151 ] on slave 20150707-142913-16777343-5050-1796-S0 at slave(1)@127.0.1.1:5051 (AWM14X) for framework 20150707-142913-16777343-5050-1796-0000 (BioBox-Mesos-Framework_7292) at scheduler-eed21049-4f05-420b-8d01-06b99a18a2da@127.0.1.1:43847
I0707 14:59:26.455986  1803 hierarchical.hpp:648] Recovered mem(*):2048; disk(*):83928; ports(*):[31000-32000]; cpus(*):2 (total allocatable: mem(*):2048; disk(*):83928; ports(*):[31000-32000]; cpus(*):2) on slave 20150707-142913-16777343-5050-1796-S0 from framework 20150707-142913-16777343-5050-1796-0000
I0707 14:59:32.458045  1804 master.cpp:3760] Sending 1 offers to framework 20150707-142913-16777343-5050-1796-0000 (BioBox-Mesos-Framework_7292) at scheduler-eed21049-4f05-420b-8d01-06b99a18a2da@127.0.1.1:43847
I0707 14:59:32.464387  1802 master.cpp:2273] Processing ACCEPT call for offers: [ 20150707-142913-16777343-5050-1796-O152 ] on slave 20150707-142913-16777343-5050-1796-S0 at slave(1)@127.0.1.1:5051 (AWM14X) for framework 20150707-142913-16777343-5050-1796-0000 (BioBox-Mesos-Framework_7292) at scheduler-eed21049-4f05-420b-8d01-06b99a18a2da@127.0.1.1:43847
I0707 14:59:32.465767  1802 hierarchical.hpp:648] Recovered mem(*):2048; disk(*):83928; ports(*):[31000-32000]; cpus(*):2 (total allocatable: mem(*):2048; disk(*):83928; ports(*):[31000-32000]; cpus(*):2) on slave 20150707-142913-16777343-5050-1796-S0 from framework 20150707-142913-16777343-5050-1796-0000
I0707 14:59:33.720469  1800 http.cpp:516] HTTP request for '/master/state.json'
I0707 14:59:38.468443  1805 master.cpp:3760] Sending 1 offers to framework 20150707-142913-16777343-5050-1796-0000 (BioBox-Mesos-Framework_7292) at scheduler-eed21049-4f05-420b-8d01-06b99a18a2da@127.0.1.1:43847
I0707 14:59:38.475242  1801 master.cpp:2273] Processing ACCEPT call for offers: [ 20150707-142913-16777343-5050-1796-O153 ] on slave 20150707-142913-16777343-5050-1796-S0 at slave(1)@127.0.1.1:5051 (AWM14X) for framework 20150707-142913-16777343-5050-1796-0000 (BioBox-Mesos-Framework_7292) at scheduler-eed21049-4f05-420b-8d01-06b99a18a2da@127.0.1.1:43847
I0707 14:59:38.477041  1803 hierarchical.hpp:648] Recovered mem(*):2048; disk(*):83928; ports(*):[31000-32000]; cpus(*):2 (total allocatable: mem(*):2048; disk(*):83928; ports(*):[31000-32000]; cpus(*):2) on slave 20150707-142913-16777343-5050-1796-S0 from framework 20150707-142913-16777343-5050-1796-0000
I0707 14:59:43.739451  1802 http.cpp:516] HTTP request for '/master/state.json'
I0707 14:59:44.478286  1798 master.cpp:3760] Sending 1 offers to framework 20150707-142913-16777343-5050-1796-0000 (BioBox-Mesos-Framework_7292) at scheduler-eed21049-4f05-420b-8d01-06b99a18a2da@127.0.1.1:43847
I0707 14:59:44.484765  1800 master.cpp:2273] Processing ACCEPT call for offers: [ 20150707-142913-16777343-5050-1796-O154 ] on slave 20150707-142913-16777343-5050-1796-S0 at slave(1)@127.0.1.1:5051 (AWM14X) for framework 20150707-142913-16777343-5050-1796-0000 (BioBox-Mesos-Framework_7292) at scheduler-eed21049-4f05-420b-8d01-06b99a18a2da@127.0.1.1:43847
I0707 14:59:44.486060  1800 hierarchical.hpp:648] Recovered mem(*):2048; disk(*):83928; ports(*):[31000-32000]; cpus(*):2 (total allocatable: mem(*):2048; disk(*):83928; ports(*):[31000-32000]; cpus(*):2) on slave 20150707-142913-16777343-5050-1796-S0 from framework 20150707-142913-16777343-5050-1796-0000
I0707 14:59:50.489013  1800 master.cpp:3760] Sending 1 offers to framework 20150707-142913-16777343-5050-1796-0000 (BioBox-Mesos-Framework_7292) at scheduler-eed21049-4f05-420b-8d01-06b99a18a2da@127.0.1.1:43847
I0707 14:59:50.495589  1803 master.cpp:2273] Processing ACCEPT call for offers: [ 20150707-142913-16777343-5050-1796-O155 ] on slave 20150707-142913-16777343-5050-1796-S0 at slave(1)@127.0.1.1:5051 (AWM14X) for framework 20150707-142913-16777343-5050-1796-0000 (BioBox-Mesos-Framework_7292) at scheduler-eed21049-4f05-420b-8d01-06b99a18a2da@127.0.1.1:43847
I0707 14:59:50.497602  1805 hierarchical.hpp:648] Recovered mem(*):2048; disk(*):83928; ports(*):[31000-32000]; cpus(*):2 (total allocatable: mem(*):2048; disk(*):83928; ports(*):[31000-32000]; cpus(*):2) on slave 20150707-142913-16777343-5050-1796-S0 from framework 20150707-142913-16777343-5050-1796-0000
I0707 14:59:53.758893  1804 http.cpp:516] HTTP request for '/master/state.json'
I0707 14:59:56.499460  1798 master.cpp:3760] Sending 1 offers to framework 20150707-142913-16777343-5050-1796-0000 (BioBox-Mesos-Framework_7292) at scheduler-eed21049-4f05-420b-8d01-06b99a18a2da@127.0.1.1:43847
I0707 14:59:56.505839  1799 master.cpp:2273] Processing ACCEPT call for offers: [ 20150707-142913-16777343-5050-1796-O156 ] on slave 20150707-142913-16777343-5050-1796-S0 at slave(1)@127.0.1.1:5051 (AWM14X) for framework 20150707-142913-16777343-5050-1796-0000 (BioBox-Mesos-Framework_7292) at scheduler-eed21049-4f05-420b-8d01-06b99a18a2da@127.0.1.1:43847
I0707 14:59:56.507120  1799 hierarchical.hpp:648] Recovered mem(*):2048; disk(*):83928; ports(*):[31000-32000]; cpus(*):2 (total allocatable: mem(*):2048; disk(*):83928; ports(*):[31000-32000]; cpus(*):2) on slave 20150707-142913-16777343-5050-1796-S0 from framework 20150707-142913-16777343-5050-1796-0000
I0707 15:00:02.509754  1798 master.cpp:3760] Sending 1 offers to framework 20150707-142913-16777343-5050-1796-0000 (BioBox-Mesos-Framework_7292) at scheduler-eed21049-4f05-420b-8d01-06b99a18a2da@127.0.1.1:43847
I0707 15:00:02.516044  1804 master.cpp:2273] Processing ACCEPT call for offers: [ 20150707-142913-16777343-5050-1796-O157 ] on slave 20150707-142913-16777343-5050-1796-S0 at slave(1)@127.0.1.1:5051 (AWM14X) for framework 20150707-142913-16777343-5050-1796-0000 (BioBox-Mesos-Framework_7292) at scheduler-eed21049-4f05-420b-8d01-06b99a18a2da@127.0.1.1:43847
I0707 15:00:02.517318  1804 hierarchical.hpp:648] Recovered mem(*):2048; disk(*):83928; ports(*):[31000-32000]; cpus(*):2 (total allocatable: mem(*):2048; disk(*):83928; ports(*):[31000-32000]; cpus(*):2) on slave 20150707-142913-16777343-5050-1796-S0 from framework 20150707-142913-16777343-5050-1796-0000
I0707 15:00:03.777778  1802 http.cpp:516] HTTP request for '/master/state.json'
I0707 15:00:07.519294  1800 master.cpp:3760] Sending 1 offers to framework 20150707-142913-16777343-5050-1796-0000 (BioBox-Mesos-Framework_7292) at scheduler-eed21049-4f05-420b-8d01-06b99a18a2da@127.0.1.1:43847
I0707 15:00:07.525154  1805 master.cpp:2273] Processing ACCEPT call for offers: [ 20150707-142913-16777343-5050-1796-O158 ] on slave 20150707-142913-16777343-5050-1796-S0 at slave(1)@127.0.1.1:5051 (AWM14X) for framework 20150707-142913-16777343-5050-1796-0000 (BioBox-Mesos-Framework_7292) at scheduler-eed21049-4f05-420b-8d01-06b99a18a2da@127.0.1.1:43847
I0707 15:00:07.526165  1805 hierarchical.hpp:648] Recovered mem(*):2048; disk(*):83928; ports(*):[31000-32000]; cpus(*):2 (total allocatable: mem(*):2048; disk(*):83928; ports(*):[31000-32000]; cpus(*):2) on slave 20150707-142913-16777343-5050-1796-S0 from framework 20150707-142913-16777343-5050-1796-0000
I0707 15:00:12.528501  1803 master.cpp:3760] Sending 1 offers to framework 20150707-142913-16777343-5050-1796-0000 (BioBox-Mesos-Framework_7292) at scheduler-eed21049-4f05-420b-8d01-06b99a18a2da@127.0.1.1:43847
I0707 15:00:12.534948  1804 master.cpp:2273] Processing ACCEPT call for offers: [ 20150707-142913-16777343-5050-1796-O159 ] on slave 20150707-142913-16777343-5050-1796-S0 at slave(1)@127.0.1.1:5051 (AWM14X) for framework 20150707-142913-16777343-5050-1796-0000 (BioBox-Mesos-Framework_7292) at scheduler-eed21049-4f05-420b-8d01-06b99a18a2da@127.0.1.1:43847
I0707 15:00:12.536309  1804 hierarchical.hpp:648] Recovered mem(*):2048; disk(*):83928; ports(*):[31000-32000]; cpus(*):2 (total allocatable: mem(*):2048; disk(*):83928; ports(*):[31000-32000]; cpus(*):2) on slave 20150707-142913-16777343-5050-1796-S0 from framework 20150707-142913-16777343-5050-1796-0000
I0707 15:00:13.795970  1805 http.cpp:516] HTTP request for '/master/state.json'
I0707 15:00:18.538719  1804 master.cpp:3760] Sending 1 offers to framework 20150707-142913-16777343-5050-1796-0000 (BioBox-Mesos-Framework_7292) at scheduler-eed21049-4f05-420b-8d01-06b99a18a2da@127.0.1.1:43847
I0707 15:00:18.545339  1799 master.cpp:2273] Processing ACCEPT call for offers: [ 20150707-142913-16777343-5050-1796-O160 ] on slave 20150707-142913-16777343-5050-1796-S0 at slave(1)@127.0.1.1:5051 (AWM14X) for framework 20150707-142913-16777343-5050-1796-0000 (BioBox-Mesos-Framework_7292) at scheduler-eed21049-4f05-420b-8d01-06b99a18a2da@127.0.1.1:43847
I0707 15:00:18.547407  1805 hierarchical.hpp:648] Recovered mem(*):2048; disk(*):83928; ports(*):[31000-32000]; cpus(*):2 (total allocatable: mem(*):2048; disk(*):83928; ports(*):[31000-32000]; cpus(*):2) on slave 20150707-142913-16777343-5050-1796-S0 from framework 20150707-142913-16777343-5050-1796-0000
I0707 15:00:23.814960  1803 http.cpp:516] HTTP request for '/master/state.json'
I0707 15:00:24.549975  1799 master.cpp:3760] Sending 1 offers to framework 20150707-142913-16777343-5050-1796-0000 (BioBox-Mesos-Framework_7292) at scheduler-eed21049-4f05-420b-8d01-06b99a18a2da@127.0.1.1:43847
I0707 15:00:24.556293  1802 master.cpp:2273] Processing ACCEPT call for offers: [ 20150707-142913-16777343-5050-1796-O161 ] on slave 20150707-142913-16777343-5050-1796-S0 at slave(1)@127.0.1.1:5051 (AWM14X) for framework 20150707-142913-16777343-5050-1796-0000 (BioBox-Mesos-Framework_7292) at scheduler-eed21049-4f05-420b-8d01-06b99a18a2da@127.0.1.1:43847
I0707 15:00:24.557589  1802 hierarchical.hpp:648] Recovered mem(*):2048; disk(*):83928; ports(*):[31000-32000]; cpus(*):2 (total allocatable: mem(*):2048; disk(*):83928; ports(*):[31000-32000]; cpus(*):2) on slave 20150707-142913-16777343-5050-1796-S0 from framework 20150707-142913-16777343-5050-1796-0000
I0707 15:00:30.560227  1802 master.cpp:3760] Sending 1 offers to framework 20150707-142913-16777343-5050-1796-0000 (BioBox-Mesos-Framework_7292) at scheduler-eed21049-4f05-420b-8d01-06b99a18a2da@127.0.1.1:43847
I0707 15:00:30.566511  1801 master.cpp:2273] Processing ACCEPT call for offers: [ 20150707-142913-16777343-5050-1796-O162 ] on slave 20150707-142913-16777343-5050-1796-S0 at slave(1)@127.0.1.1:5051 (AWM14X) for framework 20150707-142913-16777343-5050-1796-0000 (BioBox-Mesos-Framework_7292) at scheduler-eed21049-4f05-420b-8d01-06b99a18a2da@127.0.1.1:43847
I0707 15:00:30.567694  1801 hierarchical.hpp:648] Recovered mem(*):2048; disk(*):83928; ports(*):[31000-32000]; cpus(*):2 (total allocatable: mem(*):2048; disk(*):83928; ports(*):[31000-32000]; cpus(*):2) on slave 20150707-142913-16777343-5050-1796-S0 from framework 20150707-142913-16777343-5050-1796-0000
I0707 15:00:33.834297  1804 http.cpp:516] HTTP request for '/master/state.json'
I0707 15:00:36.570740  1801 master.cpp:3760] Sending 1 offers to framework 20150707-142913-16777343-5050-1796-0000 (BioBox-Mesos-Framework_7292) at scheduler-eed21049-4f05-420b-8d01-06b99a18a2da@127.0.1.1:43847
I0707 15:00:36.577118  1803 master.cpp:2273] Processing ACCEPT call for offers: [ 20150707-142913-16777343-5050-1796-O163 ] on slave 20150707-142913-16777343-5050-1796-S0 at slave(1)@127.0.1.1:5051 (AWM14X) for framework 20150707-142913-16777343-5050-1796-0000 (BioBox-Mesos-Framework_7292) at scheduler-eed21049-4f05-420b-8d01-06b99a18a2da@127.0.1.1:43847
I0707 15:00:36.578312  1803 hierarchical.hpp:648] Recovered mem(*):2048; disk(*):83928; ports(*):[31000-32000]; cpus(*):2 (total allocatable: mem(*):2048; disk(*):83928; ports(*):[31000-32000]; cpus(*):2) on slave 20150707-142913-16777343-5050-1796-S0 from framework 20150707-142913-16777343-5050-1796-0000
I0707 15:00:42.580868  1801 master.cpp:3760] Sending 1 offers to framework 20150707-142913-16777343-5050-1796-0000 (BioBox-Mesos-Framework_7292) at scheduler-eed21049-4f05-420b-8d01-06b99a18a2da@127.0.1.1:43847
I0707 15:00:42.587131  1803 master.cpp:2273] Processing ACCEPT call for offers: [ 20150707-142913-16777343-5050-1796-O164 ] on slave 20150707-142913-16777343-5050-1796-S0 at slave(1)@127.0.1.1:5051 (AWM14X) for framework 20150707-142913-16777343-5050-1796-0000 (BioBox-Mesos-Framework_7292) at scheduler-eed21049-4f05-420b-8d01-06b99a18a2da@127.0.1.1:43847
I0707 15:00:42.588620  1803 hierarchical.hpp:648] Recovered mem(*):2048; disk(*):83928; ports(*):[31000-32000]; cpus(*):2 (total allocatable: mem(*):2048; disk(*):83928; ports(*):[31000-32000]; cpus(*):2) on slave 20150707-142913-16777343-5050-1796-S0 from framework 20150707-142913-16777343-5050-1796-0000
I0707 15:00:43.853329  1800 http.cpp:516] HTTP request for '/master/state.json'
I0707 15:00:48.590538  1803 master.cpp:3760] Sending 1 offers to framework 20150707-142913-16777343-5050-1796-0000 (BioBox-Mesos-Framework_7292) at scheduler-eed21049-4f05-420b-8d01-06b99a18a2da@127.0.1.1:43847
I0707 15:00:48.596710  1801 master.cpp:2273] Processing ACCEPT call for offers: [ 20150707-142913-16777343-5050-1796-O165 ] on slave 20150707-142913-16777343-5050-1796-S0 at slave(1)@127.0.1.1:5051 (AWM14X) for framework 20150707-142913-16777343-5050-1796-0000 (BioBox-Mesos-Framework_7292) at scheduler-eed21049-4f05-420b-8d01-06b99a18a2da@127.0.1.1:43847
I0707 15:00:48.598119  1801 hierarchical.hpp:648] Recovered mem(*):2048; disk(*):83928; ports(*):[31000-32000]; cpus(*):2 (total allocatable: mem(*):2048; disk(*):83928; ports(*):[31000-32000]; cpus(*):2) on slave 20150707-142913-16777343-5050-1796-S0 from framework 20150707-142913-16777343-5050-1796-0000
I0707 15:00:53.599582  1805 master.cpp:3760] Sending 1 offers to framework 20150707-142913-16777343-5050-1796-0000 (BioBox-Mesos-Framework_7292) at scheduler-eed21049-4f05-420b-8d01-06b99a18a2da@127.0.1.1:43847
I0707 15:00:53.605659  1803 master.cpp:2273] Processing ACCEPT call for offers: [ 20150707-142913-16777343-5050-1796-O166 ] on slave 20150707-142913-16777343-5050-1796-S0 at slave(1)@127.0.1.1:5051 (AWM14X) for framework 20150707-142913-16777343-5050-1796-0000 (BioBox-Mesos-Framework_7292) at scheduler-eed21049-4f05-420b-8d01-06b99a18a2da@127.0.1.1:43847
I0707 15:00:53.606977  1803 hierarchical.hpp:648] Recovered mem(*):2048; disk(*):83928; ports(*):[31000-32000]; cpus(*):2 (total allocatable: mem(*):2048; disk(*):83928; ports(*):[31000-32000]; cpus(*):2) on slave 20150707-142913-16777343-5050-1796-S0 from framework 20150707-142913-16777343-5050-1796-0000
I0707 15:00:53.871314  1801 http.cpp:516] HTTP request for '/master/state.json'
I0707 15:00:59.609870  1800 master.cpp:3760] Sending 1 offers to framework 20150707-142913-16777343-5050-1796-0000 (BioBox-Mesos-Framework_7292) at scheduler-eed21049-4f05-420b-8d01-06b99a18a2da@127.0.1.1:43847
I0707 15:00:59.615983  1803 master.cpp:2273] Processing ACCEPT call for offers: [ 20150707-142913-16777343-5050-1796-O167 ] on slave 20150707-142913-16777343-5050-1796-S0 at slave(1)@127.0.1.1:5051 (AWM14X) for framework 20150707-142913-16777343-5050-1796-0000 (BioBox-Mesos-Framework_7292) at scheduler-eed21049-4f05-420b-8d01-06b99a18a2da@127.0.1.1:43847
I0707 15:00:59.617421  1803 hierarchical.hpp:648] Recovered mem(*):2048; disk(*):83928; ports(*):[31000-32000]; cpus(*):2 (total allocatable: mem(*):2048; disk(*):83928; ports(*):[31000-32000]; cpus(*):2) on slave 20150707-142913-16777343-5050-1796-S0 from framework 20150707-142913-16777343-5050-1796-0000
I0707 15:01:03.890493  1799 http.cpp:516] HTTP request for '/master/state.json'
I0707 15:01:04.620662  1798 master.cpp:3760] Sending 1 offers to framework 20150707-142913-16777343-5050-1796-0000 (BioBox-Mesos-Framework_7292) at scheduler-eed21049-4f05-420b-8d01-06b99a18a2da@127.0.1.1:43847
I0707 15:01:04.627069  1802 master.cpp:2273] Processing ACCEPT call for offers: [ 20150707-142913-16777343-5050-1796-O168 ] on slave 20150707-142913-16777343-5050-1796-S0 at slave(1)@127.0.1.1:5051 (AWM14X) for framework 20150707-142913-16777343-5050-1796-0000 (BioBox-Mesos-Framework_7292) at scheduler-eed21049-4f05-420b-8d01-06b99a18a2da@127.0.1.1:43847
I0707 15:01:04.628579  1803 hierarchical.hpp:648] Recovered mem(*):2048; disk(*):83928; ports(*):[31000-32000]; cpus(*):2 (total allocatable: mem(*):2048; disk(*):83928; ports(*):[31000-32000]; cpus(*):2) on slave 20150707-142913-16777343-5050-1796-S0 from framework 20150707-142913-16777343-5050-1796-0000
I0707 15:01:10.630416  1798 master.cpp:3760] Sending 1 offers to framework 20150707-142913-16777343-5050-1796-0000 (BioBox-Mesos-Framework_7292) at scheduler-eed21049-4f05-420b-8d01-06b99a18a2da@127.0.1.1:43847
I0707 15:01:10.636622  1799 master.cpp:2273] Processing ACCEPT call for offers: [ 20150707-142913-16777343-5050-1796-O169 ] on slave 20150707-142913-16777343-5050-1796-S0 at slave(1)@127.0.1.1:5051 (AWM14X) for framework 20150707-142913-16777343-5050-1796-0000 (BioBox-Mesos-Framework_7292) at scheduler-eed21049-4f05-420b-8d01-06b99a18a2da@127.0.1.1:43847
I0707 15:01:10.638094  1799 hierarchical.hpp:648] Recovered mem(*):2048; disk(*):83928; ports(*):[31000-32000]; cpus(*):2 (total allocatable: mem(*):2048; disk(*):83928; ports(*):[31000-32000]; cpus(*):2) on slave 20150707-142913-16777343-5050-1796-S0 from framework 20150707-142913-16777343-5050-1796-0000
I0707 15:01:13.910125  1800 http.cpp:516] HTTP request for '/master/state.json'
I0707 15:01:15.639946  1798 master.cpp:3760] Sending 1 offers to framework 20150707-142913-16777343-5050-1796-0000 (BioBox-Mesos-Framework_7292) at scheduler-eed21049-4f05-420b-8d01-06b99a18a2da@127.0.1.1:43847
I0707 15:01:15.646412  1799 master.cpp:2273] Processing ACCEPT call for offers: [ 20150707-142913-16777343-5050-1796-O170 ] on slave 20150707-142913-16777343-5050-1796-S0 at slave(1)@127.0.1.1:5051 (AWM14X) for framework 20150707-142913-16777343-5050-1796-0000 (BioBox-Mesos-Framework_7292) at scheduler-eed21049-4f05-420b-8d01-06b99a18a2da@127.0.1.1:43847
I0707 15:01:15.648079  1799 hierarchical.hpp:648] Recovered mem(*):2048; disk(*):83928; ports(*):[31000-32000]; cpus(*):2 (total allocatable: mem(*):2048; disk(*):83928; ports(*):[31000-32000]; cpus(*):2) on slave 20150707-142913-16777343-5050-1796-S0 from framework 20150707-142913-16777343-5050-1796-0000
I0707 15:01:21.649703  1798 master.cpp:3760] Sending 1 offers to framework 20150707-142913-16777343-5050-1796-0000 (BioBox-Mesos-Framework_7292) at scheduler-eed21049-4f05-420b-8d01-06b99a18a2da@127.0.1.1:43847
I0707 15:01:21.656440  1801 master.cpp:2273] Processing ACCEPT call for offers: [ 20150707-142913-16777343-5050-1796-O171 ] on slave 20150707-142913-16777343-5050-1796-S0 at slave(1)@127.0.1.1:5051 (AWM14X) for framework 20150707-142913-16777343-5050-1796-0000 (BioBox-Mesos-Framework_7292) at scheduler-eed21049-4f05-420b-8d01-06b99a18a2da@127.0.1.1:43847
I0707 15:01:21.658459  1802 hierarchical.hpp:648] Recovered mem(*):2048; disk(*):83928; ports(*):[31000-32000]; cpus(*):2 (total allocatable: mem(*):2048; disk(*):83928; ports(*):[31000-32000]; cpus(*):2) on slave 20150707-142913-16777343-5050-1796-S0 from framework 20150707-142913-16777343-5050-1796-0000
I0707 15:01:23.928642  1799 http.cpp:516] HTTP request for '/master/state.json'
I0707 15:01:27.660575  1800 master.cpp:3760] Sending 1 offers to framework 20150707-142913-16777343-5050-1796-0000 (BioBox-Mesos-Framework_7292) at scheduler-eed21049-4f05-420b-8d01-06b99a18a2da@127.0.1.1:43847
I0707 15:01:27.666857  1801 master.cpp:2273] Processing ACCEPT call for offers: [ 20150707-142913-16777343-5050-1796-O172 ] on slave 20150707-142913-16777343-5050-1796-S0 at slave(1)@127.0.1.1:5051 (AWM14X) for framework 20150707-142913-16777343-5050-1796-0000 (BioBox-Mesos-Framework_7292) at scheduler-eed21049-4f05-420b-8d01-06b99a18a2da@127.0.1.1:43847
I0707 15:01:27.668511  1805 hierarchical.hpp:648] Recovered mem(*):2048; disk(*):83928; ports(*):[31000-32000]; cpus(*):2 (total allocatable: mem(*):2048; disk(*):83928; ports(*):[31000-32000]; cpus(*):2) on slave 20150707-142913-16777343-5050-1796-S0 from framework 20150707-142913-16777343-5050-1796-0000
I0707 15:01:33.670230  1805 master.cpp:3760] Sending 1 offers to framework 20150707-142913-16777343-5050-1796-0000 (BioBox-Mesos-Framework_7292) at scheduler-eed21049-4f05-420b-8d01-06b99a18a2da@127.0.1.1:43847
I0707 15:01:33.676611  1800 master.cpp:2273] Processing ACCEPT call for offers: [ 20150707-142913-16777343-5050-1796-O173 ] on slave 20150707-142913-16777343-5050-1796-S0 at slave(1)@127.0.1.1:5051 (AWM14X) for framework 20150707-142913-16777343-5050-1796-0000 (BioBox-Mesos-Framework_7292) at scheduler-eed21049-4f05-420b-8d01-06b99a18a2da@127.0.1.1:43847
I0707 15:01:33.678048  1800 hierarchical.hpp:648] Recovered mem(*):2048; disk(*):83928; ports(*):[31000-32000]; cpus(*):2 (total allocatable: mem(*):2048; disk(*):83928; ports(*):[31000-32000]; cpus(*):2) on slave 20150707-142913-16777343-5050-1796-S0 from framework 20150707-142913-16777343-5050-1796-0000
I0707 15:01:33.947937  1802 http.cpp:516] HTTP request for '/master/state.json'
I0707 15:01:39.680413  1798 master.cpp:3760] Sending 1 offers to framework 20150707-142913-16777343-5050-1796-0000 (BioBox-Mesos-Framework_7292) at scheduler-eed21049-4f05-420b-8d01-06b99a18a2da@127.0.1.1:43847
I0707 15:01:39.687038  1801 master.cpp:2273] Processing ACCEPT call for offers: [ 20150707-142913-16777343-5050-1796-O174 ] on slave 20150707-142913-16777343-5050-1796-S0 at slave(1)@127.0.1.1:5051 (AWM14X) for framework 20150707-142913-16777343-5050-1796-0000 (BioBox-Mesos-Framework_7292) at scheduler-eed21049-4f05-420b-8d01-06b99a18a2da@127.0.1.1:43847
I0707 15:01:39.688446  1801 hierarchical.hpp:648] Recovered mem(*):2048; disk(*):83928; ports(*):[31000-32000]; cpus(*):2 (total allocatable: mem(*):2048; disk(*):83928; ports(*):[31000-32000]; cpus(*):2) on slave 20150707-142913-16777343-5050-1796-S0 from framework 20150707-142913-16777343-5050-1796-0000
I0707 15:01:43.967598  1799 http.cpp:516] HTTP request for '/master/state.json'
I0707 15:01:45.690448  1801 master.cpp:3760] Sending 1 offers to framework 20150707-142913-16777343-5050-1796-0000 (BioBox-Mesos-Framework_7292) at scheduler-eed21049-4f05-420b-8d01-06b99a18a2da@127.0.1.1:43847
I0707 15:01:45.697229  1802 master.cpp:2273] Processing ACCEPT call for offers: [ 20150707-142913-16777343-5050-1796-O175 ] on slave 20150707-142913-16777343-5050-1796-S0 at slave(1)@127.0.1.1:5051 (AWM14X) for framework 20150707-142913-16777343-5050-1796-0000 (BioBox-Mesos-Framework_7292) at scheduler-eed21049-4f05-420b-8d01-06b99a18a2da@127.0.1.1:43847
I0707 15:01:45.699167  1805 hierarchical.hpp:648] Recovered mem(*):2048; disk(*):83928; ports(*):[31000-32000]; cpus(*):2 (total allocatable: mem(*):2048; disk(*):83928; ports(*):[31000-32000]; cpus(*):2) on slave 20150707-142913-16777343-5050-1796-S0 from framework 20150707-142913-16777343-5050-1796-0000
I0707 15:01:51.702121  1805 master.cpp:3760] Sending 1 offers to framework 20150707-142913-16777343-5050-1796-0000 (BioBox-Mesos-Framework_7292) at scheduler-eed21049-4f05-420b-8d01-06b99a18a2da@127.0.1.1:43847
I0707 15:01:51.708511  1802 master.cpp:2273] Processing ACCEPT call for offers: [ 20150707-142913-16777343-5050-1796-O176 ] on slave 20150707-142913-16777343-5050-1796-S0 at slave(1)@127.0.1.1:5051 (AWM14X) for framework 20150707-142913-16777343-5050-1796-0000 (BioBox-Mesos-Framework_7292) at scheduler-eed21049-4f05-420b-8d01-06b99a18a2da@127.0.1.1:43847
I0707 15:01:51.709756  1802 hierarchical.hpp:648] Recovered mem(*):2048; disk(*):83928; ports(*):[31000-32000]; cpus(*):2 (total allocatable: mem(*):2048; disk(*):83928; ports(*):[31000-32000]; cpus(*):2) on slave 20150707-142913-16777343-5050-1796-S0 from framework 20150707-142913-16777343-5050-1796-0000
I0707 15:01:53.987845  1801 http.cpp:516] HTTP request for '/master/state.json'
I0707 15:01:57.712158  1804 master.cpp:3760] Sending 1 offers to framework 20150707-142913-16777343-5050-1796-0000 (BioBox-Mesos-Framework_7292) at scheduler-eed21049-4f05-420b-8d01-06b99a18a2da@127.0.1.1:43847
I0707 15:01:57.718376  1803 master.cpp:2273] Processing ACCEPT call for offers: [ 20150707-142913-16777343-5050-1796-O177 ] on slave 20150707-142913-16777343-5050-1796-S0 at slave(1)@127.0.1.1:5051 (AWM14X) for framework 20150707-142913-16777343-5050-1796-0000 (BioBox-Mesos-Framework_7292) at scheduler-eed21049-4f05-420b-8d01-06b99a18a2da@127.0.1.1:43847
I0707 15:01:57.719635  1803 hierarchical.hpp:648] Recovered mem(*):2048; disk(*):83928; ports(*):[31000-32000]; cpus(*):2 (total allocatable: mem(*):2048; disk(*):83928; ports(*):[31000-32000]; cpus(*):2) on slave 20150707-142913-16777343-5050-1796-S0 from framework 20150707-142913-16777343-5050-1796-0000
I0707 15:02:03.722254  1803 master.cpp:3760] Sending 1 offers to framework 20150707-142913-16777343-5050-1796-0000 (BioBox-Mesos-Framework_7292) at scheduler-eed21049-4f05-420b-8d01-06b99a18a2da@127.0.1.1:43847
I0707 15:02:03.728584  1798 master.cpp:2273] Processing ACCEPT call for offers: [ 20150707-142913-16777343-5050-1796-O178 ] on slave 20150707-142913-16777343-5050-1796-S0 at slave(1)@127.0.1.1:5051 (AWM14X) for framework 20150707-142913-16777343-5050-1796-0000 (BioBox-Mesos-Framework_7292) at scheduler-eed21049-4f05-420b-8d01-06b99a18a2da@127.0.1.1:43847
I0707 15:02:03.729933  1800 hierarchical.hpp:648] Recovered mem(*):2048; disk(*):83928; ports(*):[31000-32000]; cpus(*):2 (total allocatable: mem(*):2048; disk(*):83928; ports(*):[31000-32000]; cpus(*):2) on slave 20150707-142913-16777343-5050-1796-S0 from framework 20150707-142913-16777343-5050-1796-0000
I0707 15:02:04.008352  1798 http.cpp:516] HTTP request for '/master/state.json'
I0707 15:02:09.731328  1803 master.cpp:3760] Sending 1 offers to framework 20150707-142913-16777343-5050-1796-0000 (BioBox-Mesos-Framework_7292) at scheduler-eed21049-4f05-420b-8d01-06b99a18a2da@127.0.1.1:43847
I0707 15:02:09.736420  1800 master.cpp:2273] Processing ACCEPT call for offers: [ 20150707-142913-16777343-5050-1796-O179 ] on slave 20150707-142913-16777343-5050-1796-S0 at slave(1)@127.0.1.1:5051 (AWM14X) for framework 20150707-142913-16777343-5050-1796-0000 (BioBox-Mesos-Framework_7292) at scheduler-eed21049-4f05-420b-8d01-06b99a18a2da@127.0.1.1:43847
I0707 15:02:09.737488  1801 hierarchical.hpp:648] Recovered mem(*):2048; disk(*):83928; ports(*):[31000-32000]; cpus(*):2 (total allocatable: mem(*):2048; disk(*):83928; ports(*):[31000-32000]; cpus(*):2) on slave 20150707-142913-16777343-5050-1796-S0 from framework 20150707-142913-16777343-5050-1796-0000
I0707 15:02:14.074108  1802 http.cpp:516] HTTP request for '/master/state.json'
I0707 15:02:15.739738  1802 master.cpp:3760] Sending 1 offers to framework 20150707-142913-16777343-5050-1796-0000 (BioBox-Mesos-Framework_7292) at scheduler-eed21049-4f05-420b-8d01-06b99a18a2da@127.0.1.1:43847
I0707 15:02:15.743785  1800 master.cpp:2273] Processing ACCEPT call for offers: [ 20150707-142913-16777343-5050-1796-O180 ] on slave 20150707-142913-16777343-5050-1796-S0 at slave(1)@127.0.1.1:5051 (AWM14X) for framework 20150707-142913-16777343-5050-1796-0000 (BioBox-Mesos-Framework_7292) at scheduler-eed21049-4f05-420b-8d01-06b99a18a2da@127.0.1.1:43847
I0707 15:02:15.744467  1799 hierarchical.hpp:648] Recovered mem(*):2048; disk(*):83928; ports(*):[31000-32000]; cpus(*):2 (total allocatable: mem(*):2048; disk(*):83928; ports(*):[31000-32000]; cpus(*):2) on slave 20150707-142913-16777343-5050-1796-S0 from framework 20150707-142913-16777343-5050-1796-0000
I0707 15:02:20.747879  1802 master.cpp:3760] Sending 1 offers to framework 20150707-142913-16777343-5050-1796-0000 (BioBox-Mesos-Framework_7292) at scheduler-eed21049-4f05-420b-8d01-06b99a18a2da@127.0.1.1:43847
I0707 15:02:20.754041  1799 master.cpp:2273] Processing ACCEPT call for offers: [ 20150707-142913-16777343-5050-1796-O181 ] on slave 20150707-142913-16777343-5050-1796-S0 at slave(1)@127.0.1.1:5051 (AWM14X) for framework 20150707-142913-16777343-5050-1796-0000 (BioBox-Mesos-Framework_7292) at scheduler-eed21049-4f05-420b-8d01-06b99a18a2da@127.0.1.1:43847
I0707 15:02:20.755492  1799 hierarchical.hpp:648] Recovered mem(*):2048; disk(*):83928; ports(*):[31000-32000]; cpus(*):2 (total allocatable: mem(*):2048; disk(*):83928; ports(*):[31000-32000]; cpus(*):2) on slave 20150707-142913-16777343-5050-1796-S0 from framework 20150707-142913-16777343-5050-1796-0000
I0707 15:02:25.078975  1803 http.cpp:516] HTTP request for '/master/state.json'
I0707 15:02:25.757771  1803 master.cpp:3760] Sending 1 offers to framework 20150707-142913-16777343-5050-1796-0000 (BioBox-Mesos-Framework_7292) at scheduler-eed21049-4f05-420b-8d01-06b99a18a2da@127.0.1.1:43847
I0707 15:02:25.764206  1802 master.cpp:2273] Processing ACCEPT call for offers: [ 20150707-142913-16777343-5050-1796-O182 ] on slave 20150707-142913-16777343-5050-1796-S0 at slave(1)@127.0.1.1:5051 (AWM14X) for framework 20150707-142913-16777343-5050-1796-0000 (BioBox-Mesos-Framework_7292) at scheduler-eed21049-4f05-420b-8d01-06b99a18a2da@127.0.1.1:43847
I0707 15:02:25.765697  1800 hierarchical.hpp:648] Recovered mem(*):2048; disk(*):83928; ports(*):[31000-32000]; cpus(*):2 (total allocatable: mem(*):2048; disk(*):83928; ports(*):[31000-32000]; cpus(*):2) on slave 20150707-142913-16777343-5050-1796-S0 from framework 20150707-142913-16777343-5050-1796-0000
I0707 15:02:31.767948  1803 master.cpp:3760] Sending 1 offers to framework 20150707-142913-16777343-5050-1796-0000 (BioBox-Mesos-Framework_7292) at scheduler-eed21049-4f05-420b-8d01-06b99a18a2da@127.0.1.1:43847
I0707 15:02:31.774262  1800 master.cpp:2273] Processing ACCEPT call for offers: [ 20150707-142913-16777343-5050-1796-O183 ] on slave 20150707-142913-16777343-5050-1796-S0 at slave(1)@127.0.1.1:5051 (AWM14X) for framework 20150707-142913-16777343-5050-1796-0000 (BioBox-Mesos-Framework_7292) at scheduler-eed21049-4f05-420b-8d01-06b99a18a2da@127.0.1.1:43847
I0707 15:02:31.775563  1800 hierarchical.hpp:648] Recovered mem(*):2048; disk(*):83928; ports(*):[31000-32000]; cpus(*):2 (total allocatable: mem(*):2048; disk(*):83928; ports(*):[31000-32000]; cpus(*):2) on slave 20150707-142913-16777343-5050-1796-S0 from framework 20150707-142913-16777343-5050-1796-0000
I0707 15:02:36.078835  1801 http.cpp:516] HTTP request for '/master/state.json'
I0707 15:02:36.777221  1798 master.cpp:3760] Sending 1 offers to framework 20150707-142913-16777343-5050-1796-0000 (BioBox-Mesos-Framework_7292) at scheduler-eed21049-4f05-420b-8d01-06b99a18a2da@127.0.1.1:43847
I0707 15:02:36.783622  1805 master.cpp:2273] Processing ACCEPT call for offers: [ 20150707-142913-16777343-5050-1796-O184 ] on slave 20150707-142913-16777343-5050-1796-S0 at slave(1)@127.0.1.1:5051 (AWM14X) for framework 20150707-142913-16777343-5050-1796-0000 (BioBox-Mesos-Framework_7292) at scheduler-eed21049-4f05-420b-8d01-06b99a18a2da@127.0.1.1:43847
I0707 15:02:36.784854  1804 hierarchical.hpp:648] Recovered mem(*):2048; disk(*):83928; ports(*):[31000-32000]; cpus(*):2 (total allocatable: mem(*):2048; disk(*):83928; ports(*):[31000-32000]; cpus(*):2) on slave 20150707-142913-16777343-5050-1796-S0 from framework 20150707-142913-16777343-5050-1796-0000
I0707 15:02:42.786844  1798 master.cpp:3760] Sending 1 offers to framework 20150707-142913-16777343-5050-1796-0000 (BioBox-Mesos-Framework_7292) at scheduler-eed21049-4f05-420b-8d01-06b99a18a2da@127.0.1.1:43847
I0707 15:02:42.793126  1804 master.cpp:2273] Processing ACCEPT call for offers: [ 20150707-142913-16777343-5050-1796-O185 ] on slave 20150707-142913-16777343-5050-1796-S0 at slave(1)@127.0.1.1:5051 (AWM14X) for framework 20150707-142913-16777343-5050-1796-0000 (BioBox-Mesos-Framework_7292) at scheduler-eed21049-4f05-420b-8d01-06b99a18a2da@127.0.1.1:43847
I0707 15:02:42.796517  1804 hierarchical.hpp:648] Recovered mem(*):2048; disk(*):83928; ports(*):[31000-32000]; cpus(*):2 (total allocatable: mem(*):2048; disk(*):83928; ports(*):[31000-32000]; cpus(*):2) on slave 20150707-142913-16777343-5050-1796-S0 from framework 20150707-142913-16777343-5050-1796-0000
I0707 15:02:47.078153  1801 http.cpp:516] HTTP request for '/master/state.json'
I0707 15:02:48.796481  1802 master.cpp:3760] Sending 1 offers to framework 20150707-142913-16777343-5050-1796-0000 (BioBox-Mesos-Framework_7292) at scheduler-eed21049-4f05-420b-8d01-06b99a18a2da@127.0.1.1:43847
I0707 15:02:48.802547  1804 master.cpp:2273] Processing ACCEPT call for offers: [ 20150707-142913-16777343-5050-1796-O186 ] on slave 20150707-142913-16777343-5050-1796-S0 at slave(1)@127.0.1.1:5051 (AWM14X) for framework 20150707-142913-16777343-5050-1796-0000 (BioBox-Mesos-Framework_7292) at scheduler-eed21049-4f05-420b-8d01-06b99a18a2da@127.0.1.1:43847
I0707 15:02:48.804229  1803 hierarchical.hpp:648] Recovered mem(*):2048; disk(*):83928; ports(*):[31000-32000]; cpus(*):2 (total allocatable: mem(*):2048; disk(*):83928; ports(*):[31000-32000]; cpus(*):2) on slave 20150707-142913-16777343-5050-1796-S0 from framework 20150707-142913-16777343-5050-1796-0000
I0707 15:02:54.803999  1802 master.cpp:3760] Sending 1 offers to framework 20150707-142913-16777343-5050-1796-0000 (BioBox-Mesos-Framework_7292) at scheduler-eed21049-4f05-420b-8d01-06b99a18a2da@127.0.1.1:43847
I0707 15:02:54.810451  1803 master.cpp:2273] Processing ACCEPT call for offers: [ 20150707-142913-16777343-5050-1796-O187 ] on slave 20150707-142913-16777343-5050-1796-S0 at slave(1)@127.0.1.1:5051 (AWM14X) for framework 20150707-142913-16777343-5050-1796-0000 (BioBox-Mesos-Framework_7292) at scheduler-eed21049-4f05-420b-8d01-06b99a18a2da@127.0.1.1:43847
I0707 15:02:54.811981  1804 hierarchical.hpp:648] Recovered mem(*):2048; disk(*):83928; ports(*):[31000-32000]; cpus(*):2 (total allocatable: mem(*):2048; disk(*):83928; ports(*):[31000-32000]; cpus(*):2) on slave 20150707-142913-16777343-5050-1796-S0 from framework 20150707-142913-16777343-5050-1796-0000
I0707 15:02:58.076459  1799 http.cpp:516] HTTP request for '/master/state.json'
I0707 15:03:00.813710  1801 master.cpp:3760] Sending 1 offers to framework 20150707-142913-16777343-5050-1796-0000 (BioBox-Mesos-Framework_7292) at scheduler-eed21049-4f05-420b-8d01-06b99a18a2da@127.0.1.1:43847
I0707 15:03:00.819998  1800 master.cpp:2273] Processing ACCEPT call for offers: [ 20150707-142913-16777343-5050-1796-O188 ] on slave 20150707-142913-16777343-5050-1796-S0 at slave(1)@127.0.1.1:5051 (AWM14X) for framework 20150707-142913-16777343-5050-1796-0000 (BioBox-Mesos-Framework_7292) at scheduler-eed21049-4f05-420b-8d01-06b99a18a2da@127.0.1.1:43847
I0707 15:03:00.821466  1800 hierarchical.hpp:648] Recovered mem(*):2048; disk(*):83928; ports(*):[31000-32000]; cpus(*):2 (total allocatable: mem(*):2048; disk(*):83928; ports(*):[31000-32000]; cpus(*):2) on slave 20150707-142913-16777343-5050-1796-S0 from framework 20150707-142913-16777343-5050-1796-0000
I0707 15:03:05.823032  1801 master.cpp:3760] Sending 1 offers to framework 20150707-142913-16777343-5050-1796-0000 (BioBox-Mesos-Framework_7292) at scheduler-eed21049-4f05-420b-8d01-06b99a18a2da@127.0.1.1:43847
I0707 15:03:05.827970  1804 master.cpp:2273] Processing ACCEPT call for offers: [ 20150707-142913-16777343-5050-1796-O189 ] on slave 20150707-142913-16777343-5050-1796-S0 at slave(1)@127.0.1.1:5051 (AWM14X) for framework 20150707-142913-16777343-5050-1796-0000 (BioBox-Mesos-Framework_7292) at scheduler-eed21049-4f05-420b-8d01-06b99a18a2da@127.0.1.1:43847
I0707 15:03:05.828639  1804 hierarchical.hpp:648] Recovered mem(*):2048; disk(*):83928; ports(*):[31000-32000]; cpus(*):2 (total allocatable: mem(*):2048; disk(*):83928; ports(*):[31000-32000]; cpus(*):2) on slave 20150707-142913-16777343-5050-1796-S0 from framework 20150707-142913-16777343-5050-1796-0000
I0707 15:03:09.077170  1798 http.cpp:516] HTTP request for '/master/state.json'
I0707 15:03:10.829818  1805 master.cpp:3760] Sending 1 offers to framework 20150707-142913-16777343-5050-1796-0000 (BioBox-Mesos-Framework_7292) at scheduler-eed21049-4f05-420b-8d01-06b99a18a2da@127.0.1.1:43847
I0707 15:03:10.835688  1804 master.cpp:2273] Processing ACCEPT call for offers: [ 20150707-142913-16777343-5050-1796-O190 ] on slave 20150707-142913-16777343-5050-1796-S0 at slave(1)@127.0.1.1:5051 (AWM14X) for framework 20150707-142913-16777343-5050-1796-0000 (BioBox-Mesos-Framework_7292) at scheduler-eed21049-4f05-420b-8d01-06b99a18a2da@127.0.1.1:43847
I0707 15:03:10.837255  1804 hierarchical.hpp:648] Recovered mem(*):2048; disk(*):83928; ports(*):[31000-32000]; cpus(*):2 (total allocatable: mem(*):2048; disk(*):83928; ports(*):[31000-32000]; cpus(*):2) on slave 20150707-142913-16777343-5050-1796-S0 from framework 20150707-142913-16777343-5050-1796-0000
I0707 15:03:15.838654  1798 master.cpp:3760] Sending 1 offers to framework 20150707-142913-16777343-5050-1796-0000 (BioBox-Mesos-Framework_7292) at scheduler-eed21049-4f05-420b-8d01-06b99a18a2da@127.0.1.1:43847
I0707 15:03:15.846511  1805 master.cpp:2273] Processing ACCEPT call for offers: [ 20150707-142913-16777343-5050-1796-O191 ] on slave 20150707-142913-16777343-5050-1796-S0 at slave(1)@127.0.1.1:5051 (AWM14X) for framework 20150707-142913-16777343-5050-1796-0000 (BioBox-Mesos-Framework_7292) at scheduler-eed21049-4f05-420b-8d01-06b99a18a2da@127.0.1.1:43847
I0707 15:03:15.849314  1805 master.hpp:822] Adding task 3 with resources cpus(*):2; mem(*):256 on slave 20150707-142913-16777343-5050-1796-S0 (AWM14X)
I0707 15:03:15.849575  1805 master.cpp:2550] Launching task 3 of framework 20150707-142913-16777343-5050-1796-0000 (BioBox-Mesos-Framework_7292) at scheduler-eed21049-4f05-420b-8d01-06b99a18a2da@127.0.1.1:43847 with resources cpus(*):2; mem(*):256 on slave 20150707-142913-16777343-5050-1796-S0 at slave(1)@127.0.1.1:5051 (AWM14X)
I0707 15:03:15.850996  1803 hierarchical.hpp:648] Recovered mem(*):1792; disk(*):83928; ports(*):[31000-32000] (total allocatable: mem(*):1792; disk(*):83928; ports(*):[31000-32000]) on slave 20150707-142913-16777343-5050-1796-S0 from framework 20150707-142913-16777343-5050-1796-0000
I0707 15:03:16.366714  1801 master.cpp:3300] Status update TASK_RUNNING (UUID: 1575522b-a537-445a-9d41-610169f77721) for task 3 of framework 20150707-142913-16777343-5050-1796-0000 from slave 20150707-142913-16777343-5050-1796-S0 at slave(1)@127.0.1.1:5051 (AWM14X)
I0707 15:03:16.366837  1801 master.cpp:3341] Forwarding status update TASK_RUNNING (UUID: 1575522b-a537-445a-9d41-610169f77721) for task 3 of framework 20150707-142913-16777343-5050-1796-0000
I0707 15:03:16.367081  1801 master.cpp:4623] Updating the latest state of task 3 of framework 20150707-142913-16777343-5050-1796-0000 to TASK_RUNNING
I0707 15:03:16.370815  1800 master.cpp:2787] Forwarding status update acknowledgement 1575522b-a537-445a-9d41-610169f77721 for task 3 of framework 20150707-142913-16777343-5050-1796-0000 (BioBox-Mesos-Framework_7292) at scheduler-eed21049-4f05-420b-8d01-06b99a18a2da@127.0.1.1:43847 to slave 20150707-142913-16777343-5050-1796-S0 at slave(1)@127.0.1.1:5051 (AWM14X)
I0707 15:03:16.511787  1798 master.cpp:3300] Status update TASK_FINISHED (UUID: 450a9771-b22b-4869-884b-9cfd098ed04a) for task 3 of framework 20150707-142913-16777343-5050-1796-0000 from slave 20150707-142913-16777343-5050-1796-S0 at slave(1)@127.0.1.1:5051 (AWM14X)
I0707 15:03:16.511960  1798 master.cpp:3341] Forwarding status update TASK_FINISHED (UUID: 450a9771-b22b-4869-884b-9cfd098ed04a) for task 3 of framework 20150707-142913-16777343-5050-1796-0000
I0707 15:03:16.512261  1798 master.cpp:4623] Updating the latest state of task 3 of framework 20150707-142913-16777343-5050-1796-0000 to TASK_FINISHED
I0707 15:03:16.512485  1799 hierarchical.hpp:648] Recovered cpus(*):2; mem(*):256 (total allocatable: mem(*):2048; disk(*):83928; ports(*):[31000-32000]; cpus(*):2) on slave 20150707-142913-16777343-5050-1796-S0 from framework 20150707-142913-16777343-5050-1796-0000
I0707 15:03:16.513903  1802 master.cpp:4690] Removing task 3 with resources cpus(*):2; mem(*):256 of framework 20150707-142913-16777343-5050-1796-0000 on slave 20150707-142913-16777343-5050-1796-S0 at slave(1)@127.0.1.1:5051 (AWM14X)
I0707 15:03:16.514114  1802 master.cpp:2787] Forwarding status update acknowledgement 450a9771-b22b-4869-884b-9cfd098ed04a for task 3 of framework 20150707-142913-16777343-5050-1796-0000 (BioBox-Mesos-Framework_7292) at scheduler-eed21049-4f05-420b-8d01-06b99a18a2da@127.0.1.1:43847 to slave 20150707-142913-16777343-5050-1796-S0 at slave(1)@127.0.1.1:5051 (AWM14X)
I0707 15:03:16.841114  1801 master.cpp:3760] Sending 1 offers to framework 20150707-142913-16777343-5050-1796-0000 (BioBox-Mesos-Framework_7292) at scheduler-eed21049-4f05-420b-8d01-06b99a18a2da@127.0.1.1:43847
I0707 15:03:16.847774  1803 master.cpp:2273] Processing ACCEPT call for offers: [ 20150707-142913-16777343-5050-1796-O192 ] on slave 20150707-142913-16777343-5050-1796-S0 at slave(1)@127.0.1.1:5051 (AWM14X) for framework 20150707-142913-16777343-5050-1796-0000 (BioBox-Mesos-Framework_7292) at scheduler-eed21049-4f05-420b-8d01-06b99a18a2da@127.0.1.1:43847
I0707 15:03:16.849630  1803 hierarchical.hpp:648] Recovered mem(*):2048; disk(*):83928; ports(*):[31000-32000]; cpus(*):2 (total allocatable: mem(*):2048; disk(*):83928; ports(*):[31000-32000]; cpus(*):2) on slave 20150707-142913-16777343-5050-1796-S0 from framework 20150707-142913-16777343-5050-1796-0000
I0707 15:03:19.821682  1804 http.cpp:516] HTTP request for '/master/state.json'
I0707 15:03:22.850196  1798 master.cpp:3760] Sending 1 offers to framework 20150707-142913-16777343-5050-1796-0000 (BioBox-Mesos-Framework_7292) at scheduler-eed21049-4f05-420b-8d01-06b99a18a2da@127.0.1.1:43847
I0707 15:03:22.856528  1802 master.cpp:2273] Processing ACCEPT call for offers: [ 20150707-142913-16777343-5050-1796-O193 ] on slave 20150707-142913-16777343-5050-1796-S0 at slave(1)@127.0.1.1:5051 (AWM14X) for framework 20150707-142913-16777343-5050-1796-0000 (BioBox-Mesos-Framework_7292) at scheduler-eed21049-4f05-420b-8d01-06b99a18a2da@127.0.1.1:43847
I0707 15:03:22.857652  1802 hierarchical.hpp:648] Recovered mem(*):2048; disk(*):83928; ports(*):[31000-32000]; cpus(*):2 (total allocatable: mem(*):2048; disk(*):83928; ports(*):[31000-32000]; cpus(*):2) on slave 20150707-142913-16777343-5050-1796-S0 from framework 20150707-142913-16777343-5050-1796-0000
I0707 15:03:28.860152  1798 master.cpp:3760] Sending 1 offers to framework 20150707-142913-16777343-5050-1796-0000 (BioBox-Mesos-Framework_7292) at scheduler-eed21049-4f05-420b-8d01-06b99a18a2da@127.0.1.1:43847
I0707 15:03:28.866036  1802 master.cpp:2273] Processing ACCEPT call for offers: [ 20150707-142913-16777343-5050-1796-O194 ] on slave 20150707-142913-16777343-5050-1796-S0 at slave(1)@127.0.1.1:5051 (AWM14X) for framework 20150707-142913-16777343-5050-1796-0000 (BioBox-Mesos-Framework_7292) at scheduler-eed21049-4f05-420b-8d01-06b99a18a2da@127.0.1.1:43847
I0707 15:03:28.867318  1801 hierarchical.hpp:648] Recovered mem(*):2048; disk(*):83928; ports(*):[31000-32000]; cpus(*):2 (total allocatable: mem(*):2048; disk(*):83928; ports(*):[31000-32000]; cpus(*):2) on slave 20150707-142913-16777343-5050-1796-S0 from framework 20150707-142913-16777343-5050-1796-0000
I0707 15:03:29.836343  1802 http.cpp:516] HTTP request for '/master/state.json'
I0707 15:03:33.869441  1801 master.cpp:3760] Sending 1 offers to framework 20150707-142913-16777343-5050-1796-0000 (BioBox-Mesos-Framework_7292) at scheduler-eed21049-4f05-420b-8d01-06b99a18a2da@127.0.1.1:43847
I0707 15:03:33.875576  1805 master.cpp:2273] Processing ACCEPT call for offers: [ 20150707-142913-16777343-5050-1796-O195 ] on slave 20150707-142913-16777343-5050-1796-S0 at slave(1)@127.0.1.1:5051 (AWM14X) for framework 20150707-142913-16777343-5050-1796-0000 (BioBox-Mesos-Framework_7292) at scheduler-eed21049-4f05-420b-8d01-06b99a18a2da@127.0.1.1:43847
I0707 15:03:33.877332  1805 hierarchical.hpp:648] Recovered mem(*):2048; disk(*):83928; ports(*):[31000-32000]; cpus(*):2 (total allocatable: mem(*):2048; disk(*):83928; ports(*):[31000-32000]; cpus(*):2) on slave 20150707-142913-16777343-5050-1796-S0 from framework 20150707-142913-16777343-5050-1796-0000
I0707 15:03:38.878615  1800 master.cpp:3760] Sending 1 offers to framework 20150707-142913-16777343-5050-1796-0000 (BioBox-Mesos-Framework_7292) at scheduler-eed21049-4f05-420b-8d01-06b99a18a2da@127.0.1.1:43847
I0707 15:03:38.895913  1801 master.cpp:2273] Processing ACCEPT call for offers: [ 20150707-142913-16777343-5050-1796-O196 ] on slave 20150707-142913-16777343-5050-1796-S0 at slave(1)@127.0.1.1:5051 (AWM14X) for framework 20150707-142913-16777343-5050-1796-0000 (BioBox-Mesos-Framework_7292) at scheduler-eed21049-4f05-420b-8d01-06b99a18a2da@127.0.1.1:43847
I0707 15:03:38.897061  1805 hierarchical.hpp:648] Recovered mem(*):2048; disk(*):83928; ports(*):[31000-32000]; cpus(*):2 (total allocatable: mem(*):2048; disk(*):83928; ports(*):[31000-32000]; cpus(*):2) on slave 20150707-142913-16777343-5050-1796-S0 from framework 20150707-142913-16777343-5050-1796-0000
I0707 15:03:39.857522  1801 http.cpp:516] HTTP request for '/master/state.json'
I0707 15:03:44.888139  1800 master.cpp:3760] Sending 1 offers to framework 20150707-142913-16777343-5050-1796-0000 (BioBox-Mesos-Framework_7292) at scheduler-eed21049-4f05-420b-8d01-06b99a18a2da@127.0.1.1:43847
I0707 15:03:44.894152  1805 master.cpp:2273] Processing ACCEPT call for offers: [ 20150707-142913-16777343-5050-1796-O197 ] on slave 20150707-142913-16777343-5050-1796-S0 at slave(1)@127.0.1.1:5051 (AWM14X) for framework 20150707-142913-16777343-5050-1796-0000 (BioBox-Mesos-Framework_7292) at scheduler-eed21049-4f05-420b-8d01-06b99a18a2da@127.0.1.1:43847
I0707 15:03:44.895524  1801 hierarchical.hpp:648] Recovered mem(*):2048; disk(*):83928; ports(*):[31000-32000]; cpus(*):2 (total allocatable: mem(*):2048; disk(*):83928; ports(*):[31000-32000]; cpus(*):2) on slave 20150707-142913-16777343-5050-1796-S0 from framework 20150707-142913-16777343-5050-1796-0000
I0707 15:03:49.876729  1803 http.cpp:516] HTTP request for '/master/state.json'
I0707 15:03:50.897567  1799 master.cpp:3760] Sending 1 offers to framework 20150707-142913-16777343-5050-1796-0000 (BioBox-Mesos-Framework_7292) at scheduler-eed21049-4f05-420b-8d01-06b99a18a2da@127.0.1.1:43847
I0707 15:03:50.903048  1804 master.cpp:2273] Processing ACCEPT call for offers: [ 20150707-142913-16777343-5050-1796-O198 ] on slave 20150707-142913-16777343-5050-1796-S0 at slave(1)@127.0.1.1:5051 (AWM14X) for framework 20150707-142913-16777343-5050-1796-0000 (BioBox-Mesos-Framework_7292) at scheduler-eed21049-4f05-420b-8d01-06b99a18a2da@127.0.1.1:43847
I0707 15:03:50.904461  1804 hierarchical.hpp:648] Recovered mem(*):2048; disk(*):83928; ports(*):[31000-32000]; cpus(*):2 (total allocatable: mem(*):2048; disk(*):83928; ports(*):[31000-32000]; cpus(*):2) on slave 20150707-142913-16777343-5050-1796-S0 from framework 20150707-142913-16777343-5050-1796-0000
I0707 15:03:55.906157  1805 master.cpp:3760] Sending 1 offers to framework 20150707-142913-16777343-5050-1796-0000 (BioBox-Mesos-Framework_7292) at scheduler-eed21049-4f05-420b-8d01-06b99a18a2da@127.0.1.1:43847
I0707 15:03:55.912637  1799 master.cpp:2273] Processing ACCEPT call for offers: [ 20150707-142913-16777343-5050-1796-O199 ] on slave 20150707-142913-16777343-5050-1796-S0 at slave(1)@127.0.1.1:5051 (AWM14X) for framework 20150707-142913-16777343-5050-1796-0000 (BioBox-Mesos-Framework_7292) at scheduler-eed21049-4f05-420b-8d01-06b99a18a2da@127.0.1.1:43847
I0707 15:03:55.913884  1799 hierarchical.hpp:648] Recovered mem(*):2048; disk(*):83928; ports(*):[31000-32000]; cpus(*):2 (total allocatable: mem(*):2048; disk(*):83928; ports(*):[31000-32000]; cpus(*):2) on slave 20150707-142913-16777343-5050-1796-S0 from framework 20150707-142913-16777343-5050-1796-0000
I0707 15:03:59.896121  1800 http.cpp:516] HTTP request for '/master/state.json'
I0707 15:04:01.916745  1798 master.cpp:3760] Sending 1 offers to framework 20150707-142913-16777343-5050-1796-0000 (BioBox-Mesos-Framework_7292) at scheduler-eed21049-4f05-420b-8d01-06b99a18a2da@127.0.1.1:43847
I0707 15:04:01.922926  1802 master.cpp:2273] Processing ACCEPT call for offers: [ 20150707-142913-16777343-5050-1796-O200 ] on slave 20150707-142913-16777343-5050-1796-S0 at slave(1)@127.0.1.1:5051 (AWM14X) for framework 20150707-142913-16777343-5050-1796-0000 (BioBox-Mesos-Framework_7292) at scheduler-eed21049-4f05-420b-8d01-06b99a18a2da@127.0.1.1:43847
I0707 15:04:01.924267  1802 hierarchical.hpp:648] Recovered mem(*):2048; disk(*):83928; ports(*):[31000-32000]; cpus(*):2 (total allocatable: mem(*):2048; disk(*):83928; ports(*):[31000-32000]; cpus(*):2) on slave 20150707-142913-16777343-5050-1796-S0 from framework 20150707-142913-16777343-5050-1796-0000
I0707 15:04:06.926643  1799 master.cpp:3760] Sending 1 offers to framework 20150707-142913-16777343-5050-1796-0000 (BioBox-Mesos-Framework_7292) at scheduler-eed21049-4f05-420b-8d01-06b99a18a2da@127.0.1.1:43847
I0707 15:04:06.932875  1802 master.cpp:2273] Processing ACCEPT call for offers: [ 20150707-142913-16777343-5050-1796-O201 ] on slave 20150707-142913-16777343-5050-1796-S0 at slave(1)@127.0.1.1:5051 (AWM14X) for framework 20150707-142913-16777343-5050-1796-0000 (BioBox-Mesos-Framework_7292) at scheduler-eed21049-4f05-420b-8d01-06b99a18a2da@127.0.1.1:43847
I0707 15:04:06.934636  1802 hierarchical.hpp:648] Recovered mem(*):2048; disk(*):83928; ports(*):[31000-32000]; cpus(*):2 (total allocatable: mem(*):2048; disk(*):83928; ports(*):[31000-32000]; cpus(*):2) on slave 20150707-142913-16777343-5050-1796-S0 from framework 20150707-142913-16777343-5050-1796-0000
I0707 15:04:09.914592  1803 http.cpp:516] HTTP request for '/master/state.json'
I0707 15:04:12.936455  1804 master.cpp:3760] Sending 1 offers to framework 20150707-142913-16777343-5050-1796-0000 (BioBox-Mesos-Framework_7292) at scheduler-eed21049-4f05-420b-8d01-06b99a18a2da@127.0.1.1:43847
I0707 15:04:12.942803  1798 master.cpp:2273] Processing ACCEPT call for offers: [ 20150707-142913-16777343-5050-1796-O202 ] on slave 20150707-142913-16777343-5050-1796-S0 at slave(1)@127.0.1.1:5051 (AWM14X) for framework 20150707-142913-16777343-5050-1796-0000 (BioBox-Mesos-Framework_7292) at scheduler-eed21049-4f05-420b-8d01-06b99a18a2da@127.0.1.1:43847
I0707 15:04:12.944417  1799 hierarchical.hpp:648] Recovered mem(*):2048; disk(*):83928; ports(*):[31000-32000]; cpus(*):2 (total allocatable: mem(*):2048; disk(*):83928; ports(*):[31000-32000]; cpus(*):2) on slave 20150707-142913-16777343-5050-1796-S0 from framework 20150707-142913-16777343-5050-1796-0000
I0707 15:04:18.946421  1799 master.cpp:3760] Sending 1 offers to framework 20150707-142913-16777343-5050-1796-0000 (BioBox-Mesos-Framework_7292) at scheduler-eed21049-4f05-420b-8d01-06b99a18a2da@127.0.1.1:43847
I0707 15:04:18.953692  1798 master.cpp:2273] Processing ACCEPT call for offers: [ 20150707-142913-16777343-5050-1796-O203 ] on slave 20150707-142913-16777343-5050-1796-S0 at slave(1)@127.0.1.1:5051 (AWM14X) for framework 20150707-142913-16777343-5050-1796-0000 (BioBox-Mesos-Framework_7292) at scheduler-eed21049-4f05-420b-8d01-06b99a18a2da@127.0.1.1:43847
I0707 15:04:18.955035  1798 hierarchical.hpp:648] Recovered mem(*):2048; disk(*):83928; ports(*):[31000-32000]; cpus(*):2 (total allocatable: mem(*):2048; disk(*):83928; ports(*):[31000-32000]; cpus(*):2) on slave 20150707-142913-16777343-5050-1796-S0 from framework 20150707-142913-16777343-5050-1796-0000
I0707 15:04:19.932970  1800 http.cpp:516] HTTP request for '/master/state.json'
I0707 15:04:24.955507  1804 master.cpp:3760] Sending 1 offers to framework 20150707-142913-16777343-5050-1796-0000 (BioBox-Mesos-Framework_7292) at scheduler-eed21049-4f05-420b-8d01-06b99a18a2da@127.0.1.1:43847
I0707 15:04:24.961762  1805 master.cpp:2273] Processing ACCEPT call for offers: [ 20150707-142913-16777343-5050-1796-O204 ] on slave 20150707-142913-16777343-5050-1796-S0 at slave(1)@127.0.1.1:5051 (AWM14X) for framework 20150707-142913-16777343-5050-1796-0000 (BioBox-Mesos-Framework_7292) at scheduler-eed21049-4f05-420b-8d01-06b99a18a2da@127.0.1.1:43847
I0707 15:04:24.963062  1800 hierarchical.hpp:648] Recovered mem(*):2048; disk(*):83928; ports(*):[31000-32000]; cpus(*):2 (total allocatable: mem(*):2048; disk(*):83928; ports(*):[31000-32000]; cpus(*):2) on slave 20150707-142913-16777343-5050-1796-S0 from framework 20150707-142913-16777343-5050-1796-0000
I0707 15:04:29.952919  1798 http.cpp:516] HTTP request for '/master/state.json'
I0707 15:04:29.964886  1801 master.cpp:3760] Sending 1 offers to framework 20150707-142913-16777343-5050-1796-0000 (BioBox-Mesos-Framework_7292) at scheduler-eed21049-4f05-420b-8d01-06b99a18a2da@127.0.1.1:43847
I0707 15:04:29.970320  1803 master.cpp:2273] Processing ACCEPT call for offers: [ 20150707-142913-16777343-5050-1796-O205 ] on slave 20150707-142913-16777343-5050-1796-S0 at slave(1)@127.0.1.1:5051 (AWM14X) for framework 20150707-142913-16777343-5050-1796-0000 (BioBox-Mesos-Framework_7292) at scheduler-eed21049-4f05-420b-8d01-06b99a18a2da@127.0.1.1:43847
I0707 15:04:29.971803  1804 hierarchical.hpp:648] Recovered mem(*):2048; disk(*):83928; ports(*):[31000-32000]; cpus(*):2 (total allocatable: mem(*):2048; disk(*):83928; ports(*):[31000-32000]; cpus(*):2) on slave 20150707-142913-16777343-5050-1796-S0 from framework 20150707-142913-16777343-5050-1796-0000
I0707 15:04:35.974583  1804 master.cpp:3760] Sending 1 offers to framework 20150707-142913-16777343-5050-1796-0000 (BioBox-Mesos-Framework_7292) at scheduler-eed21049-4f05-420b-8d01-06b99a18a2da@127.0.1.1:43847
I0707 15:04:35.980916  1803 master.cpp:2273] Processing ACCEPT call for offers: [ 20150707-142913-16777343-5050-1796-O206 ] on slave 20150707-142913-16777343-5050-1796-S0 at slave(1)@127.0.1.1:5051 (AWM14X) for framework 20150707-142913-16777343-5050-1796-0000 (BioBox-Mesos-Framework_7292) at scheduler-eed21049-4f05-420b-8d01-06b99a18a2da@127.0.1.1:43847
I0707 15:04:35.982496  1803 hierarchical.hpp:648] Recovered mem(*):2048; disk(*):83928; ports(*):[31000-32000]; cpus(*):2 (total allocatable: mem(*):2048; disk(*):83928; ports(*):[31000-32000]; cpus(*):2) on slave 20150707-142913-16777343-5050-1796-S0 from framework 20150707-142913-16777343-5050-1796-0000
I0707 15:04:39.973057  1802 http.cpp:516] HTTP request for '/master/state.json'
I0707 15:04:41.985291  1804 master.cpp:3760] Sending 1 offers to framework 20150707-142913-16777343-5050-1796-0000 (BioBox-Mesos-Framework_7292) at scheduler-eed21049-4f05-420b-8d01-06b99a18a2da@127.0.1.1:43847
I0707 15:04:41.991610  1800 master.cpp:2273] Processing ACCEPT call for offers: [ 20150707-142913-16777343-5050-1796-O207 ] on slave 20150707-142913-16777343-5050-1796-S0 at slave(1)@127.0.1.1:5051 (AWM14X) for framework 20150707-142913-16777343-5050-1796-0000 (BioBox-Mesos-Framework_7292) at scheduler-eed21049-4f05-420b-8d01-06b99a18a2da@127.0.1.1:43847
I0707 15:04:41.993015  1800 hierarchical.hpp:648] Recovered mem(*):2048; disk(*):83928; ports(*):[31000-32000]; cpus(*):2 (total allocatable: mem(*):2048; disk(*):83928; ports(*):[31000-32000]; cpus(*):2) on slave 20150707-142913-16777343-5050-1796-S0 from framework 20150707-142913-16777343-5050-1796-0000
I0707 15:04:47.994019  1802 master.cpp:3760] Sending 1 offers to framework 20150707-142913-16777343-5050-1796-0000 (BioBox-Mesos-Framework_7292) at scheduler-eed21049-4f05-420b-8d01-06b99a18a2da@127.0.1.1:43847
I0707 15:04:48.000361  1804 master.cpp:2273] Processing ACCEPT call for offers: [ 20150707-142913-16777343-5050-1796-O208 ] on slave 20150707-142913-16777343-5050-1796-S0 at slave(1)@127.0.1.1:5051 (AWM14X) for framework 20150707-142913-16777343-5050-1796-0000 (BioBox-Mesos-Framework_7292) at scheduler-eed21049-4f05-420b-8d01-06b99a18a2da@127.0.1.1:43847
I0707 15:04:48.001633  1804 hierarchical.hpp:648] Recovered mem(*):2048; disk(*):83928; ports(*):[31000-32000]; cpus(*):2 (total allocatable: mem(*):2048; disk(*):83928; ports(*):[31000-32000]; cpus(*):2) on slave 20150707-142913-16777343-5050-1796-S0 from framework 20150707-142913-16777343-5050-1796-0000
I0707 15:04:49.992945  1799 http.cpp:516] HTTP request for '/master/state.json'
I0707 15:04:54.002159  1803 master.cpp:3760] Sending 1 offers to framework 20150707-142913-16777343-5050-1796-0000 (BioBox-Mesos-Framework_7292) at scheduler-eed21049-4f05-420b-8d01-06b99a18a2da@127.0.1.1:43847
I0707 15:04:54.004876  1798 master.cpp:2273] Processing ACCEPT call for offers: [ 20150707-142913-16777343-5050-1796-O209 ] on slave 20150707-142913-16777343-5050-1796-S0 at slave(1)@127.0.1.1:5051 (AWM14X) for framework 20150707-142913-16777343-5050-1796-0000 (BioBox-Mesos-Framework_7292) at scheduler-eed21049-4f05-420b-8d01-06b99a18a2da@127.0.1.1:43847
I0707 15:04:54.005388  1798 hierarchical.hpp:648] Recovered mem(*):2048; disk(*):83928; ports(*):[31000-32000]; cpus(*):2 (total allocatable: mem(*):2048; disk(*):83928; ports(*):[31000-32000]; cpus(*):2) on slave 20150707-142913-16777343-5050-1796-S0 from framework 20150707-142913-16777343-5050-1796-0000
I0707 15:04:59.010588  1802 master.cpp:3760] Sending 1 offers to framework 20150707-142913-16777343-5050-1796-0000 (BioBox-Mesos-Framework_7292) at scheduler-eed21049-4f05-420b-8d01-06b99a18a2da@127.0.1.1:43847
I0707 15:04:59.017083  1803 master.cpp:2273] Processing ACCEPT call for offers: [ 20150707-142913-16777343-5050-1796-O210 ] on slave 20150707-142913-16777343-5050-1796-S0 at slave(1)@127.0.1.1:5051 (AWM14X) for framework 20150707-142913-16777343-5050-1796-0000 (BioBox-Mesos-Framework_7292) at scheduler-eed21049-4f05-420b-8d01-06b99a18a2da@127.0.1.1:43847
I0707 15:04:59.018503  1798 hierarchical.hpp:648] Recovered mem(*):2048; disk(*):83928; ports(*):[31000-32000]; cpus(*):2 (total allocatable: mem(*):2048; disk(*):83928; ports(*):[31000-32000]; cpus(*):2) on slave 20150707-142913-16777343-5050-1796-S0 from framework 20150707-142913-16777343-5050-1796-0000
I0707 15:05:00.012454  1805 http.cpp:516] HTTP request for '/master/state.json'
I0707 15:05:05.020395  1804 master.cpp:3760] Sending 1 offers to framework 20150707-142913-16777343-5050-1796-0000 (BioBox-Mesos-Framework_7292) at scheduler-eed21049-4f05-420b-8d01-06b99a18a2da@127.0.1.1:43847
I0707 15:05:05.026741  1802 master.cpp:2273] Processing ACCEPT call for offers: [ 20150707-142913-16777343-5050-1796-O211 ] on slave 20150707-142913-16777343-5050-1796-S0 at slave(1)@127.0.1.1:5051 (AWM14X) for framework 20150707-142913-16777343-5050-1796-0000 (BioBox-Mesos-Framework_7292) at scheduler-eed21049-4f05-420b-8d01-06b99a18a2da@127.0.1.1:43847
I0707 15:05:05.028286  1800 hierarchical.hpp:648] Recovered mem(*):2048; disk(*):83928; ports(*):[31000-32000]; cpus(*):2 (total allocatable: mem(*):2048; disk(*):83928; ports(*):[31000-32000]; cpus(*):2) on slave 20150707-142913-16777343-5050-1796-S0 from framework 20150707-142913-16777343-5050-1796-0000
I0707 15:05:10.033500  1799 http.cpp:516] HTTP request for '/master/state.json'
I0707 15:05:11.031355  1800 master.cpp:3760] Sending 1 offers to framework 20150707-142913-16777343-5050-1796-0000 (BioBox-Mesos-Framework_7292) at scheduler-eed21049-4f05-420b-8d01-06b99a18a2da@127.0.1.1:43847
I0707 15:05:11.037358  1803 master.cpp:2273] Processing ACCEPT call for offers: [ 20150707-142913-16777343-5050-1796-O212 ] on slave 20150707-142913-16777343-5050-1796-S0 at slave(1)@127.0.1.1:5051 (AWM14X) for framework 20150707-142913-16777343-5050-1796-0000 (BioBox-Mesos-Framework_7292) at scheduler-eed21049-4f05-420b-8d01-06b99a18a2da@127.0.1.1:43847
I0707 15:05:11.038491  1805 hierarchical.hpp:648] Recovered mem(*):2048; disk(*):83928; ports(*):[31000-32000]; cpus(*):2 (total allocatable: mem(*):2048; disk(*):83928; ports(*):[31000-32000]; cpus(*):2) on slave 20150707-142913-16777343-5050-1796-S0 from framework 20150707-142913-16777343-5050-1796-0000
I0707 15:05:16.039990  1801 master.cpp:3760] Sending 1 offers to framework 20150707-142913-16777343-5050-1796-0000 (BioBox-Mesos-Framework_7292) at scheduler-eed21049-4f05-420b-8d01-06b99a18a2da@127.0.1.1:43847
I0707 15:05:16.046139  1798 master.cpp:2273] Processing ACCEPT call for offers: [ 20150707-142913-16777343-5050-1796-O213 ] on slave 20150707-142913-16777343-5050-1796-S0 at slave(1)@127.0.1.1:5051 (AWM14X) for framework 20150707-142913-16777343-5050-1796-0000 (BioBox-Mesos-Framework_7292) at scheduler-eed21049-4f05-420b-8d01-06b99a18a2da@127.0.1.1:43847
I0707 15:05:16.047442  1800 hierarchical.hpp:648] Recovered mem(*):2048; disk(*):83928; ports(*):[31000-32000]; cpus(*):2 (total allocatable: mem(*):2048; disk(*):83928; ports(*):[31000-32000]; cpus(*):2) on slave 20150707-142913-16777343-5050-1796-S0 from framework 20150707-142913-16777343-5050-1796-0000
I0707 15:05:20.053025  1803 http.cpp:516] HTTP request for '/master/state.json'
I0707 15:05:21.049244  1799 master.cpp:3760] Sending 1 offers to framework 20150707-142913-16777343-5050-1796-0000 (BioBox-Mesos-Framework_7292) at scheduler-eed21049-4f05-420b-8d01-06b99a18a2da@127.0.1.1:43847
I0707 15:05:21.055917  1800 master.cpp:2273] Processing ACCEPT call for offers: [ 20150707-142913-16777343-5050-1796-O214 ] on slave 20150707-142913-16777343-5050-1796-S0 at slave(1)@127.0.1.1:5051 (AWM14X) for framework 20150707-142913-16777343-5050-1796-0000 (BioBox-Mesos-Framework_7292) at scheduler-eed21049-4f05-420b-8d01-06b99a18a2da@127.0.1.1:43847
I0707 15:05:21.057847  1805 hierarchical.hpp:648] Recovered mem(*):2048; disk(*):83928; ports(*):[31000-32000]; cpus(*):2 (total allocatable: mem(*):2048; disk(*):83928; ports(*):[31000-32000]; cpus(*):2) on slave 20150707-142913-16777343-5050-1796-S0 from framework 20150707-142913-16777343-5050-1796-0000
I0707 15:05:27.059823  1799 master.cpp:3760] Sending 1 offers to framework 20150707-142913-16777343-5050-1796-0000 (BioBox-Mesos-Framework_7292) at scheduler-eed21049-4f05-420b-8d01-06b99a18a2da@127.0.1.1:43847
I0707 15:05:27.065723  1805 master.cpp:2273] Processing ACCEPT call for offers: [ 20150707-142913-16777343-5050-1796-O215 ] on slave 20150707-142913-16777343-5050-1796-S0 at slave(1)@127.0.1.1:5051 (AWM14X) for framework 20150707-142913-16777343-5050-1796-0000 (BioBox-Mesos-Framework_7292) at scheduler-eed21049-4f05-420b-8d01-06b99a18a2da@127.0.1.1:43847
I0707 15:05:27.067250  1800 hierarchical.hpp:648] Recovered mem(*):2048; disk(*):83928; ports(*):[31000-32000]; cpus(*):2 (total allocatable: mem(*):2048; disk(*):83928; ports(*):[31000-32000]; cpus(*):2) on slave 20150707-142913-16777343-5050-1796-S0 from framework 20150707-142913-16777343-5050-1796-0000
I0707 15:05:30.072507  1804 http.cpp:516] HTTP request for '/master/state.json'
I0707 15:05:32.069239  1799 master.cpp:3760] Sending 1 offers to framework 20150707-142913-16777343-5050-1796-0000 (BioBox-Mesos-Framework_7292) at scheduler-eed21049-4f05-420b-8d01-06b99a18a2da@127.0.1.1:43847
I0707 15:05:32.075592  1800 master.cpp:2273] Processing ACCEPT call for offers: [ 20150707-142913-16777343-5050-1796-O216 ] on slave 20150707-142913-16777343-5050-1796-S0 at slave(1)@127.0.1.1:5051 (AWM14X) for framework 20150707-142913-16777343-5050-1796-0000 (BioBox-Mesos-Framework_7292) at scheduler-eed21049-4f05-420b-8d01-06b99a18a2da@127.0.1.1:43847
I0707 15:05:32.077153  1800 hierarchical.hpp:648] Recovered mem(*):2048; disk(*):83928; ports(*):[31000-32000]; cpus(*):2 (total allocatable: mem(*):2048; disk(*):83928; ports(*):[31000-32000]; cpus(*):2) on slave 20150707-142913-16777343-5050-1796-S0 from framework 20150707-142913-16777343-5050-1796-0000
I0707 15:05:37.078935  1799 master.cpp:3760] Sending 1 offers to framework 20150707-142913-16777343-5050-1796-0000 (BioBox-Mesos-Framework_7292) at scheduler-eed21049-4f05-420b-8d01-06b99a18a2da@127.0.1.1:43847
I0707 15:05:37.084900  1800 master.cpp:2273] Processing ACCEPT call for offers: [ 20150707-142913-16777343-5050-1796-O217 ] on slave 20150707-142913-16777343-5050-1796-S0 at slave(1)@127.0.1.1:5051 (AWM14X) for framework 20150707-142913-16777343-5050-1796-0000 (BioBox-Mesos-Framework_7292) at scheduler-eed21049-4f05-420b-8d01-06b99a18a2da@127.0.1.1:43847
I0707 15:05:37.086267  1805 hierarchical.hpp:648] Recovered mem(*):2048; disk(*):83928; ports(*):[31000-32000]; cpus(*):2 (total allocatable: mem(*):2048; disk(*):83928; ports(*):[31000-32000]; cpus(*):2) on slave 20150707-142913-16777343-5050-1796-S0 from framework 20150707-142913-16777343-5050-1796-0000
I0707 15:05:40.090558  1801 http.cpp:516] HTTP request for '/master/state.json'
I0707 15:05:42.087646  1800 master.cpp:3760] Sending 1 offers to framework 20150707-142913-16777343-5050-1796-0000 (BioBox-Mesos-Framework_7292) at scheduler-eed21049-4f05-420b-8d01-06b99a18a2da@127.0.1.1:43847
I0707 15:05:42.093786  1804 master.cpp:2273] Processing ACCEPT call for offers: [ 20150707-142913-16777343-5050-1796-O218 ] on slave 20150707-142913-16777343-5050-1796-S0 at slave(1)@127.0.1.1:5051 (AWM14X) for framework 20150707-142913-16777343-5050-1796-0000 (BioBox-Mesos-Framework_7292) at scheduler-eed21049-4f05-420b-8d01-06b99a18a2da@127.0.1.1:43847
I0707 15:05:42.095165  1799 hierarchical.hpp:648] Recovered mem(*):2048; disk(*):83928; ports(*):[31000-32000]; cpus(*):2 (total allocatable: mem(*):2048; disk(*):83928; ports(*):[31000-32000]; cpus(*):2) on slave 20150707-142913-16777343-5050-1796-S0 from framework 20150707-142913-16777343-5050-1796-0000
I0707 15:05:48.097393  1800 master.cpp:3760] Sending 1 offers to framework 20150707-142913-16777343-5050-1796-0000 (BioBox-Mesos-Framework_7292) at scheduler-eed21049-4f05-420b-8d01-06b99a18a2da@127.0.1.1:43847
I0707 15:05:48.102777  1799 master.cpp:2273] Processing ACCEPT call for offers: [ 20150707-142913-16777343-5050-1796-O219 ] on slave 20150707-142913-16777343-5050-1796-S0 at slave(1)@127.0.1.1:5051 (AWM14X) for framework 20150707-142913-16777343-5050-1796-0000 (BioBox-Mesos-Framework_7292) at scheduler-eed21049-4f05-420b-8d01-06b99a18a2da@127.0.1.1:43847
I0707 15:05:48.104297  1799 hierarchical.hpp:648] Recovered mem(*):2048; disk(*):83928; ports(*):[31000-32000]; cpus(*):2 (total allocatable: mem(*):2048; disk(*):83928; ports(*):[31000-32000]; cpus(*):2) on slave 20150707-142913-16777343-5050-1796-S0 from framework 20150707-142913-16777343-5050-1796-0000
I0707 15:05:50.109371  1803 http.cpp:516] HTTP request for '/master/state.json'
I0707 15:05:54.107931  1805 master.cpp:3760] Sending 1 offers to framework 20150707-142913-16777343-5050-1796-0000 (BioBox-Mesos-Framework_7292) at scheduler-eed21049-4f05-420b-8d01-06b99a18a2da@127.0.1.1:43847
I0707 15:05:54.114665  1798 master.cpp:2273] Processing ACCEPT call for offers: [ 20150707-142913-16777343-5050-1796-O220 ] on slave 20150707-142913-16777343-5050-1796-S0 at slave(1)@127.0.1.1:5051 (AWM14X) for framework 20150707-142913-16777343-5050-1796-0000 (BioBox-Mesos-Framework_7292) at scheduler-eed21049-4f05-420b-8d01-06b99a18a2da@127.0.1.1:43847
I0707 15:05:54.115974  1801 hierarchical.hpp:648] Recovered mem(*):2048; disk(*):83928; ports(*):[31000-32000]; cpus(*):2 (total allocatable: mem(*):2048; disk(*):83928; ports(*):[31000-32000]; cpus(*):2) on slave 20150707-142913-16777343-5050-1796-S0 from framework 20150707-142913-16777343-5050-1796-0000
I0707 15:06:00.116866  1799 master.cpp:3760] Sending 1 offers to framework 20150707-142913-16777343-5050-1796-0000 (BioBox-Mesos-Framework_7292) at scheduler-eed21049-4f05-420b-8d01-06b99a18a2da@127.0.1.1:43847
I0707 15:06:00.123832  1804 master.cpp:2273] Processing ACCEPT call for offers: [ 20150707-142913-16777343-5050-1796-O221 ] on slave 20150707-142913-16777343-5050-1796-S0 at slave(1)@127.0.1.1:5051 (AWM14X) for framework 20150707-142913-16777343-5050-1796-0000 (BioBox-Mesos-Framework_7292) at scheduler-eed21049-4f05-420b-8d01-06b99a18a2da@127.0.1.1:43847
I0707 15:06:00.125965  1802 hierarchical.hpp:648] Recovered mem(*):2048; disk(*):83928; ports(*):[31000-32000]; cpus(*):2 (total allocatable: mem(*):2048; disk(*):83928; ports(*):[31000-32000]; cpus(*):2) on slave 20150707-142913-16777343-5050-1796-S0 from framework 20150707-142913-16777343-5050-1796-0000
I0707 15:06:00.126415  1803 http.cpp:516] HTTP request for '/master/state.json'
I0707 15:06:06.127810  1799 master.cpp:3760] Sending 1 offers to framework 20150707-142913-16777343-5050-1796-0000 (BioBox-Mesos-Framework_7292) at scheduler-eed21049-4f05-420b-8d01-06b99a18a2da@127.0.1.1:43847
I0707 15:06:06.134249  1803 master.cpp:2273] Processing ACCEPT call for offers: [ 20150707-142913-16777343-5050-1796-O222 ] on slave 20150707-142913-16777343-5050-1796-S0 at slave(1)@127.0.1.1:5051 (AWM14X) for framework 20150707-142913-16777343-5050-1796-0000 (BioBox-Mesos-Framework_7292) at scheduler-eed21049-4f05-420b-8d01-06b99a18a2da@127.0.1.1:43847
I0707 15:06:06.135495  1803 hierarchical.hpp:648] Recovered mem(*):2048; disk(*):83928; ports(*):[31000-32000]; cpus(*):2 (total allocatable: mem(*):2048; disk(*):83928; ports(*):[31000-32000]; cpus(*):2) on slave 20150707-142913-16777343-5050-1796-S0 from framework 20150707-142913-16777343-5050-1796-0000
I0707 15:06:10.145791  1801 http.cpp:516] HTTP request for '/master/state.json'
I0707 15:06:12.136154  1803 master.cpp:3760] Sending 1 offers to framework 20150707-142913-16777343-5050-1796-0000 (BioBox-Mesos-Framework_7292) at scheduler-eed21049-4f05-420b-8d01-06b99a18a2da@127.0.1.1:43847
I0707 15:06:20.160814  1799 http.cpp:516] HTTP request for '/master/state.json'
I0707 15:06:30.171008  1803 http.cpp:516] HTTP request for '/master/state.json'
I0707 15:06:40.179205  1798 http.cpp:516] HTTP request for '/master/state.json'
I0707 15:06:50.187583  1800 http.cpp:516] HTTP request for '/master/state.json'
I0707 15:07:00.197612  1804 http.cpp:516] HTTP request for '/master/state.json'
I0707 15:07:10.207487  1805 http.cpp:516] HTTP request for '/master/state.json'
I0707 15:07:20.216601  1804 http.cpp:516] HTTP request for '/master/state.json'
I0707 15:07:30.227066  1798 http.cpp:516] HTTP request for '/master/state.json'
I0707 15:07:40.237398  1802 http.cpp:516] HTTP request for '/master/state.json'
I0707 15:07:50.245698  1800 http.cpp:516] HTTP request for '/master/state.json'
I0707 15:08:00.237236  1804 master.cpp:878] Framework 20150707-142913-16777343-5050-1796-0000 (BioBox-Mesos-Framework_7292) at scheduler-eed21049-4f05-420b-8d01-06b99a18a2da@127.0.1.1:43847 disconnected
I0707 15:08:00.237325  1804 master.cpp:1948] Disconnecting framework 20150707-142913-16777343-5050-1796-0000 (BioBox-Mesos-Framework_7292) at scheduler-eed21049-4f05-420b-8d01-06b99a18a2da@127.0.1.1:43847
I0707 15:08:00.237393  1804 master.cpp:1964] Deactivating framework 20150707-142913-16777343-5050-1796-0000 (BioBox-Mesos-Framework_7292) at scheduler-eed21049-4f05-420b-8d01-06b99a18a2da@127.0.1.1:43847
I0707 15:08:00.237499  1798 hierarchical.hpp:400] Deactivated framework 20150707-142913-16777343-5050-1796-0000
I0707 15:08:00.238311  1804 master.cpp:900] Giving framework 20150707-142913-16777343-5050-1796-0000 (BioBox-Mesos-Framework_7292) at scheduler-eed21049-4f05-420b-8d01-06b99a18a2da@127.0.1.1:43847 25secs to failover
I0707 15:08:00.238551  1804 hierarchical.hpp:648] Recovered mem(*):2048; disk(*):83928; ports(*):[31000-32000]; cpus(*):2 (total allocatable: mem(*):2048; disk(*):83928; ports(*):[31000-32000]; cpus(*):2) on slave 20150707-142913-16777343-5050-1796-S0 from framework 20150707-142913-16777343-5050-1796-0000
I0707 15:08:00.254539  1804 http.cpp:516] HTTP request for '/master/state.json'
I0707 15:08:10.269186  1804 http.cpp:516] HTTP request for '/master/state.json'
I0707 15:08:20.293820  1798 http.cpp:516] HTTP request for '/master/state.json'
I0707 15:08:25.239605  1804 master.cpp:3630] Framework failover timeout, removing framework 20150707-142913-16777343-5050-1796-0000 (BioBox-Mesos-Framework_7292) at scheduler-eed21049-4f05-420b-8d01-06b99a18a2da@127.0.1.1:43847
I0707 15:08:25.239958  1804 master.cpp:4188] Removing framework 20150707-142913-16777343-5050-1796-0000 (BioBox-Mesos-Framework_7292) at scheduler-eed21049-4f05-420b-8d01-06b99a18a2da@127.0.1.1:43847
I0707 15:08:25.241307  1801 hierarchical.hpp:354] Removed framework 20150707-142913-16777343-5050-1796-0000
I0707 15:08:30.315008  1805 http.cpp:516] HTTP request for '/master/state.json'
I0707 15:08:40.330983  1800 http.cpp:516] HTTP request for '/master/state.json'
I0707 15:08:50.342931  1801 http.cpp:516] HTTP request for '/master/state.json'
I0707 15:09:00.360270  1799 http.cpp:516] HTTP request for '/master/state.json'
I0707 15:09:10.380728  1805 http.cpp:516] HTTP request for '/master/state.json'
I0707 15:09:20.400476  1799 http.cpp:516] HTTP request for '/master/state.json'
I0707 15:09:30.420899  1805 http.cpp:516] HTTP request for '/master/state.json'
I0707 15:09:40.441556  1799 http.cpp:516] HTTP request for '/master/state.json'
I0707 15:09:50.461879  1805 http.cpp:516] HTTP request for '/master/state.json'
I0707 15:10:00.482288  1800 http.cpp:516] HTTP request for '/master/state.json'
I0707 15:10:10.502238  1798 http.cpp:516] HTTP request for '/master/state.json'
I0707 15:10:20.522531  1800 http.cpp:516] HTTP request for '/master/state.json'
I0707 15:10:30.541942  1799 http.cpp:516] HTTP request for '/master/state.json'
I0707 15:10:40.561216  1801 http.cpp:516] HTTP request for '/master/state.json'
I0707 15:10:50.581151  1798 http.cpp:516] HTTP request for '/master/state.json'
I0707 15:11:00.602221  1804 http.cpp:516] HTTP request for '/master/state.json'
I0707 15:11:10.622303  1800 http.cpp:516] HTTP request for '/master/state.json'
I0707 15:11:20.642432  1802 http.cpp:516] HTTP request for '/master/state.json'
I0707 15:11:30.662367  1801 http.cpp:516] HTTP request for '/master/state.json'
I0707 15:11:40.682246  1802 http.cpp:516] HTTP request for '/master/state.json'
I0707 15:11:50.701972  1799 http.cpp:516] HTTP request for '/master/state.json'
I0707 15:12:00.723537  1798 http.cpp:516] HTTP request for '/master/state.json'
I0707 15:12:10.744118  1805 http.cpp:516] HTTP request for '/master/state.json'
I0707 15:12:20.765060  1800 http.cpp:516] HTTP request for '/master/state.json'
I0707 15:12:30.785007  1799 http.cpp:516] HTTP request for '/master/state.json'
I0707 15:12:40.805261  1803 http.cpp:516] HTTP request for '/master/state.json'
I0707 15:12:50.827410  1801 http.cpp:516] HTTP request for '/master/state.json'
I0707 15:13:00.849156  1804 http.cpp:516] HTTP request for '/master/state.json'
I0707 15:13:10.868561  1805 http.cpp:516] HTTP request for '/master/state.json'
I0707 15:13:20.887887  1798 http.cpp:516] HTTP request for '/master/state.json'
I0707 15:13:30.906435  1799 http.cpp:516] HTTP request for '/master/state.json'
I0707 15:13:40.925629  1802 http.cpp:516] HTTP request for '/master/state.json'
I0707 15:13:50.946457  1803 http.cpp:516] HTTP request for '/master/state.json'
I0707 15:14:00.965988  1805 http.cpp:516] HTTP request for '/master/state.json'
I0707 15:14:10.986974  1801 http.cpp:516] HTTP request for '/master/state.json'
I0707 15:14:21.007985  1803 http.cpp:516] HTTP request for '/master/state.json'
I0707 15:14:31.027930  1799 http.cpp:516] HTTP request for '/master/state.json'
I0707 15:14:41.047866  1804 http.cpp:516] HTTP request for '/master/state.json'
I0707 15:14:51.068681  1801 http.cpp:516] HTTP request for '/master/state.json'
I0707 15:15:01.090340  1799 http.cpp:516] HTTP request for '/master/state.json'
I0707 15:15:11.109325  1804 http.cpp:516] HTTP request for '/master/state.json'
I0707 15:15:21.129452  1801 http.cpp:516] HTTP request for '/master/state.json'
I0707 15:15:31.149379  1798 http.cpp:516] HTTP request for '/master/state.json'
I0707 15:15:41.169303  1801 http.cpp:516] HTTP request for '/master/state.json'
I0707 15:15:51.188235  1804 http.cpp:516] HTTP request for '/master/state.json'
I0707 15:16:01.209327  1799 http.cpp:516] HTTP request for '/master/state.json'
I0707 15:16:11.228790  1801 http.cpp:516] HTTP request for '/master/state.json'
I0707 15:16:21.245089  1805 http.cpp:516] HTTP request for '/master/state.json'
I0707 15:16:31.260673  1798 http.cpp:516] HTTP request for '/master/state.json'
I0707 15:16:41.280944  1804 http.cpp:516] HTTP request for '/master/state.json'
I0707 15:16:51.300928  1801 http.cpp:516] HTTP request for '/master/state.json'
I0707 15:17:01.323464  1798 http.cpp:516] HTTP request for '/master/state.json'
I0707 15:17:11.343977  1804 http.cpp:516] HTTP request for '/master/state.json'
I0707 15:17:21.364886  1805 http.cpp:516] HTTP request for '/master/state.json'
I0707 15:17:31.384371  1802 http.cpp:516] HTTP request for '/master/state.json'
I0707 15:17:41.404819  1799 http.cpp:516] HTTP request for '/master/state.json'
I0707 15:17:51.425910  1805 http.cpp:516] HTTP request for '/master/state.json'
I0707 15:18:01.447401  1803 http.cpp:516] HTTP request for '/master/state.json'
I0707 15:18:11.467972  1801 http.cpp:516] HTTP request for '/master/state.json'
I0707 15:18:21.489266  1805 http.cpp:516] HTTP request for '/master/state.json'
I0707 15:18:31.510117  1798 http.cpp:516] HTTP request for '/master/state.json'
I0707 15:18:41.530167  1803 http.cpp:516] HTTP request for '/master/state.json'
I0707 15:18:51.549577  1801 http.cpp:516] HTTP request for '/master/state.json'
I0707 15:19:01.570657  1805 http.cpp:516] HTTP request for '/master/state.json'
I0707 15:19:11.590240  1800 http.cpp:516] HTTP request for '/master/state.json'
I0707 15:19:21.609791  1802 http.cpp:516] HTTP request for '/master/state.json'
I0707 15:19:31.632079  1804 http.cpp:516] HTTP request for '/master/state.json'
I0707 15:19:41.649745  1799 http.cpp:516] HTTP request for '/master/state.json'
W0707 15:19:41.649745  1796 logging.cpp:81] RAW: Received signal SIGTERM from process 1 of user 0; exiting
